[2024-02-12 12:35:06 +0000] [7] [INFO] Starting gunicorn 21.2.0
[2024-02-12 12:35:06 +0000] [7] [INFO] Listening at: http://0.0.0.0:8000 (7)
[2024-02-12 12:35:06 +0000] [7] [INFO] Using worker: sync
[2024-02-12 12:35:06 +0000] [12] [INFO] Booting worker with pid: 12
Bad Request: /auth/register
[2024-02-12 12:49:11 +0000] [7] [INFO] Handling signal: term
[2024-02-12 12:49:11 +0000] [12] [INFO] Worker exiting (pid: 12)
[2024-02-12 12:49:11 +0000] [7] [INFO] Shutting down: Master
[2024-02-12 12:49:16 +0000] [7] [INFO] Starting gunicorn 21.2.0
[2024-02-12 12:49:16 +0000] [7] [INFO] Listening at: http://0.0.0.0:8000 (7)
[2024-02-12 12:49:16 +0000] [7] [INFO] Using worker: sync
[2024-02-12 12:49:16 +0000] [12] [INFO] Booting worker with pid: 12
Internal Server Error: /auth/register
Traceback (most recent call last):
  File "/home/ft_transcendence/venv/lib/python3.11/site-packages/django/core/handlers/exception.py", line 55, in inner
    response = get_response(request)
               ^^^^^^^^^^^^^^^^^^^^^
  File "/home/ft_transcendence/venv/lib/python3.11/site-packages/django/core/handlers/base.py", line 197, in _get_response
    response = wrapped_callback(request, *callback_args, **callback_kwargs)
               ^^^^^^^^^^^^^^^^^^^^^^^^^^^^^^^^^^^^^^^^^^^^^^^^^^^^^^^^^^^^
  File "/home/ft_transcendence/venv/lib/python3.11/site-packages/django/views/decorators/csrf.py", line 56, in wrapper_view
    return view_func(*args, **kwargs)
           ^^^^^^^^^^^^^^^^^^^^^^^^^^
  File "/home/ft_transcendence/venv/lib/python3.11/site-packages/django/views/generic/base.py", line 104, in view
    return self.dispatch(request, *args, **kwargs)
           ^^^^^^^^^^^^^^^^^^^^^^^^^^^^^^^^^^^^^^^
  File "/home/ft_transcendence/venv/lib/python3.11/site-packages/rest_framework/views.py", line 509, in dispatch
    response = self.handle_exception(exc)
               ^^^^^^^^^^^^^^^^^^^^^^^^^^
  File "/home/ft_transcendence/venv/lib/python3.11/site-packages/rest_framework/views.py", line 469, in handle_exception
    self.raise_uncaught_exception(exc)
  File "/home/ft_transcendence/venv/lib/python3.11/site-packages/rest_framework/views.py", line 480, in raise_uncaught_exception
    raise exc
  File "/home/ft_transcendence/venv/lib/python3.11/site-packages/rest_framework/views.py", line 506, in dispatch
    response = handler(request, *args, **kwargs)
               ^^^^^^^^^^^^^^^^^^^^^^^^^^^^^^^^^
  File "/home/ft_transcendence/src/api/views/account.py", line 16, in post
    user = serializer.save()
           ^^^^^^^^^^^^^^^^^
  File "/home/ft_transcendence/venv/lib/python3.11/site-packages/rest_framework/serializers.py", line 212, in save
    self.instance = self.create(validated_data)
                    ^^^^^^^^^^^^^^^^^^^^^^^^^^^
  File "/home/ft_transcendence/src/api/serializers/account.py", line 24, in create
    stream = BytesIO()
             ^^^^^^^
NameError: name 'BytesIO' is not defined
[2024-02-12 12:51:17 +0000] [7] [INFO] Handling signal: term
[2024-02-12 12:51:17 +0000] [12] [INFO] Worker exiting (pid: 12)
[2024-02-12 12:51:18 +0000] [7] [INFO] Shutting down: Master
[2024-02-12 12:51:20 +0000] [7] [INFO] Starting gunicorn 21.2.0
[2024-02-12 12:51:20 +0000] [7] [INFO] Listening at: http://0.0.0.0:8000 (7)
[2024-02-12 12:51:20 +0000] [7] [INFO] Using worker: sync
[2024-02-12 12:51:20 +0000] [12] [INFO] Booting worker with pid: 12
Internal Server Error: /auth/register
Traceback (most recent call last):
  File "/home/ft_transcendence/venv/lib/python3.11/site-packages/django/core/handlers/exception.py", line 55, in inner
    response = get_response(request)
               ^^^^^^^^^^^^^^^^^^^^^
  File "/home/ft_transcendence/venv/lib/python3.11/site-packages/django/core/handlers/base.py", line 197, in _get_response
    response = wrapped_callback(request, *callback_args, **callback_kwargs)
               ^^^^^^^^^^^^^^^^^^^^^^^^^^^^^^^^^^^^^^^^^^^^^^^^^^^^^^^^^^^^
  File "/home/ft_transcendence/venv/lib/python3.11/site-packages/django/views/decorators/csrf.py", line 56, in wrapper_view
    return view_func(*args, **kwargs)
           ^^^^^^^^^^^^^^^^^^^^^^^^^^
  File "/home/ft_transcendence/venv/lib/python3.11/site-packages/django/views/generic/base.py", line 104, in view
    return self.dispatch(request, *args, **kwargs)
           ^^^^^^^^^^^^^^^^^^^^^^^^^^^^^^^^^^^^^^^
  File "/home/ft_transcendence/venv/lib/python3.11/site-packages/rest_framework/views.py", line 509, in dispatch
    response = self.handle_exception(exc)
               ^^^^^^^^^^^^^^^^^^^^^^^^^^
  File "/home/ft_transcendence/venv/lib/python3.11/site-packages/rest_framework/views.py", line 469, in handle_exception
    self.raise_uncaught_exception(exc)
  File "/home/ft_transcendence/venv/lib/python3.11/site-packages/rest_framework/views.py", line 480, in raise_uncaught_exception
    raise exc
  File "/home/ft_transcendence/venv/lib/python3.11/site-packages/rest_framework/views.py", line 506, in dispatch
    response = handler(request, *args, **kwargs)
               ^^^^^^^^^^^^^^^^^^^^^^^^^^^^^^^^^
  File "/home/ft_transcendence/src/api/views/account.py", line 16, in post
    user = serializer.save()
           ^^^^^^^^^^^^^^^^^
  File "/home/ft_transcendence/venv/lib/python3.11/site-packages/rest_framework/serializers.py", line 212, in save
    self.instance = self.create(validated_data)
                    ^^^^^^^^^^^^^^^^^^^^^^^^^^^
  File "/home/ft_transcendence/src/api/serializers/account.py", line 25, in create
    stream = BytesIO()
             ^^^^^^^
NameError: name 'BytesIO' is not defined
[2024-02-12 12:53:08 +0000] [7] [INFO] Handling signal: term
[2024-02-12 12:53:08 +0000] [12] [INFO] Worker exiting (pid: 12)
[2024-02-12 12:53:09 +0000] [7] [INFO] Shutting down: Master
[2024-02-12 12:53:11 +0000] [7] [INFO] Starting gunicorn 21.2.0
[2024-02-12 12:53:11 +0000] [7] [INFO] Listening at: http://0.0.0.0:8000 (7)
[2024-02-12 12:53:11 +0000] [7] [INFO] Using worker: sync
[2024-02-12 12:53:11 +0000] [12] [INFO] Booting worker with pid: 12
Internal Server Error: /auth/register
Traceback (most recent call last):
  File "/home/ft_transcendence/venv/lib/python3.11/site-packages/django/core/handlers/exception.py", line 55, in inner
    response = get_response(request)
               ^^^^^^^^^^^^^^^^^^^^^
  File "/home/ft_transcendence/venv/lib/python3.11/site-packages/django/core/handlers/base.py", line 197, in _get_response
    response = wrapped_callback(request, *callback_args, **callback_kwargs)
               ^^^^^^^^^^^^^^^^^^^^^^^^^^^^^^^^^^^^^^^^^^^^^^^^^^^^^^^^^^^^
  File "/home/ft_transcendence/venv/lib/python3.11/site-packages/django/views/decorators/csrf.py", line 56, in wrapper_view
    return view_func(*args, **kwargs)
           ^^^^^^^^^^^^^^^^^^^^^^^^^^
  File "/home/ft_transcendence/venv/lib/python3.11/site-packages/django/views/generic/base.py", line 104, in view
    return self.dispatch(request, *args, **kwargs)
           ^^^^^^^^^^^^^^^^^^^^^^^^^^^^^^^^^^^^^^^
  File "/home/ft_transcendence/venv/lib/python3.11/site-packages/rest_framework/views.py", line 509, in dispatch
    response = self.handle_exception(exc)
               ^^^^^^^^^^^^^^^^^^^^^^^^^^
  File "/home/ft_transcendence/venv/lib/python3.11/site-packages/rest_framework/views.py", line 469, in handle_exception
    self.raise_uncaught_exception(exc)
  File "/home/ft_transcendence/venv/lib/python3.11/site-packages/rest_framework/views.py", line 480, in raise_uncaught_exception
    raise exc
  File "/home/ft_transcendence/venv/lib/python3.11/site-packages/rest_framework/views.py", line 506, in dispatch
    response = handler(request, *args, **kwargs)
               ^^^^^^^^^^^^^^^^^^^^^^^^^^^^^^^^^
  File "/home/ft_transcendence/src/api/views/account.py", line 16, in post
    user = serializer.save()
           ^^^^^^^^^^^^^^^^^
  File "/home/ft_transcendence/venv/lib/python3.11/site-packages/rest_framework/serializers.py", line 212, in save
    self.instance = self.create(validated_data)
                    ^^^^^^^^^^^^^^^^^^^^^^^^^^^
  File "/home/ft_transcendence/src/api/serializers/account.py", line 26, in create
    image = qrcode.make(f"{otp_auth_url}")
            ^^^^^^
NameError: name 'qrcode' is not defined
[2024-02-12 12:55:23 +0000] [7] [INFO] Handling signal: term
[2024-02-12 12:55:23 +0000] [12] [INFO] Worker exiting (pid: 12)
[2024-02-12 12:55:24 +0000] [7] [INFO] Shutting down: Master
[2024-02-12 12:55:27 +0000] [7] [INFO] Starting gunicorn 21.2.0
[2024-02-12 12:55:27 +0000] [7] [INFO] Listening at: http://0.0.0.0:8000 (7)
[2024-02-12 12:55:27 +0000] [7] [INFO] Using worker: sync
[2024-02-12 12:55:27 +0000] [12] [INFO] Booting worker with pid: 12
[2024-02-12 12:57:20 +0000] [7] [INFO] Handling signal: term
[2024-02-12 12:57:20 +0000] [12] [INFO] Worker exiting (pid: 12)
[2024-02-12 12:57:20 +0000] [7] [INFO] Shutting down: Master
[2024-02-12 12:57:23 +0000] [7] [INFO] Starting gunicorn 21.2.0
[2024-02-12 12:57:23 +0000] [7] [INFO] Listening at: http://0.0.0.0:8000 (7)
[2024-02-12 12:57:23 +0000] [7] [INFO] Using worker: sync
[2024-02-12 12:57:23 +0000] [12] [INFO] Booting worker with pid: 12
Internal Server Error: /auth/register
Traceback (most recent call last):
  File "/home/ft_transcendence/venv/lib/python3.11/site-packages/django/core/handlers/exception.py", line 55, in inner
    response = get_response(request)
               ^^^^^^^^^^^^^^^^^^^^^
  File "/home/ft_transcendence/venv/lib/python3.11/site-packages/django/core/handlers/base.py", line 197, in _get_response
    response = wrapped_callback(request, *callback_args, **callback_kwargs)
               ^^^^^^^^^^^^^^^^^^^^^^^^^^^^^^^^^^^^^^^^^^^^^^^^^^^^^^^^^^^^
  File "/home/ft_transcendence/venv/lib/python3.11/site-packages/django/views/decorators/csrf.py", line 56, in wrapper_view
    return view_func(*args, **kwargs)
           ^^^^^^^^^^^^^^^^^^^^^^^^^^
  File "/home/ft_transcendence/venv/lib/python3.11/site-packages/django/views/generic/base.py", line 104, in view
    return self.dispatch(request, *args, **kwargs)
           ^^^^^^^^^^^^^^^^^^^^^^^^^^^^^^^^^^^^^^^
  File "/home/ft_transcendence/venv/lib/python3.11/site-packages/rest_framework/views.py", line 509, in dispatch
    response = self.handle_exception(exc)
               ^^^^^^^^^^^^^^^^^^^^^^^^^^
  File "/home/ft_transcendence/venv/lib/python3.11/site-packages/rest_framework/views.py", line 469, in handle_exception
    self.raise_uncaught_exception(exc)
  File "/home/ft_transcendence/venv/lib/python3.11/site-packages/rest_framework/views.py", line 480, in raise_uncaught_exception
    raise exc
  File "/home/ft_transcendence/venv/lib/python3.11/site-packages/rest_framework/views.py", line 506, in dispatch
    response = handler(request, *args, **kwargs)
               ^^^^^^^^^^^^^^^^^^^^^^^^^^^^^^^^^
  File "/home/ft_transcendence/src/api/views/account.py", line 16, in post
    user = serializer.save()
           ^^^^^^^^^^^^^^^^^
  File "/home/ft_transcendence/venv/lib/python3.11/site-packages/rest_framework/serializers.py", line 212, in save
    self.instance = self.create(validated_data)
                    ^^^^^^^^^^^^^^^^^^^^^^^^^^^
  File "/home/ft_transcendence/src/api/serializers/account.py", line 29, in create
    user = Account.objects.create_user(
           ^^^^^^^^^^^^^^^^^^^^^^^^^^^^
  File "/home/ft_transcendence/venv/lib/python3.11/site-packages/django/contrib/auth/models.py", line 161, in create_user
    return self._create_user(username, email, password, **extra_fields)
           ^^^^^^^^^^^^^^^^^^^^^^^^^^^^^^^^^^^^^^^^^^^^^^^^^^^^^^^^^^^^
  File "/home/ft_transcendence/venv/lib/python3.11/site-packages/django/contrib/auth/models.py", line 153, in _create_user
    user = self.model(username=username, email=email, **extra_fields)
           ^^^^^^^^^^^^^^^^^^^^^^^^^^^^^^^^^^^^^^^^^^^^^^^^^^^^^^^^^^
  File "/home/ft_transcendence/venv/lib/python3.11/site-packages/django/db/models/base.py", line 567, in __init__
    raise TypeError(
TypeError: Account() got unexpected keyword arguments: 'qr_code'
[2024-02-12 12:59:11 +0000] [7] [INFO] Handling signal: term
[2024-02-12 12:59:11 +0000] [12] [INFO] Worker exiting (pid: 12)
[2024-02-12 12:59:12 +0000] [7] [INFO] Shutting down: Master
[2024-02-12 13:05:39 +0000] [8] [INFO] Starting gunicorn 21.2.0
[2024-02-12 13:05:39 +0000] [8] [INFO] Listening at: http://0.0.0.0:8000 (8)
[2024-02-12 13:05:39 +0000] [8] [INFO] Using worker: sync
[2024-02-12 13:05:39 +0000] [13] [INFO] Booting worker with pid: 13
Internal Server Error: /auth/register
Traceback (most recent call last):
  File "/home/ft_transcendence/venv/lib/python3.11/site-packages/django/core/handlers/exception.py", line 55, in inner
    response = get_response(request)
               ^^^^^^^^^^^^^^^^^^^^^
  File "/home/ft_transcendence/venv/lib/python3.11/site-packages/django/core/handlers/base.py", line 197, in _get_response
    response = wrapped_callback(request, *callback_args, **callback_kwargs)
               ^^^^^^^^^^^^^^^^^^^^^^^^^^^^^^^^^^^^^^^^^^^^^^^^^^^^^^^^^^^^
  File "/home/ft_transcendence/venv/lib/python3.11/site-packages/django/views/decorators/csrf.py", line 56, in wrapper_view
    return view_func(*args, **kwargs)
           ^^^^^^^^^^^^^^^^^^^^^^^^^^
  File "/home/ft_transcendence/venv/lib/python3.11/site-packages/django/views/generic/base.py", line 104, in view
    return self.dispatch(request, *args, **kwargs)
           ^^^^^^^^^^^^^^^^^^^^^^^^^^^^^^^^^^^^^^^
  File "/home/ft_transcendence/venv/lib/python3.11/site-packages/rest_framework/views.py", line 509, in dispatch
    response = self.handle_exception(exc)
               ^^^^^^^^^^^^^^^^^^^^^^^^^^
  File "/home/ft_transcendence/venv/lib/python3.11/site-packages/rest_framework/views.py", line 469, in handle_exception
    self.raise_uncaught_exception(exc)
  File "/home/ft_transcendence/venv/lib/python3.11/site-packages/rest_framework/views.py", line 480, in raise_uncaught_exception
    raise exc
  File "/home/ft_transcendence/venv/lib/python3.11/site-packages/rest_framework/views.py", line 506, in dispatch
    response = handler(request, *args, **kwargs)
               ^^^^^^^^^^^^^^^^^^^^^^^^^^^^^^^^^
  File "/home/ft_transcendence/src/api/views/account.py", line 16, in post
    user = serializer.save()
           ^^^^^^^^^^^^^^^^^
  File "/home/ft_transcendence/venv/lib/python3.11/site-packages/rest_framework/serializers.py", line 212, in save
    self.instance = self.create(validated_data)
                    ^^^^^^^^^^^^^^^^^^^^^^^^^^^
  File "/home/ft_transcendence/src/api/serializers/account.py", line 29, in create
    user = Account.objects.create_user(
           ^^^^^^^^^^^^^^^^^^^^^^^^^^^^
  File "/home/ft_transcendence/venv/lib/python3.11/site-packages/django/contrib/auth/models.py", line 161, in create_user
    return self._create_user(username, email, password, **extra_fields)
           ^^^^^^^^^^^^^^^^^^^^^^^^^^^^^^^^^^^^^^^^^^^^^^^^^^^^^^^^^^^^
  File "/home/ft_transcendence/venv/lib/python3.11/site-packages/django/contrib/auth/models.py", line 155, in _create_user
    user.save(using=self._db)
  File "/home/ft_transcendence/venv/lib/python3.11/site-packages/django/contrib/auth/base_user.py", line 76, in save
    super().save(*args, **kwargs)
  File "/home/ft_transcendence/venv/lib/python3.11/site-packages/django/db/models/base.py", line 814, in save
    self.save_base(
  File "/home/ft_transcendence/venv/lib/python3.11/site-packages/django/db/models/base.py", line 877, in save_base
    updated = self._save_table(
              ^^^^^^^^^^^^^^^^^
  File "/home/ft_transcendence/venv/lib/python3.11/site-packages/django/db/models/base.py", line 1020, in _save_table
    results = self._do_insert(
              ^^^^^^^^^^^^^^^^
  File "/home/ft_transcendence/venv/lib/python3.11/site-packages/django/db/models/base.py", line 1061, in _do_insert
    return manager._insert(
           ^^^^^^^^^^^^^^^^
  File "/home/ft_transcendence/venv/lib/python3.11/site-packages/django/db/models/manager.py", line 87, in manager_method
    return getattr(self.get_queryset(), name)(*args, **kwargs)
           ^^^^^^^^^^^^^^^^^^^^^^^^^^^^^^^^^^^^^^^^^^^^^^^^^^^
  File "/home/ft_transcendence/venv/lib/python3.11/site-packages/django/db/models/query.py", line 1805, in _insert
    return query.get_compiler(using=using).execute_sql(returning_fields)
           ^^^^^^^^^^^^^^^^^^^^^^^^^^^^^^^^^^^^^^^^^^^^^^^^^^^^^^^^^^^^^
  File "/home/ft_transcendence/venv/lib/python3.11/site-packages/django/db/models/sql/compiler.py", line 1821, in execute_sql
    for sql, params in self.as_sql():
                       ^^^^^^^^^^^^^
  File "/home/ft_transcendence/venv/lib/python3.11/site-packages/django/db/models/sql/compiler.py", line 1745, in as_sql
    value_rows = [
                 ^
  File "/home/ft_transcendence/venv/lib/python3.11/site-packages/django/db/models/sql/compiler.py", line 1746, in <listcomp>
    [
  File "/home/ft_transcendence/venv/lib/python3.11/site-packages/django/db/models/sql/compiler.py", line 1747, in <listcomp>
    self.prepare_value(field, self.pre_save_val(field, obj))
                              ^^^^^^^^^^^^^^^^^^^^^^^^^^^^^
  File "/home/ft_transcendence/venv/lib/python3.11/site-packages/django/db/models/sql/compiler.py", line 1695, in pre_save_val
    return field.pre_save(obj, add=True)
           ^^^^^^^^^^^^^^^^^^^^^^^^^^^^^
  File "/home/ft_transcendence/venv/lib/python3.11/site-packages/django/db/models/fields/files.py", line 315, in pre_save
    if file and not file._committed:
                    ^^^^^^^^^^^^^^^
  File "/home/ft_transcendence/venv/lib/python3.11/site-packages/qrcode/image/pil.py", line 61, in __getattr__
    return getattr(self._img, name)
           ^^^^^^^^^^^^^^^^^^^^^^^^
AttributeError: 'Image' object has no attribute '_committed'
[2024-02-12 13:11:43 +0000] [8] [INFO] Handling signal: term
[2024-02-12 13:11:43 +0000] [13] [INFO] Worker exiting (pid: 13)
[2024-02-12 13:11:43 +0000] [8] [INFO] Shutting down: Master
[2024-02-12 13:11:47 +0000] [8] [INFO] Starting gunicorn 21.2.0
[2024-02-12 13:11:47 +0000] [8] [INFO] Listening at: http://0.0.0.0:8000 (8)
[2024-02-12 13:11:47 +0000] [8] [INFO] Using worker: sync
[2024-02-12 13:11:47 +0000] [13] [INFO] Booting worker with pid: 13
[2024-02-12 13:12:29 +0000] [8] [INFO] Handling signal: term
[2024-02-12 13:12:29 +0000] [13] [INFO] Worker exiting (pid: 13)
[2024-02-12 13:12:29 +0000] [8] [INFO] Shutting down: Master
[2024-02-12 13:12:33 +0000] [7] [INFO] Starting gunicorn 21.2.0
[2024-02-12 13:12:33 +0000] [7] [INFO] Listening at: http://0.0.0.0:8000 (7)
[2024-02-12 13:12:33 +0000] [7] [INFO] Using worker: sync
[2024-02-12 13:12:33 +0000] [12] [INFO] Booting worker with pid: 12
[2024-02-12 13:13:21 +0000] [7] [INFO] Handling signal: term
[2024-02-12 13:13:21 +0000] [12] [INFO] Worker exiting (pid: 12)
[2024-02-12 13:13:21 +0000] [7] [INFO] Shutting down: Master
[2024-02-12 13:13:24 +0000] [7] [INFO] Starting gunicorn 21.2.0
[2024-02-12 13:13:24 +0000] [7] [INFO] Listening at: http://0.0.0.0:8000 (7)
[2024-02-12 13:13:24 +0000] [7] [INFO] Using worker: sync
[2024-02-12 13:13:24 +0000] [12] [INFO] Booting worker with pid: 12
Bad Request: /auth/register
[2024-02-12 13:33:55 +0000] [7] [INFO] Handling signal: term
[2024-02-12 13:33:55 +0000] [12] [INFO] Worker exiting (pid: 12)
[2024-02-12 13:33:55 +0000] [7] [INFO] Shutting down: Master
[2024-02-12 13:39:37 +0000] [7] [INFO] Starting gunicorn 21.2.0
[2024-02-12 13:39:37 +0000] [7] [INFO] Listening at: http://0.0.0.0:8000 (7)
[2024-02-12 13:39:37 +0000] [7] [INFO] Using worker: sync
[2024-02-12 13:39:37 +0000] [12] [INFO] Booting worker with pid: 12
Bad Request: /players/friend-requests/1
[2024-02-12 14:12:28 +0000] [7] [INFO] Handling signal: term
[2024-02-12 14:12:28 +0000] [12] [INFO] Worker exiting (pid: 12)
[2024-02-12 14:12:29 +0000] [7] [INFO] Shutting down: Master
[2024-02-12 14:21:24 +0000] [7] [INFO] Starting gunicorn 21.2.0
[2024-02-12 14:21:24 +0000] [7] [INFO] Listening at: http://0.0.0.0:8000 (7)
[2024-02-12 14:21:24 +0000] [7] [INFO] Using worker: sync
[2024-02-12 14:21:25 +0000] [12] [INFO] Booting worker with pid: 12
[2024-02-12 14:23:10 +0000] [7] [INFO] Handling signal: term
[2024-02-12 14:23:10 +0000] [12] [INFO] Worker exiting (pid: 12)
[2024-02-12 14:23:10 +0000] [7] [INFO] Shutting down: Master
[2024-02-12 14:23:14 +0000] [7] [INFO] Starting gunicorn 21.2.0
[2024-02-12 14:23:14 +0000] [7] [INFO] Listening at: http://0.0.0.0:8000 (7)
[2024-02-12 14:23:14 +0000] [7] [INFO] Using worker: sync
[2024-02-12 14:23:14 +0000] [12] [INFO] Booting worker with pid: 12
Internal Server Error: /auth/login
Traceback (most recent call last):
  File "/home/ft_transcendence/venv/lib/python3.11/site-packages/django/core/handlers/exception.py", line 55, in inner
    response = get_response(request)
               ^^^^^^^^^^^^^^^^^^^^^
  File "/home/ft_transcendence/venv/lib/python3.11/site-packages/django/core/handlers/base.py", line 197, in _get_response
    response = wrapped_callback(request, *callback_args, **callback_kwargs)
               ^^^^^^^^^^^^^^^^^^^^^^^^^^^^^^^^^^^^^^^^^^^^^^^^^^^^^^^^^^^^
  File "/home/ft_transcendence/venv/lib/python3.11/site-packages/django/views/decorators/csrf.py", line 56, in wrapper_view
    return view_func(*args, **kwargs)
           ^^^^^^^^^^^^^^^^^^^^^^^^^^
  File "/home/ft_transcendence/venv/lib/python3.11/site-packages/django/views/generic/base.py", line 104, in view
    return self.dispatch(request, *args, **kwargs)
           ^^^^^^^^^^^^^^^^^^^^^^^^^^^^^^^^^^^^^^^
  File "/home/ft_transcendence/venv/lib/python3.11/site-packages/rest_framework/views.py", line 509, in dispatch
    response = self.handle_exception(exc)
               ^^^^^^^^^^^^^^^^^^^^^^^^^^
  File "/home/ft_transcendence/venv/lib/python3.11/site-packages/rest_framework/views.py", line 469, in handle_exception
    self.raise_uncaught_exception(exc)
  File "/home/ft_transcendence/venv/lib/python3.11/site-packages/rest_framework/views.py", line 480, in raise_uncaught_exception
    raise exc
  File "/home/ft_transcendence/venv/lib/python3.11/site-packages/rest_framework/views.py", line 506, in dispatch
    response = handler(request, *args, **kwargs)
               ^^^^^^^^^^^^^^^^^^^^^^^^^^^^^^^^^
  File "/home/ft_transcendence/src/api/views/account.py", line 29, in post
    serializer.is_valid(raise_exception=True)
  File "/home/ft_transcendence/venv/lib/python3.11/site-packages/rest_framework/serializers.py", line 227, in is_valid
    self._validated_data = self.run_validation(self.initial_data)
                           ^^^^^^^^^^^^^^^^^^^^^^^^^^^^^^^^^^^^^^
  File "/home/ft_transcendence/venv/lib/python3.11/site-packages/rest_framework/serializers.py", line 429, in run_validation
    value = self.validate(value)
            ^^^^^^^^^^^^^^^^^^^^
  File "/home/ft_transcendence/src/api/serializers/account.py", line 56, in validate
    raise exceptions.AuthenticationFailed("Invalid login details.")
          ^^^^^^^^^^
NameError: name 'exceptions' is not defined
[2024-02-12 14:25:31 +0000] [7] [INFO] Handling signal: term
[2024-02-12 14:25:31 +0000] [12] [INFO] Worker exiting (pid: 12)
[2024-02-12 14:25:31 +0000] [7] [INFO] Shutting down: Master
[2024-02-12 14:25:34 +0000] [7] [INFO] Starting gunicorn 21.2.0
[2024-02-12 14:25:34 +0000] [7] [INFO] Listening at: http://0.0.0.0:8000 (7)
[2024-02-12 14:25:34 +0000] [7] [INFO] Using worker: sync
[2024-02-12 14:25:35 +0000] [12] [INFO] Booting worker with pid: 12
[2024-02-12 14:26:38 +0000] [7] [INFO] Handling signal: term
[2024-02-12 14:26:38 +0000] [12] [INFO] Worker exiting (pid: 12)
[2024-02-12 14:26:38 +0000] [7] [INFO] Shutting down: Master
[2024-02-12 14:26:41 +0000] [7] [INFO] Starting gunicorn 21.2.0
[2024-02-12 14:26:41 +0000] [7] [INFO] Listening at: http://0.0.0.0:8000 (7)
[2024-02-12 14:26:41 +0000] [7] [INFO] Using worker: sync
[2024-02-12 14:26:41 +0000] [12] [INFO] Booting worker with pid: 12
Internal Server Error: /auth/login
Traceback (most recent call last):
  File "/home/ft_transcendence/venv/lib/python3.11/site-packages/django/core/handlers/exception.py", line 55, in inner
    response = get_response(request)
               ^^^^^^^^^^^^^^^^^^^^^
  File "/home/ft_transcendence/venv/lib/python3.11/site-packages/django/core/handlers/base.py", line 197, in _get_response
    response = wrapped_callback(request, *callback_args, **callback_kwargs)
               ^^^^^^^^^^^^^^^^^^^^^^^^^^^^^^^^^^^^^^^^^^^^^^^^^^^^^^^^^^^^
  File "/home/ft_transcendence/venv/lib/python3.11/site-packages/django/views/decorators/csrf.py", line 56, in wrapper_view
    return view_func(*args, **kwargs)
           ^^^^^^^^^^^^^^^^^^^^^^^^^^
  File "/home/ft_transcendence/venv/lib/python3.11/site-packages/django/views/generic/base.py", line 104, in view
    return self.dispatch(request, *args, **kwargs)
           ^^^^^^^^^^^^^^^^^^^^^^^^^^^^^^^^^^^^^^^
  File "/home/ft_transcendence/venv/lib/python3.11/site-packages/rest_framework/views.py", line 509, in dispatch
    response = self.handle_exception(exc)
               ^^^^^^^^^^^^^^^^^^^^^^^^^^
  File "/home/ft_transcendence/venv/lib/python3.11/site-packages/rest_framework/views.py", line 469, in handle_exception
    self.raise_uncaught_exception(exc)
  File "/home/ft_transcendence/venv/lib/python3.11/site-packages/rest_framework/views.py", line 480, in raise_uncaught_exception
    raise exc
  File "/home/ft_transcendence/venv/lib/python3.11/site-packages/rest_framework/views.py", line 506, in dispatch
    response = handler(request, *args, **kwargs)
               ^^^^^^^^^^^^^^^^^^^^^^^^^^^^^^^^^
  File "/home/ft_transcendence/src/api/views/account.py", line 29, in post
    serializer.is_valid(raise_exception=True)
  File "/home/ft_transcendence/venv/lib/python3.11/site-packages/rest_framework/serializers.py", line 227, in is_valid
    self._validated_data = self.run_validation(self.initial_data)
                           ^^^^^^^^^^^^^^^^^^^^^^^^^^^^^^^^^^^^^^
  File "/home/ft_transcendence/venv/lib/python3.11/site-packages/rest_framework/serializers.py", line 429, in run_validation
    value = self.validate(value)
            ^^^^^^^^^^^^^^^^^^^^
  File "/home/ft_transcendence/src/api/serializers/account.py", line 65, in validate
    raise exceptions.AuthenticationFailed("Invalid login details.")
          ^^^^^^^^^^
NameError: name 'exceptions' is not defined
[2024-02-12 14:28:28 +0000] [7] [INFO] Handling signal: term
[2024-02-12 14:28:28 +0000] [12] [INFO] Worker exiting (pid: 12)
[2024-02-12 14:28:28 +0000] [7] [INFO] Shutting down: Master
[2024-02-12 14:28:32 +0000] [8] [INFO] Starting gunicorn 21.2.0
[2024-02-12 14:28:32 +0000] [8] [INFO] Listening at: http://0.0.0.0:8000 (8)
[2024-02-12 14:28:32 +0000] [8] [INFO] Using worker: sync
[2024-02-12 14:28:32 +0000] [13] [INFO] Booting worker with pid: 13
Bad Request: /auth/login
[2024-02-12 14:29:35 +0000] [8] [INFO] Handling signal: term
[2024-02-12 14:29:35 +0000] [13] [INFO] Worker exiting (pid: 13)
[2024-02-12 14:29:35 +0000] [8] [INFO] Shutting down: Master
[2024-02-12 14:29:38 +0000] [7] [INFO] Starting gunicorn 21.2.0
[2024-02-12 14:29:38 +0000] [7] [INFO] Listening at: http://0.0.0.0:8000 (7)
[2024-02-12 14:29:38 +0000] [7] [INFO] Using worker: sync
[2024-02-12 14:29:38 +0000] [12] [INFO] Booting worker with pid: 12
Internal Server Error: /auth/login
Traceback (most recent call last):
  File "/home/ft_transcendence/venv/lib/python3.11/site-packages/django/db/backends/utils.py", line 89, in _execute
    return self.cursor.execute(sql, params)
           ^^^^^^^^^^^^^^^^^^^^^^^^^^^^^^^^
  File "/home/ft_transcendence/venv/lib/python3.11/site-packages/psycopg/cursor.py", line 737, in execute
    raise ex.with_traceback(None)
psycopg.errors.UndefinedColumn: column api_account.login_otp does not exist
LINE 1: ...ed", "api_account"."bio", "api_account"."avatar", "api_accou...
                                                             ^

The above exception was the direct cause of the following exception:

Traceback (most recent call last):
  File "/home/ft_transcendence/venv/lib/python3.11/site-packages/django/core/handlers/exception.py", line 55, in inner
    response = get_response(request)
               ^^^^^^^^^^^^^^^^^^^^^
  File "/home/ft_transcendence/venv/lib/python3.11/site-packages/django/core/handlers/base.py", line 197, in _get_response
    response = wrapped_callback(request, *callback_args, **callback_kwargs)
               ^^^^^^^^^^^^^^^^^^^^^^^^^^^^^^^^^^^^^^^^^^^^^^^^^^^^^^^^^^^^
  File "/home/ft_transcendence/venv/lib/python3.11/site-packages/django/views/decorators/csrf.py", line 56, in wrapper_view
    return view_func(*args, **kwargs)
           ^^^^^^^^^^^^^^^^^^^^^^^^^^
  File "/home/ft_transcendence/venv/lib/python3.11/site-packages/django/views/generic/base.py", line 104, in view
    return self.dispatch(request, *args, **kwargs)
           ^^^^^^^^^^^^^^^^^^^^^^^^^^^^^^^^^^^^^^^
  File "/home/ft_transcendence/venv/lib/python3.11/site-packages/rest_framework/views.py", line 509, in dispatch
    response = self.handle_exception(exc)
               ^^^^^^^^^^^^^^^^^^^^^^^^^^
  File "/home/ft_transcendence/venv/lib/python3.11/site-packages/rest_framework/views.py", line 469, in handle_exception
    self.raise_uncaught_exception(exc)
  File "/home/ft_transcendence/venv/lib/python3.11/site-packages/rest_framework/views.py", line 480, in raise_uncaught_exception
    raise exc
  File "/home/ft_transcendence/venv/lib/python3.11/site-packages/rest_framework/views.py", line 506, in dispatch
    response = handler(request, *args, **kwargs)
               ^^^^^^^^^^^^^^^^^^^^^^^^^^^^^^^^^
  File "/home/ft_transcendence/src/api/views/account.py", line 29, in post
    serializer.is_valid(raise_exception=True)
  File "/home/ft_transcendence/venv/lib/python3.11/site-packages/rest_framework/serializers.py", line 227, in is_valid
    self._validated_data = self.run_validation(self.initial_data)
                           ^^^^^^^^^^^^^^^^^^^^^^^^^^^^^^^^^^^^^^
  File "/home/ft_transcendence/venv/lib/python3.11/site-packages/rest_framework/serializers.py", line 429, in run_validation
    value = self.validate(value)
            ^^^^^^^^^^^^^^^^^^^^
  File "/home/ft_transcendence/src/api/serializers/account.py", line 59, in validate
    user = authenticate(
           ^^^^^^^^^^^^^
  File "/home/ft_transcendence/venv/lib/python3.11/site-packages/django/views/decorators/debug.py", line 42, in sensitive_variables_wrapper
    return func(*func_args, **func_kwargs)
           ^^^^^^^^^^^^^^^^^^^^^^^^^^^^^^^
  File "/home/ft_transcendence/venv/lib/python3.11/site-packages/django/contrib/auth/__init__.py", line 77, in authenticate
    user = backend.authenticate(request, **credentials)
           ^^^^^^^^^^^^^^^^^^^^^^^^^^^^^^^^^^^^^^^^^^^^
  File "/home/ft_transcendence/venv/lib/python3.11/site-packages/django/contrib/auth/backends.py", line 46, in authenticate
    user = UserModel._default_manager.get_by_natural_key(username)
           ^^^^^^^^^^^^^^^^^^^^^^^^^^^^^^^^^^^^^^^^^^^^^^^^^^^^^^^
  File "/home/ft_transcendence/venv/lib/python3.11/site-packages/django/contrib/auth/base_user.py", line 54, in get_by_natural_key
    return self.get(**{self.model.USERNAME_FIELD: username})
           ^^^^^^^^^^^^^^^^^^^^^^^^^^^^^^^^^^^^^^^^^^^^^^^^^
  File "/home/ft_transcendence/venv/lib/python3.11/site-packages/django/db/models/manager.py", line 87, in manager_method
    return getattr(self.get_queryset(), name)(*args, **kwargs)
           ^^^^^^^^^^^^^^^^^^^^^^^^^^^^^^^^^^^^^^^^^^^^^^^^^^^
  File "/home/ft_transcendence/venv/lib/python3.11/site-packages/django/db/models/query.py", line 633, in get
    num = len(clone)
          ^^^^^^^^^^
  File "/home/ft_transcendence/venv/lib/python3.11/site-packages/django/db/models/query.py", line 380, in __len__
    self._fetch_all()
  File "/home/ft_transcendence/venv/lib/python3.11/site-packages/django/db/models/query.py", line 1881, in _fetch_all
    self._result_cache = list(self._iterable_class(self))
                         ^^^^^^^^^^^^^^^^^^^^^^^^^^^^^^^^
  File "/home/ft_transcendence/venv/lib/python3.11/site-packages/django/db/models/query.py", line 91, in __iter__
    results = compiler.execute_sql(
              ^^^^^^^^^^^^^^^^^^^^^
  File "/home/ft_transcendence/venv/lib/python3.11/site-packages/django/db/models/sql/compiler.py", line 1562, in execute_sql
    cursor.execute(sql, params)
  File "/home/ft_transcendence/venv/lib/python3.11/site-packages/django/db/backends/utils.py", line 102, in execute
    return super().execute(sql, params)
           ^^^^^^^^^^^^^^^^^^^^^^^^^^^^
  File "/home/ft_transcendence/venv/lib/python3.11/site-packages/django/db/backends/utils.py", line 67, in execute
    return self._execute_with_wrappers(
           ^^^^^^^^^^^^^^^^^^^^^^^^^^^^
  File "/home/ft_transcendence/venv/lib/python3.11/site-packages/django/db/backends/utils.py", line 80, in _execute_with_wrappers
    return executor(sql, params, many, context)
           ^^^^^^^^^^^^^^^^^^^^^^^^^^^^^^^^^^^^
  File "/home/ft_transcendence/venv/lib/python3.11/site-packages/django/db/backends/utils.py", line 84, in _execute
    with self.db.wrap_database_errors:
  File "/home/ft_transcendence/venv/lib/python3.11/site-packages/django/db/utils.py", line 91, in __exit__
    raise dj_exc_value.with_traceback(traceback) from exc_value
  File "/home/ft_transcendence/venv/lib/python3.11/site-packages/django/db/backends/utils.py", line 89, in _execute
    return self.cursor.execute(sql, params)
           ^^^^^^^^^^^^^^^^^^^^^^^^^^^^^^^^
  File "/home/ft_transcendence/venv/lib/python3.11/site-packages/psycopg/cursor.py", line 737, in execute
    raise ex.with_traceback(None)
django.db.utils.ProgrammingError: column api_account.login_otp does not exist
LINE 1: ...ed", "api_account"."bio", "api_account"."avatar", "api_accou...
                                                             ^
[2024-02-12 14:32:02 +0000] [7] [INFO] Handling signal: term
[2024-02-12 14:32:02 +0000] [12] [INFO] Worker exiting (pid: 12)
[2024-02-12 14:32:03 +0000] [7] [INFO] Shutting down: Master
[2024-02-12 14:36:18 +0000] [7] [INFO] Starting gunicorn 21.2.0
[2024-02-12 14:36:18 +0000] [7] [INFO] Listening at: http://0.0.0.0:8000 (7)
[2024-02-12 14:36:18 +0000] [7] [INFO] Using worker: sync
[2024-02-12 14:36:18 +0000] [12] [INFO] Booting worker with pid: 12
Internal Server Error: /auth/login
Traceback (most recent call last):
  File "/home/ft_transcendence/venv/lib/python3.11/site-packages/django/core/handlers/exception.py", line 55, in inner
    response = get_response(request)
               ^^^^^^^^^^^^^^^^^^^^^
  File "/home/ft_transcendence/venv/lib/python3.11/site-packages/django/core/handlers/base.py", line 197, in _get_response
    response = wrapped_callback(request, *callback_args, **callback_kwargs)
               ^^^^^^^^^^^^^^^^^^^^^^^^^^^^^^^^^^^^^^^^^^^^^^^^^^^^^^^^^^^^
  File "/home/ft_transcendence/venv/lib/python3.11/site-packages/django/views/decorators/csrf.py", line 56, in wrapper_view
    return view_func(*args, **kwargs)
           ^^^^^^^^^^^^^^^^^^^^^^^^^^
  File "/home/ft_transcendence/venv/lib/python3.11/site-packages/django/views/generic/base.py", line 104, in view
    return self.dispatch(request, *args, **kwargs)
           ^^^^^^^^^^^^^^^^^^^^^^^^^^^^^^^^^^^^^^^
  File "/home/ft_transcendence/venv/lib/python3.11/site-packages/rest_framework/views.py", line 509, in dispatch
    response = self.handle_exception(exc)
               ^^^^^^^^^^^^^^^^^^^^^^^^^^
  File "/home/ft_transcendence/venv/lib/python3.11/site-packages/rest_framework/views.py", line 469, in handle_exception
    self.raise_uncaught_exception(exc)
  File "/home/ft_transcendence/venv/lib/python3.11/site-packages/rest_framework/views.py", line 480, in raise_uncaught_exception
    raise exc
  File "/home/ft_transcendence/venv/lib/python3.11/site-packages/rest_framework/views.py", line 506, in dispatch
    response = handler(request, *args, **kwargs)
               ^^^^^^^^^^^^^^^^^^^^^^^^^^^^^^^^^
  File "/home/ft_transcendence/src/api/views/account.py", line 30, in post
    user = serializer.save()
           ^^^^^^^^^^^^^^^^^
  File "/home/ft_transcendence/venv/lib/python3.11/site-packages/rest_framework/serializers.py", line 212, in save
    self.instance = self.create(validated_data)
                    ^^^^^^^^^^^^^^^^^^^^^^^^^^^
  File "/home/ft_transcendence/src/api/serializers/account.py", line 74, in create
    user.otp_created_at = datetime.now(timezone.utc)
                          ^^^^^^^^^^^^
AttributeError: module 'datetime' has no attribute 'now'
[2024-02-12 14:39:03 +0000] [7] [INFO] Handling signal: term
[2024-02-12 14:39:03 +0000] [12] [INFO] Worker exiting (pid: 12)
[2024-02-12 14:39:04 +0000] [7] [INFO] Shutting down: Master
[2024-02-12 14:39:09 +0000] [7] [INFO] Starting gunicorn 21.2.0
[2024-02-12 14:39:09 +0000] [7] [INFO] Listening at: http://0.0.0.0:8000 (7)
[2024-02-12 14:39:09 +0000] [7] [INFO] Using worker: sync
[2024-02-12 14:39:09 +0000] [12] [INFO] Booting worker with pid: 12
Internal Server Error: /auth/login
Traceback (most recent call last):
  File "/home/ft_transcendence/venv/lib/python3.11/site-packages/django/core/handlers/exception.py", line 55, in inner
    response = get_response(request)
               ^^^^^^^^^^^^^^^^^^^^^
  File "/home/ft_transcendence/venv/lib/python3.11/site-packages/django/core/handlers/base.py", line 197, in _get_response
    response = wrapped_callback(request, *callback_args, **callback_kwargs)
               ^^^^^^^^^^^^^^^^^^^^^^^^^^^^^^^^^^^^^^^^^^^^^^^^^^^^^^^^^^^^
  File "/home/ft_transcendence/venv/lib/python3.11/site-packages/django/views/decorators/csrf.py", line 56, in wrapper_view
    return view_func(*args, **kwargs)
           ^^^^^^^^^^^^^^^^^^^^^^^^^^
  File "/home/ft_transcendence/venv/lib/python3.11/site-packages/django/views/generic/base.py", line 104, in view
    return self.dispatch(request, *args, **kwargs)
           ^^^^^^^^^^^^^^^^^^^^^^^^^^^^^^^^^^^^^^^
  File "/home/ft_transcendence/venv/lib/python3.11/site-packages/rest_framework/views.py", line 509, in dispatch
    response = self.handle_exception(exc)
               ^^^^^^^^^^^^^^^^^^^^^^^^^^
  File "/home/ft_transcendence/venv/lib/python3.11/site-packages/rest_framework/views.py", line 469, in handle_exception
    self.raise_uncaught_exception(exc)
  File "/home/ft_transcendence/venv/lib/python3.11/site-packages/rest_framework/views.py", line 480, in raise_uncaught_exception
    raise exc
  File "/home/ft_transcendence/venv/lib/python3.11/site-packages/rest_framework/views.py", line 506, in dispatch
    response = handler(request, *args, **kwargs)
               ^^^^^^^^^^^^^^^^^^^^^^^^^^^^^^^^^
  File "/home/ft_transcendence/src/api/views/account.py", line 30, in post
    user = serializer.save()
           ^^^^^^^^^^^^^^^^^
  File "/home/ft_transcendence/venv/lib/python3.11/site-packages/rest_framework/serializers.py", line 212, in save
    self.instance = self.create(validated_data)
                    ^^^^^^^^^^^^^^^^^^^^^^^^^^^
  File "/home/ft_transcendence/src/api/serializers/account.py", line 76, in create
    user.save(update_fields=["login_otp", "otp_created_at", "login_otp_used"])
  File "/home/ft_transcendence/venv/lib/python3.11/site-packages/django/contrib/auth/base_user.py", line 76, in save
    super().save(*args, **kwargs)
  File "/home/ft_transcendence/venv/lib/python3.11/site-packages/django/db/models/base.py", line 797, in save
    raise ValueError(
ValueError: The following fields do not exist in this model, are m2m fields, or are non-concrete fields: otp_created_at
[2024-02-12 14:40:16 +0000] [7] [INFO] Handling signal: term
[2024-02-12 14:40:16 +0000] [12] [INFO] Worker exiting (pid: 12)
[2024-02-12 14:40:17 +0000] [7] [INFO] Shutting down: Master
[2024-02-12 14:44:25 +0000] [7] [INFO] Starting gunicorn 21.2.0
[2024-02-12 14:44:25 +0000] [7] [INFO] Listening at: http://0.0.0.0:8000 (7)
[2024-02-12 14:44:25 +0000] [7] [INFO] Using worker: sync
[2024-02-12 14:44:25 +0000] [12] [INFO] Booting worker with pid: 12
Unauthorized: /auth/token/verify
Unauthorized: /auth/token/refresh
Unauthorized: /auth/token/verify
Unauthorized: /auth/token/refresh
Not Found: /favicon.ico
Bad Request: /auth/login
Unauthorized: /auth/token/verify
Unauthorized: /auth/token/refresh
Unauthorized: /auth/token/verify
Unauthorized: /auth/token/refresh
Unauthorized: /auth/token/verify
Unauthorized: /auth/token/refresh
Unauthorized: /auth/token/verify
Unauthorized: /auth/token/refresh
Unauthorized: /auth/token/verify
Unauthorized: /auth/token/refresh
Unauthorized: /auth/token/verify
Unauthorized: /auth/token/refresh
Unauthorized: /auth/token/verify
Unauthorized: /auth/token/refresh
Unauthorized: /auth/token/verify
Unauthorized: /auth/token/refresh
Bad Request: /auth/login
Unauthorized: /auth/token/verify
Unauthorized: /auth/token/refresh
Bad Request: /auth/login
Unauthorized: /auth/token/verify
Unauthorized: /auth/token/refresh
Unauthorized: /auth/token/verify
Unauthorized: /auth/token/refresh
Unauthorized: /auth/token/verify
Unauthorized: /auth/token/refresh
Unauthorized: /auth/token/verify
Unauthorized: /auth/token/refresh
Unauthorized: /auth/token/verify
Unauthorized: /auth/token/refresh
Unauthorized: /auth/token/verify
Unauthorized: /auth/token/refresh
Unauthorized: /auth/token/verify
Unauthorized: /auth/token/refresh
Unauthorized: /auth/token/verify
Unauthorized: /auth/token/refresh
Unauthorized: /auth/token/verify
Unauthorized: /auth/token/refresh
Not Found: /auth/otp
Not Found: /auth/otp
Not Found: /auth/otp
Unauthorized: /auth/token/verify
Unauthorized: /auth/token/refresh
Not Found: /auth/otp
Unauthorized: /auth/token/verify
Unauthorized: /auth/token/refresh
Unauthorized: /auth/token/verify
Unauthorized: /auth/token/refresh
Unauthorized: /auth/token/verify
Unauthorized: /auth/token/refresh
Unauthorized: /auth/token/verify
Unauthorized: /auth/token/refresh
Unauthorized: /auth/token/verify
Unauthorized: /auth/token/refresh
Not Found: /auth/otp
Unauthorized: /auth/token/verify
Unauthorized: /auth/token/refresh
[2024-02-12 15:09:46 +0000] [7] [INFO] Handling signal: term
[2024-02-12 15:09:46 +0000] [12] [INFO] Worker exiting (pid: 12)
[2024-02-12 15:09:46 +0000] [7] [INFO] Shutting down: Master
[2024-02-12 15:09:51 +0000] [7] [INFO] Starting gunicorn 21.2.0
[2024-02-12 15:09:51 +0000] [7] [INFO] Listening at: http://0.0.0.0:8000 (7)
[2024-02-12 15:09:51 +0000] [7] [INFO] Using worker: sync
[2024-02-12 15:09:51 +0000] [12] [INFO] Booting worker with pid: 12
Unauthorized: /auth/token/verify
Unauthorized: /auth/token/refresh
Bad Request: /auth/otp
Bad Request: /auth/otp
Unauthorized: /auth/token/verify
Unauthorized: /auth/token/refresh
Unauthorized: /auth/token/verify
Unauthorized: /auth/token/refresh
Unauthorized: /auth/token/verify
Unauthorized: /auth/token/refresh
Unauthorized: /auth/token/verify
Unauthorized: /auth/token/refresh
Unauthorized: /auth/token/verify
Unauthorized: /auth/token/refresh
Unauthorized: /auth/token/verify
Unauthorized: /auth/token/refresh
Unauthorized: /auth/token/verify
Unauthorized: /auth/token/refresh
Bad Request: /auth/otp
Bad Request: /auth/otp
Bad Request: /auth/otp
[2024-02-12 15:20:21 +0000] [7] [INFO] Handling signal: term
[2024-02-12 15:20:21 +0000] [12] [INFO] Worker exiting (pid: 12)
[2024-02-12 15:20:22 +0000] [7] [INFO] Shutting down: Master
[2024-02-12 15:20:25 +0000] [7] [INFO] Starting gunicorn 21.2.0
[2024-02-12 15:20:25 +0000] [7] [INFO] Listening at: http://0.0.0.0:8000 (7)
[2024-02-12 15:20:25 +0000] [7] [INFO] Using worker: sync
[2024-02-12 15:20:25 +0000] [12] [INFO] Booting worker with pid: 12
Internal Server Error: /auth/otp
Traceback (most recent call last):
  File "/home/ft_transcendence/venv/lib/python3.11/site-packages/django/core/handlers/exception.py", line 55, in inner
    response = get_response(request)
               ^^^^^^^^^^^^^^^^^^^^^
  File "/home/ft_transcendence/venv/lib/python3.11/site-packages/django/core/handlers/base.py", line 197, in _get_response
    response = wrapped_callback(request, *callback_args, **callback_kwargs)
               ^^^^^^^^^^^^^^^^^^^^^^^^^^^^^^^^^^^^^^^^^^^^^^^^^^^^^^^^^^^^
  File "/home/ft_transcendence/venv/lib/python3.11/site-packages/django/views/decorators/csrf.py", line 56, in wrapper_view
    return view_func(*args, **kwargs)
           ^^^^^^^^^^^^^^^^^^^^^^^^^^
  File "/home/ft_transcendence/venv/lib/python3.11/site-packages/django/views/generic/base.py", line 104, in view
    return self.dispatch(request, *args, **kwargs)
           ^^^^^^^^^^^^^^^^^^^^^^^^^^^^^^^^^^^^^^^
  File "/home/ft_transcendence/venv/lib/python3.11/site-packages/rest_framework/views.py", line 509, in dispatch
    response = self.handle_exception(exc)
               ^^^^^^^^^^^^^^^^^^^^^^^^^^
  File "/home/ft_transcendence/venv/lib/python3.11/site-packages/rest_framework/views.py", line 469, in handle_exception
    self.raise_uncaught_exception(exc)
  File "/home/ft_transcendence/venv/lib/python3.11/site-packages/rest_framework/views.py", line 480, in raise_uncaught_exception
    raise exc
  File "/home/ft_transcendence/venv/lib/python3.11/site-packages/rest_framework/views.py", line 506, in dispatch
    response = handler(request, *args, **kwargs)
               ^^^^^^^^^^^^^^^^^^^^^^^^^^^^^^^^^
  File "/home/ft_transcendence/src/api/views/account.py", line 46, in post
    serializer.is_valid(raise_exception=True)
  File "/home/ft_transcendence/venv/lib/python3.11/site-packages/rest_framework/serializers.py", line 227, in is_valid
    self._validated_data = self.run_validation(self.initial_data)
                           ^^^^^^^^^^^^^^^^^^^^^^^^^^^^^^^^^^^^^^
  File "/home/ft_transcendence/venv/lib/python3.11/site-packages/rest_framework/serializers.py", line 429, in run_validation
    value = self.validate(value)
            ^^^^^^^^^^^^^^^^^^^^
  File "/home/ft_transcendence/src/api/serializers/account.py", line 84, in validate
    user: User = User.objects.filter(id=attrs.get("id")).first()
                 ^^^^
NameError: name 'User' is not defined
[2024-02-12 15:22:05 +0000] [7] [INFO] Handling signal: term
[2024-02-12 15:22:05 +0000] [12] [INFO] Worker exiting (pid: 12)
[2024-02-12 15:22:05 +0000] [7] [INFO] Shutting down: Master
[2024-02-12 15:22:09 +0000] [7] [INFO] Starting gunicorn 21.2.0
[2024-02-12 15:22:09 +0000] [7] [INFO] Listening at: http://0.0.0.0:8000 (7)
[2024-02-12 15:22:09 +0000] [7] [INFO] Using worker: sync
[2024-02-12 15:22:09 +0000] [12] [INFO] Booting worker with pid: 12
Internal Server Error: /auth/otp
Traceback (most recent call last):
  File "/home/ft_transcendence/venv/lib/python3.11/site-packages/django/core/handlers/exception.py", line 55, in inner
    response = get_response(request)
               ^^^^^^^^^^^^^^^^^^^^^
  File "/home/ft_transcendence/venv/lib/python3.11/site-packages/django/core/handlers/base.py", line 197, in _get_response
    response = wrapped_callback(request, *callback_args, **callback_kwargs)
               ^^^^^^^^^^^^^^^^^^^^^^^^^^^^^^^^^^^^^^^^^^^^^^^^^^^^^^^^^^^^
  File "/home/ft_transcendence/venv/lib/python3.11/site-packages/django/views/decorators/csrf.py", line 56, in wrapper_view
    return view_func(*args, **kwargs)
           ^^^^^^^^^^^^^^^^^^^^^^^^^^
  File "/home/ft_transcendence/venv/lib/python3.11/site-packages/django/views/generic/base.py", line 104, in view
    return self.dispatch(request, *args, **kwargs)
           ^^^^^^^^^^^^^^^^^^^^^^^^^^^^^^^^^^^^^^^
  File "/home/ft_transcendence/venv/lib/python3.11/site-packages/rest_framework/views.py", line 509, in dispatch
    response = self.handle_exception(exc)
               ^^^^^^^^^^^^^^^^^^^^^^^^^^
  File "/home/ft_transcendence/venv/lib/python3.11/site-packages/rest_framework/views.py", line 469, in handle_exception
    self.raise_uncaught_exception(exc)
  File "/home/ft_transcendence/venv/lib/python3.11/site-packages/rest_framework/views.py", line 480, in raise_uncaught_exception
    raise exc
  File "/home/ft_transcendence/venv/lib/python3.11/site-packages/rest_framework/views.py", line 506, in dispatch
    response = handler(request, *args, **kwargs)
               ^^^^^^^^^^^^^^^^^^^^^^^^^^^^^^^^^
  File "/home/ft_transcendence/src/api/views/account.py", line 46, in post
    serializer.is_valid(raise_exception=True)
  File "/home/ft_transcendence/venv/lib/python3.11/site-packages/rest_framework/serializers.py", line 227, in is_valid
    self._validated_data = self.run_validation(self.initial_data)
                           ^^^^^^^^^^^^^^^^^^^^^^^^^^^^^^^^^^^^^^
  File "/home/ft_transcendence/venv/lib/python3.11/site-packages/rest_framework/serializers.py", line 429, in run_validation
    value = self.validate(value)
            ^^^^^^^^^^^^^^^^^^^^
  File "/home/ft_transcendence/src/api/serializers/account.py", line 89, in validate
    not check_password(attrs.get("otp"), user.login_otp)
        ^^^^^^^^^^^^^^
NameError: name 'check_password' is not defined
[2024-02-12 15:23:54 +0000] [7] [INFO] Handling signal: term
[2024-02-12 15:23:54 +0000] [12] [INFO] Worker exiting (pid: 12)
[2024-02-12 15:23:54 +0000] [7] [INFO] Shutting down: Master
[2024-02-12 15:23:57 +0000] [7] [INFO] Starting gunicorn 21.2.0
[2024-02-12 15:23:57 +0000] [7] [INFO] Listening at: http://0.0.0.0:8000 (7)
[2024-02-12 15:23:57 +0000] [7] [INFO] Using worker: sync
[2024-02-12 15:23:57 +0000] [12] [INFO] Booting worker with pid: 12
Internal Server Error: /auth/otp
Traceback (most recent call last):
  File "/home/ft_transcendence/venv/lib/python3.11/site-packages/django/core/handlers/exception.py", line 55, in inner
    response = get_response(request)
               ^^^^^^^^^^^^^^^^^^^^^
  File "/home/ft_transcendence/venv/lib/python3.11/site-packages/django/core/handlers/base.py", line 197, in _get_response
    response = wrapped_callback(request, *callback_args, **callback_kwargs)
               ^^^^^^^^^^^^^^^^^^^^^^^^^^^^^^^^^^^^^^^^^^^^^^^^^^^^^^^^^^^^
  File "/home/ft_transcendence/venv/lib/python3.11/site-packages/django/views/decorators/csrf.py", line 56, in wrapper_view
    return view_func(*args, **kwargs)
           ^^^^^^^^^^^^^^^^^^^^^^^^^^
  File "/home/ft_transcendence/venv/lib/python3.11/site-packages/django/views/generic/base.py", line 104, in view
    return self.dispatch(request, *args, **kwargs)
           ^^^^^^^^^^^^^^^^^^^^^^^^^^^^^^^^^^^^^^^
  File "/home/ft_transcendence/venv/lib/python3.11/site-packages/rest_framework/views.py", line 509, in dispatch
    response = self.handle_exception(exc)
               ^^^^^^^^^^^^^^^^^^^^^^^^^^
  File "/home/ft_transcendence/venv/lib/python3.11/site-packages/rest_framework/views.py", line 469, in handle_exception
    self.raise_uncaught_exception(exc)
  File "/home/ft_transcendence/venv/lib/python3.11/site-packages/rest_framework/views.py", line 480, in raise_uncaught_exception
    raise exc
  File "/home/ft_transcendence/venv/lib/python3.11/site-packages/rest_framework/views.py", line 506, in dispatch
    response = handler(request, *args, **kwargs)
               ^^^^^^^^^^^^^^^^^^^^^^^^^^^^^^^^^
  File "/home/ft_transcendence/src/api/views/account.py", line 47, in post
    login_info: dict = serializer.save()
                       ^^^^^^^^^^^^^^^^^
  File "/home/ft_transcendence/venv/lib/python3.11/site-packages/rest_framework/serializers.py", line 212, in save
    self.instance = self.create(validated_data)
                    ^^^^^^^^^^^^^^^^^^^^^^^^^^^
  File "/home/ft_transcendence/src/api/serializers/account.py", line 98, in create
    refresh = RefreshToken.for_user(user)
              ^^^^^^^^^^^^
NameError: name 'RefreshToken' is not defined
[2024-02-12 15:25:29 +0000] [7] [INFO] Handling signal: term
[2024-02-12 15:25:29 +0000] [12] [INFO] Worker exiting (pid: 12)
[2024-02-12 15:25:29 +0000] [7] [INFO] Shutting down: Master
[2024-02-12 15:25:32 +0000] [7] [INFO] Starting gunicorn 21.2.0
[2024-02-12 15:25:32 +0000] [7] [INFO] Listening at: http://0.0.0.0:8000 (7)
[2024-02-12 15:25:32 +0000] [7] [INFO] Using worker: sync
[2024-02-12 15:25:32 +0000] [12] [INFO] Booting worker with pid: 12
Internal Server Error: /auth/otp
Traceback (most recent call last):
  File "/home/ft_transcendence/venv/lib/python3.11/site-packages/django/core/handlers/exception.py", line 55, in inner
    response = get_response(request)
               ^^^^^^^^^^^^^^^^^^^^^
  File "/home/ft_transcendence/venv/lib/python3.11/site-packages/django/core/handlers/base.py", line 197, in _get_response
    response = wrapped_callback(request, *callback_args, **callback_kwargs)
               ^^^^^^^^^^^^^^^^^^^^^^^^^^^^^^^^^^^^^^^^^^^^^^^^^^^^^^^^^^^^
  File "/home/ft_transcendence/venv/lib/python3.11/site-packages/django/views/decorators/csrf.py", line 56, in wrapper_view
    return view_func(*args, **kwargs)
           ^^^^^^^^^^^^^^^^^^^^^^^^^^
  File "/home/ft_transcendence/venv/lib/python3.11/site-packages/django/views/generic/base.py", line 104, in view
    return self.dispatch(request, *args, **kwargs)
           ^^^^^^^^^^^^^^^^^^^^^^^^^^^^^^^^^^^^^^^
  File "/home/ft_transcendence/venv/lib/python3.11/site-packages/rest_framework/views.py", line 509, in dispatch
    response = self.handle_exception(exc)
               ^^^^^^^^^^^^^^^^^^^^^^^^^^
  File "/home/ft_transcendence/venv/lib/python3.11/site-packages/rest_framework/views.py", line 469, in handle_exception
    self.raise_uncaught_exception(exc)
  File "/home/ft_transcendence/venv/lib/python3.11/site-packages/rest_framework/views.py", line 480, in raise_uncaught_exception
    raise exc
  File "/home/ft_transcendence/venv/lib/python3.11/site-packages/rest_framework/views.py", line 506, in dispatch
    response = handler(request, *args, **kwargs)
               ^^^^^^^^^^^^^^^^^^^^^^^^^^^^^^^^^
  File "/home/ft_transcendence/src/api/views/account.py", line 46, in post
    serializer.is_valid(raise_exception=True)
  File "/home/ft_transcendence/venv/lib/python3.11/site-packages/rest_framework/serializers.py", line 227, in is_valid
    self._validated_data = self.run_validation(self.initial_data)
                           ^^^^^^^^^^^^^^^^^^^^^^^^^^^^^^^^^^^^^^
  File "/home/ft_transcendence/venv/lib/python3.11/site-packages/rest_framework/serializers.py", line 429, in run_validation
    value = self.validate(value)
            ^^^^^^^^^^^^^^^^^^^^
  File "/home/ft_transcendence/src/api/serializers/account.py", line 91, in validate
    or not user.is_valid_otp()
           ^^^^^^^^^^^^^^^^^
AttributeError: 'Account' object has no attribute 'is_valid_otp'
[2024-02-12 15:26:55 +0000] [7] [INFO] Handling signal: term
[2024-02-12 15:26:55 +0000] [12] [INFO] Worker exiting (pid: 12)
[2024-02-12 15:26:55 +0000] [7] [INFO] Shutting down: Master
[2024-02-12 15:26:59 +0000] [7] [INFO] Starting gunicorn 21.2.0
[2024-02-12 15:26:59 +0000] [7] [INFO] Listening at: http://0.0.0.0:8000 (7)
[2024-02-12 15:26:59 +0000] [7] [INFO] Using worker: sync
[2024-02-12 15:26:59 +0000] [12] [INFO] Booting worker with pid: 12
Internal Server Error: /auth/otp
Traceback (most recent call last):
  File "/home/ft_transcendence/venv/lib/python3.11/site-packages/django/core/handlers/exception.py", line 55, in inner
    response = get_response(request)
               ^^^^^^^^^^^^^^^^^^^^^
  File "/home/ft_transcendence/venv/lib/python3.11/site-packages/django/core/handlers/base.py", line 197, in _get_response
    response = wrapped_callback(request, *callback_args, **callback_kwargs)
               ^^^^^^^^^^^^^^^^^^^^^^^^^^^^^^^^^^^^^^^^^^^^^^^^^^^^^^^^^^^^
  File "/home/ft_transcendence/venv/lib/python3.11/site-packages/django/views/decorators/csrf.py", line 56, in wrapper_view
    return view_func(*args, **kwargs)
           ^^^^^^^^^^^^^^^^^^^^^^^^^^
  File "/home/ft_transcendence/venv/lib/python3.11/site-packages/django/views/generic/base.py", line 104, in view
    return self.dispatch(request, *args, **kwargs)
           ^^^^^^^^^^^^^^^^^^^^^^^^^^^^^^^^^^^^^^^
  File "/home/ft_transcendence/venv/lib/python3.11/site-packages/rest_framework/views.py", line 509, in dispatch
    response = self.handle_exception(exc)
               ^^^^^^^^^^^^^^^^^^^^^^^^^^
  File "/home/ft_transcendence/venv/lib/python3.11/site-packages/rest_framework/views.py", line 469, in handle_exception
    self.raise_uncaught_exception(exc)
  File "/home/ft_transcendence/venv/lib/python3.11/site-packages/rest_framework/views.py", line 480, in raise_uncaught_exception
    raise exc
  File "/home/ft_transcendence/venv/lib/python3.11/site-packages/rest_framework/views.py", line 506, in dispatch
    response = handler(request, *args, **kwargs)
               ^^^^^^^^^^^^^^^^^^^^^^^^^^^^^^^^^
  File "/home/ft_transcendence/src/api/views/account.py", line 46, in post
    serializer.is_valid(raise_exception=True)
  File "/home/ft_transcendence/venv/lib/python3.11/site-packages/rest_framework/serializers.py", line 227, in is_valid
    self._validated_data = self.run_validation(self.initial_data)
                           ^^^^^^^^^^^^^^^^^^^^^^^^^^^^^^^^^^^^^^
  File "/home/ft_transcendence/venv/lib/python3.11/site-packages/rest_framework/serializers.py", line 429, in run_validation
    value = self.validate(value)
            ^^^^^^^^^^^^^^^^^^^^
  File "/home/ft_transcendence/src/api/serializers/account.py", line 89, in validate
    or not user.is_valid_otp()
           ^^^^^^^^^^^^^^^^^
AttributeError: 'Account' object has no attribute 'is_valid_otp'
[2024-02-12 15:29:03 +0000] [7] [INFO] Handling signal: term
[2024-02-12 15:29:03 +0000] [12] [INFO] Worker exiting (pid: 12)
[2024-02-12 15:29:04 +0000] [7] [INFO] Shutting down: Master
[2024-02-12 15:29:07 +0000] [7] [INFO] Starting gunicorn 21.2.0
[2024-02-12 15:29:07 +0000] [7] [INFO] Listening at: http://0.0.0.0:8000 (7)
[2024-02-12 15:29:07 +0000] [7] [INFO] Using worker: sync
[2024-02-12 15:29:07 +0000] [12] [INFO] Booting worker with pid: 12
[2024-02-12 15:30:18 +0000] [7] [INFO] Handling signal: term
[2024-02-12 15:30:18 +0000] [12] [INFO] Worker exiting (pid: 12)
[2024-02-12 15:30:19 +0000] [7] [INFO] Shutting down: Master
[2024-02-13 11:51:09 +0000] [7] [INFO] Starting gunicorn 21.2.0
[2024-02-13 11:51:09 +0000] [7] [INFO] Listening at: http://0.0.0.0:8000 (7)
[2024-02-13 11:51:09 +0000] [7] [INFO] Using worker: sync
[2024-02-13 11:51:09 +0000] [12] [INFO] Booting worker with pid: 12
Internal Server Error: /auth/otp
Traceback (most recent call last):
  File "/home/ft_transcendence/venv/lib/python3.11/site-packages/django/core/handlers/exception.py", line 55, in inner
    response = get_response(request)
               ^^^^^^^^^^^^^^^^^^^^^
  File "/home/ft_transcendence/venv/lib/python3.11/site-packages/django/core/handlers/base.py", line 197, in _get_response
    response = wrapped_callback(request, *callback_args, **callback_kwargs)
               ^^^^^^^^^^^^^^^^^^^^^^^^^^^^^^^^^^^^^^^^^^^^^^^^^^^^^^^^^^^^
  File "/home/ft_transcendence/venv/lib/python3.11/site-packages/django/views/decorators/csrf.py", line 56, in wrapper_view
    return view_func(*args, **kwargs)
           ^^^^^^^^^^^^^^^^^^^^^^^^^^
  File "/home/ft_transcendence/venv/lib/python3.11/site-packages/django/views/generic/base.py", line 104, in view
    return self.dispatch(request, *args, **kwargs)
           ^^^^^^^^^^^^^^^^^^^^^^^^^^^^^^^^^^^^^^^
  File "/home/ft_transcendence/venv/lib/python3.11/site-packages/rest_framework/views.py", line 509, in dispatch
    response = self.handle_exception(exc)
               ^^^^^^^^^^^^^^^^^^^^^^^^^^
  File "/home/ft_transcendence/venv/lib/python3.11/site-packages/rest_framework/views.py", line 469, in handle_exception
    self.raise_uncaught_exception(exc)
  File "/home/ft_transcendence/venv/lib/python3.11/site-packages/rest_framework/views.py", line 480, in raise_uncaught_exception
    raise exc
  File "/home/ft_transcendence/venv/lib/python3.11/site-packages/rest_framework/views.py", line 506, in dispatch
    response = handler(request, *args, **kwargs)
               ^^^^^^^^^^^^^^^^^^^^^^^^^^^^^^^^^
  File "/home/ft_transcendence/src/api/views/account.py", line 46, in post
    serializer.is_valid(raise_exception=True)
  File "/home/ft_transcendence/venv/lib/python3.11/site-packages/rest_framework/serializers.py", line 227, in is_valid
    self._validated_data = self.run_validation(self.initial_data)
                           ^^^^^^^^^^^^^^^^^^^^^^^^^^^^^^^^^^^^^^
  File "/home/ft_transcendence/venv/lib/python3.11/site-packages/rest_framework/serializers.py", line 429, in run_validation
    value = self.validate(value)
            ^^^^^^^^^^^^^^^^^^^^
  File "/home/ft_transcendence/src/api/serializers/account.py", line 90, in validate
    or not user.is_valid_otp()
           ^^^^^^^^^^^^^^^^^
AttributeError: 'Account' object has no attribute 'is_valid_otp'
Internal Server Error: /auth/otp
Traceback (most recent call last):
  File "/home/ft_transcendence/venv/lib/python3.11/site-packages/django/core/handlers/exception.py", line 55, in inner
    response = get_response(request)
               ^^^^^^^^^^^^^^^^^^^^^
  File "/home/ft_transcendence/venv/lib/python3.11/site-packages/django/core/handlers/base.py", line 197, in _get_response
    response = wrapped_callback(request, *callback_args, **callback_kwargs)
               ^^^^^^^^^^^^^^^^^^^^^^^^^^^^^^^^^^^^^^^^^^^^^^^^^^^^^^^^^^^^
  File "/home/ft_transcendence/venv/lib/python3.11/site-packages/django/views/decorators/csrf.py", line 56, in wrapper_view
    return view_func(*args, **kwargs)
           ^^^^^^^^^^^^^^^^^^^^^^^^^^
  File "/home/ft_transcendence/venv/lib/python3.11/site-packages/django/views/generic/base.py", line 104, in view
    return self.dispatch(request, *args, **kwargs)
           ^^^^^^^^^^^^^^^^^^^^^^^^^^^^^^^^^^^^^^^
  File "/home/ft_transcendence/venv/lib/python3.11/site-packages/rest_framework/views.py", line 509, in dispatch
    response = self.handle_exception(exc)
               ^^^^^^^^^^^^^^^^^^^^^^^^^^
  File "/home/ft_transcendence/venv/lib/python3.11/site-packages/rest_framework/views.py", line 469, in handle_exception
    self.raise_uncaught_exception(exc)
  File "/home/ft_transcendence/venv/lib/python3.11/site-packages/rest_framework/views.py", line 480, in raise_uncaught_exception
    raise exc
  File "/home/ft_transcendence/venv/lib/python3.11/site-packages/rest_framework/views.py", line 506, in dispatch
    response = handler(request, *args, **kwargs)
               ^^^^^^^^^^^^^^^^^^^^^^^^^^^^^^^^^
  File "/home/ft_transcendence/src/api/views/account.py", line 46, in post
    serializer.is_valid(raise_exception=True)
  File "/home/ft_transcendence/venv/lib/python3.11/site-packages/rest_framework/serializers.py", line 227, in is_valid
    self._validated_data = self.run_validation(self.initial_data)
                           ^^^^^^^^^^^^^^^^^^^^^^^^^^^^^^^^^^^^^^
  File "/home/ft_transcendence/venv/lib/python3.11/site-packages/rest_framework/serializers.py", line 429, in run_validation
    value = self.validate(value)
            ^^^^^^^^^^^^^^^^^^^^
  File "/home/ft_transcendence/src/api/serializers/account.py", line 90, in validate
    or not user.is_valid_otp()
           ^^^^^^^^^^^^^^^^^
AttributeError: 'Account' object has no attribute 'is_valid_otp'
Internal Server Error: /auth/otp
Traceback (most recent call last):
  File "/home/ft_transcendence/venv/lib/python3.11/site-packages/django/core/handlers/exception.py", line 55, in inner
    response = get_response(request)
               ^^^^^^^^^^^^^^^^^^^^^
  File "/home/ft_transcendence/venv/lib/python3.11/site-packages/django/core/handlers/base.py", line 197, in _get_response
    response = wrapped_callback(request, *callback_args, **callback_kwargs)
               ^^^^^^^^^^^^^^^^^^^^^^^^^^^^^^^^^^^^^^^^^^^^^^^^^^^^^^^^^^^^
  File "/home/ft_transcendence/venv/lib/python3.11/site-packages/django/views/decorators/csrf.py", line 56, in wrapper_view
    return view_func(*args, **kwargs)
           ^^^^^^^^^^^^^^^^^^^^^^^^^^
  File "/home/ft_transcendence/venv/lib/python3.11/site-packages/django/views/generic/base.py", line 104, in view
    return self.dispatch(request, *args, **kwargs)
           ^^^^^^^^^^^^^^^^^^^^^^^^^^^^^^^^^^^^^^^
  File "/home/ft_transcendence/venv/lib/python3.11/site-packages/rest_framework/views.py", line 509, in dispatch
    response = self.handle_exception(exc)
               ^^^^^^^^^^^^^^^^^^^^^^^^^^
  File "/home/ft_transcendence/venv/lib/python3.11/site-packages/rest_framework/views.py", line 469, in handle_exception
    self.raise_uncaught_exception(exc)
  File "/home/ft_transcendence/venv/lib/python3.11/site-packages/rest_framework/views.py", line 480, in raise_uncaught_exception
    raise exc
  File "/home/ft_transcendence/venv/lib/python3.11/site-packages/rest_framework/views.py", line 506, in dispatch
    response = handler(request, *args, **kwargs)
               ^^^^^^^^^^^^^^^^^^^^^^^^^^^^^^^^^
  File "/home/ft_transcendence/src/api/views/account.py", line 46, in post
    serializer.is_valid(raise_exception=True)
  File "/home/ft_transcendence/venv/lib/python3.11/site-packages/rest_framework/serializers.py", line 227, in is_valid
    self._validated_data = self.run_validation(self.initial_data)
                           ^^^^^^^^^^^^^^^^^^^^^^^^^^^^^^^^^^^^^^
  File "/home/ft_transcendence/venv/lib/python3.11/site-packages/rest_framework/serializers.py", line 429, in run_validation
    value = self.validate(value)
            ^^^^^^^^^^^^^^^^^^^^
  File "/home/ft_transcendence/src/api/serializers/account.py", line 90, in validate
    or not user.is_valid_otp()
           ^^^^^^^^^^^^^^^^^
AttributeError: 'Account' object has no attribute 'is_valid_otp'
Internal Server Error: /auth/otp
Traceback (most recent call last):
  File "/home/ft_transcendence/venv/lib/python3.11/site-packages/django/core/handlers/exception.py", line 55, in inner
    response = get_response(request)
               ^^^^^^^^^^^^^^^^^^^^^
  File "/home/ft_transcendence/venv/lib/python3.11/site-packages/django/core/handlers/base.py", line 197, in _get_response
    response = wrapped_callback(request, *callback_args, **callback_kwargs)
               ^^^^^^^^^^^^^^^^^^^^^^^^^^^^^^^^^^^^^^^^^^^^^^^^^^^^^^^^^^^^
  File "/home/ft_transcendence/venv/lib/python3.11/site-packages/django/views/decorators/csrf.py", line 56, in wrapper_view
    return view_func(*args, **kwargs)
           ^^^^^^^^^^^^^^^^^^^^^^^^^^
  File "/home/ft_transcendence/venv/lib/python3.11/site-packages/django/views/generic/base.py", line 104, in view
    return self.dispatch(request, *args, **kwargs)
           ^^^^^^^^^^^^^^^^^^^^^^^^^^^^^^^^^^^^^^^
  File "/home/ft_transcendence/venv/lib/python3.11/site-packages/rest_framework/views.py", line 509, in dispatch
    response = self.handle_exception(exc)
               ^^^^^^^^^^^^^^^^^^^^^^^^^^
  File "/home/ft_transcendence/venv/lib/python3.11/site-packages/rest_framework/views.py", line 469, in handle_exception
    self.raise_uncaught_exception(exc)
  File "/home/ft_transcendence/venv/lib/python3.11/site-packages/rest_framework/views.py", line 480, in raise_uncaught_exception
    raise exc
  File "/home/ft_transcendence/venv/lib/python3.11/site-packages/rest_framework/views.py", line 506, in dispatch
    response = handler(request, *args, **kwargs)
               ^^^^^^^^^^^^^^^^^^^^^^^^^^^^^^^^^
  File "/home/ft_transcendence/src/api/views/account.py", line 46, in post
    serializer.is_valid(raise_exception=True)
  File "/home/ft_transcendence/venv/lib/python3.11/site-packages/rest_framework/serializers.py", line 227, in is_valid
    self._validated_data = self.run_validation(self.initial_data)
                           ^^^^^^^^^^^^^^^^^^^^^^^^^^^^^^^^^^^^^^
  File "/home/ft_transcendence/venv/lib/python3.11/site-packages/rest_framework/serializers.py", line 429, in run_validation
    value = self.validate(value)
            ^^^^^^^^^^^^^^^^^^^^
  File "/home/ft_transcendence/src/api/serializers/account.py", line 90, in validate
    or not user.is_valid_otp()
           ^^^^^^^^^^^^^^^^^
AttributeError: 'Account' object has no attribute 'is_valid_otp'
Internal Server Error: /auth/otp
Traceback (most recent call last):
  File "/home/ft_transcendence/venv/lib/python3.11/site-packages/django/core/handlers/exception.py", line 55, in inner
    response = get_response(request)
               ^^^^^^^^^^^^^^^^^^^^^
  File "/home/ft_transcendence/venv/lib/python3.11/site-packages/django/core/handlers/base.py", line 197, in _get_response
    response = wrapped_callback(request, *callback_args, **callback_kwargs)
               ^^^^^^^^^^^^^^^^^^^^^^^^^^^^^^^^^^^^^^^^^^^^^^^^^^^^^^^^^^^^
  File "/home/ft_transcendence/venv/lib/python3.11/site-packages/django/views/decorators/csrf.py", line 56, in wrapper_view
    return view_func(*args, **kwargs)
           ^^^^^^^^^^^^^^^^^^^^^^^^^^
  File "/home/ft_transcendence/venv/lib/python3.11/site-packages/django/views/generic/base.py", line 104, in view
    return self.dispatch(request, *args, **kwargs)
           ^^^^^^^^^^^^^^^^^^^^^^^^^^^^^^^^^^^^^^^
  File "/home/ft_transcendence/venv/lib/python3.11/site-packages/rest_framework/views.py", line 509, in dispatch
    response = self.handle_exception(exc)
               ^^^^^^^^^^^^^^^^^^^^^^^^^^
  File "/home/ft_transcendence/venv/lib/python3.11/site-packages/rest_framework/views.py", line 469, in handle_exception
    self.raise_uncaught_exception(exc)
  File "/home/ft_transcendence/venv/lib/python3.11/site-packages/rest_framework/views.py", line 480, in raise_uncaught_exception
    raise exc
  File "/home/ft_transcendence/venv/lib/python3.11/site-packages/rest_framework/views.py", line 506, in dispatch
    response = handler(request, *args, **kwargs)
               ^^^^^^^^^^^^^^^^^^^^^^^^^^^^^^^^^
  File "/home/ft_transcendence/src/api/views/account.py", line 46, in post
    serializer.is_valid(raise_exception=True)
  File "/home/ft_transcendence/venv/lib/python3.11/site-packages/rest_framework/serializers.py", line 227, in is_valid
    self._validated_data = self.run_validation(self.initial_data)
                           ^^^^^^^^^^^^^^^^^^^^^^^^^^^^^^^^^^^^^^
  File "/home/ft_transcendence/venv/lib/python3.11/site-packages/rest_framework/serializers.py", line 429, in run_validation
    value = self.validate(value)
            ^^^^^^^^^^^^^^^^^^^^
  File "/home/ft_transcendence/src/api/serializers/account.py", line 90, in validate
    or not user.is_valid_otp()
           ^^^^^^^^^^^^^^^^^
AttributeError: 'Account' object has no attribute 'is_valid_otp'
Internal Server Error: /auth/otp
Traceback (most recent call last):
  File "/home/ft_transcendence/venv/lib/python3.11/site-packages/django/core/handlers/exception.py", line 55, in inner
    response = get_response(request)
               ^^^^^^^^^^^^^^^^^^^^^
  File "/home/ft_transcendence/venv/lib/python3.11/site-packages/django/core/handlers/base.py", line 197, in _get_response
    response = wrapped_callback(request, *callback_args, **callback_kwargs)
               ^^^^^^^^^^^^^^^^^^^^^^^^^^^^^^^^^^^^^^^^^^^^^^^^^^^^^^^^^^^^
  File "/home/ft_transcendence/venv/lib/python3.11/site-packages/django/views/decorators/csrf.py", line 56, in wrapper_view
    return view_func(*args, **kwargs)
           ^^^^^^^^^^^^^^^^^^^^^^^^^^
  File "/home/ft_transcendence/venv/lib/python3.11/site-packages/django/views/generic/base.py", line 104, in view
    return self.dispatch(request, *args, **kwargs)
           ^^^^^^^^^^^^^^^^^^^^^^^^^^^^^^^^^^^^^^^
  File "/home/ft_transcendence/venv/lib/python3.11/site-packages/rest_framework/views.py", line 509, in dispatch
    response = self.handle_exception(exc)
               ^^^^^^^^^^^^^^^^^^^^^^^^^^
  File "/home/ft_transcendence/venv/lib/python3.11/site-packages/rest_framework/views.py", line 469, in handle_exception
    self.raise_uncaught_exception(exc)
  File "/home/ft_transcendence/venv/lib/python3.11/site-packages/rest_framework/views.py", line 480, in raise_uncaught_exception
    raise exc
  File "/home/ft_transcendence/venv/lib/python3.11/site-packages/rest_framework/views.py", line 506, in dispatch
    response = handler(request, *args, **kwargs)
               ^^^^^^^^^^^^^^^^^^^^^^^^^^^^^^^^^
  File "/home/ft_transcendence/src/api/views/account.py", line 46, in post
    serializer.is_valid(raise_exception=True)
  File "/home/ft_transcendence/venv/lib/python3.11/site-packages/rest_framework/serializers.py", line 227, in is_valid
    self._validated_data = self.run_validation(self.initial_data)
                           ^^^^^^^^^^^^^^^^^^^^^^^^^^^^^^^^^^^^^^
  File "/home/ft_transcendence/venv/lib/python3.11/site-packages/rest_framework/serializers.py", line 429, in run_validation
    value = self.validate(value)
            ^^^^^^^^^^^^^^^^^^^^
  File "/home/ft_transcendence/src/api/serializers/account.py", line 90, in validate
    or not user.is_valid_otp()
           ^^^^^^^^^^^^^^^^^
AttributeError: 'Account' object has no attribute 'is_valid_otp'
Internal Server Error: /auth/otp
Traceback (most recent call last):
  File "/home/ft_transcendence/venv/lib/python3.11/site-packages/django/core/handlers/exception.py", line 55, in inner
    response = get_response(request)
               ^^^^^^^^^^^^^^^^^^^^^
  File "/home/ft_transcendence/venv/lib/python3.11/site-packages/django/core/handlers/base.py", line 197, in _get_response
    response = wrapped_callback(request, *callback_args, **callback_kwargs)
               ^^^^^^^^^^^^^^^^^^^^^^^^^^^^^^^^^^^^^^^^^^^^^^^^^^^^^^^^^^^^
  File "/home/ft_transcendence/venv/lib/python3.11/site-packages/django/views/decorators/csrf.py", line 56, in wrapper_view
    return view_func(*args, **kwargs)
           ^^^^^^^^^^^^^^^^^^^^^^^^^^
  File "/home/ft_transcendence/venv/lib/python3.11/site-packages/django/views/generic/base.py", line 104, in view
    return self.dispatch(request, *args, **kwargs)
           ^^^^^^^^^^^^^^^^^^^^^^^^^^^^^^^^^^^^^^^
  File "/home/ft_transcendence/venv/lib/python3.11/site-packages/rest_framework/views.py", line 509, in dispatch
    response = self.handle_exception(exc)
               ^^^^^^^^^^^^^^^^^^^^^^^^^^
  File "/home/ft_transcendence/venv/lib/python3.11/site-packages/rest_framework/views.py", line 469, in handle_exception
    self.raise_uncaught_exception(exc)
  File "/home/ft_transcendence/venv/lib/python3.11/site-packages/rest_framework/views.py", line 480, in raise_uncaught_exception
    raise exc
  File "/home/ft_transcendence/venv/lib/python3.11/site-packages/rest_framework/views.py", line 506, in dispatch
    response = handler(request, *args, **kwargs)
               ^^^^^^^^^^^^^^^^^^^^^^^^^^^^^^^^^
  File "/home/ft_transcendence/src/api/views/account.py", line 46, in post
    serializer.is_valid(raise_exception=True)
  File "/home/ft_transcendence/venv/lib/python3.11/site-packages/rest_framework/serializers.py", line 227, in is_valid
    self._validated_data = self.run_validation(self.initial_data)
                           ^^^^^^^^^^^^^^^^^^^^^^^^^^^^^^^^^^^^^^
  File "/home/ft_transcendence/venv/lib/python3.11/site-packages/rest_framework/serializers.py", line 429, in run_validation
    value = self.validate(value)
            ^^^^^^^^^^^^^^^^^^^^
  File "/home/ft_transcendence/src/api/serializers/account.py", line 90, in validate
    or not user.is_valid_otp()
           ^^^^^^^^^^^^^^^^^
AttributeError: 'Account' object has no attribute 'is_valid_otp'
Internal Server Error: /auth/otp
Traceback (most recent call last):
  File "/home/ft_transcendence/venv/lib/python3.11/site-packages/django/core/handlers/exception.py", line 55, in inner
    response = get_response(request)
               ^^^^^^^^^^^^^^^^^^^^^
  File "/home/ft_transcendence/venv/lib/python3.11/site-packages/django/core/handlers/base.py", line 197, in _get_response
    response = wrapped_callback(request, *callback_args, **callback_kwargs)
               ^^^^^^^^^^^^^^^^^^^^^^^^^^^^^^^^^^^^^^^^^^^^^^^^^^^^^^^^^^^^
  File "/home/ft_transcendence/venv/lib/python3.11/site-packages/django/views/decorators/csrf.py", line 56, in wrapper_view
    return view_func(*args, **kwargs)
           ^^^^^^^^^^^^^^^^^^^^^^^^^^
  File "/home/ft_transcendence/venv/lib/python3.11/site-packages/django/views/generic/base.py", line 104, in view
    return self.dispatch(request, *args, **kwargs)
           ^^^^^^^^^^^^^^^^^^^^^^^^^^^^^^^^^^^^^^^
  File "/home/ft_transcendence/venv/lib/python3.11/site-packages/rest_framework/views.py", line 509, in dispatch
    response = self.handle_exception(exc)
               ^^^^^^^^^^^^^^^^^^^^^^^^^^
  File "/home/ft_transcendence/venv/lib/python3.11/site-packages/rest_framework/views.py", line 469, in handle_exception
    self.raise_uncaught_exception(exc)
  File "/home/ft_transcendence/venv/lib/python3.11/site-packages/rest_framework/views.py", line 480, in raise_uncaught_exception
    raise exc
  File "/home/ft_transcendence/venv/lib/python3.11/site-packages/rest_framework/views.py", line 506, in dispatch
    response = handler(request, *args, **kwargs)
               ^^^^^^^^^^^^^^^^^^^^^^^^^^^^^^^^^
  File "/home/ft_transcendence/src/api/views/account.py", line 46, in post
    serializer.is_valid(raise_exception=True)
  File "/home/ft_transcendence/venv/lib/python3.11/site-packages/rest_framework/serializers.py", line 227, in is_valid
    self._validated_data = self.run_validation(self.initial_data)
                           ^^^^^^^^^^^^^^^^^^^^^^^^^^^^^^^^^^^^^^
  File "/home/ft_transcendence/venv/lib/python3.11/site-packages/rest_framework/serializers.py", line 429, in run_validation
    value = self.validate(value)
            ^^^^^^^^^^^^^^^^^^^^
  File "/home/ft_transcendence/src/api/serializers/account.py", line 90, in validate
    or not user.is_valid_otp()
           ^^^^^^^^^^^^^^^^^
AttributeError: 'Account' object has no attribute 'is_valid_otp'
Internal Server Error: /auth/otp
Traceback (most recent call last):
  File "/home/ft_transcendence/venv/lib/python3.11/site-packages/django/core/handlers/exception.py", line 55, in inner
    response = get_response(request)
               ^^^^^^^^^^^^^^^^^^^^^
  File "/home/ft_transcendence/venv/lib/python3.11/site-packages/django/core/handlers/base.py", line 197, in _get_response
    response = wrapped_callback(request, *callback_args, **callback_kwargs)
               ^^^^^^^^^^^^^^^^^^^^^^^^^^^^^^^^^^^^^^^^^^^^^^^^^^^^^^^^^^^^
  File "/home/ft_transcendence/venv/lib/python3.11/site-packages/django/views/decorators/csrf.py", line 56, in wrapper_view
    return view_func(*args, **kwargs)
           ^^^^^^^^^^^^^^^^^^^^^^^^^^
  File "/home/ft_transcendence/venv/lib/python3.11/site-packages/django/views/generic/base.py", line 104, in view
    return self.dispatch(request, *args, **kwargs)
           ^^^^^^^^^^^^^^^^^^^^^^^^^^^^^^^^^^^^^^^
  File "/home/ft_transcendence/venv/lib/python3.11/site-packages/rest_framework/views.py", line 509, in dispatch
    response = self.handle_exception(exc)
               ^^^^^^^^^^^^^^^^^^^^^^^^^^
  File "/home/ft_transcendence/venv/lib/python3.11/site-packages/rest_framework/views.py", line 469, in handle_exception
    self.raise_uncaught_exception(exc)
  File "/home/ft_transcendence/venv/lib/python3.11/site-packages/rest_framework/views.py", line 480, in raise_uncaught_exception
    raise exc
  File "/home/ft_transcendence/venv/lib/python3.11/site-packages/rest_framework/views.py", line 506, in dispatch
    response = handler(request, *args, **kwargs)
               ^^^^^^^^^^^^^^^^^^^^^^^^^^^^^^^^^
  File "/home/ft_transcendence/src/api/views/account.py", line 46, in post
    serializer.is_valid(raise_exception=True)
  File "/home/ft_transcendence/venv/lib/python3.11/site-packages/rest_framework/serializers.py", line 227, in is_valid
    self._validated_data = self.run_validation(self.initial_data)
                           ^^^^^^^^^^^^^^^^^^^^^^^^^^^^^^^^^^^^^^
  File "/home/ft_transcendence/venv/lib/python3.11/site-packages/rest_framework/serializers.py", line 429, in run_validation
    value = self.validate(value)
            ^^^^^^^^^^^^^^^^^^^^
  File "/home/ft_transcendence/src/api/serializers/account.py", line 90, in validate
    or not user.is_valid_otp()
           ^^^^^^^^^^^^^^^^^
AttributeError: 'Account' object has no attribute 'is_valid_otp'
Internal Server Error: /auth/otp
Traceback (most recent call last):
  File "/home/ft_transcendence/venv/lib/python3.11/site-packages/django/core/handlers/exception.py", line 55, in inner
    response = get_response(request)
               ^^^^^^^^^^^^^^^^^^^^^
  File "/home/ft_transcendence/venv/lib/python3.11/site-packages/django/core/handlers/base.py", line 197, in _get_response
    response = wrapped_callback(request, *callback_args, **callback_kwargs)
               ^^^^^^^^^^^^^^^^^^^^^^^^^^^^^^^^^^^^^^^^^^^^^^^^^^^^^^^^^^^^
  File "/home/ft_transcendence/venv/lib/python3.11/site-packages/django/views/decorators/csrf.py", line 56, in wrapper_view
    return view_func(*args, **kwargs)
           ^^^^^^^^^^^^^^^^^^^^^^^^^^
  File "/home/ft_transcendence/venv/lib/python3.11/site-packages/django/views/generic/base.py", line 104, in view
    return self.dispatch(request, *args, **kwargs)
           ^^^^^^^^^^^^^^^^^^^^^^^^^^^^^^^^^^^^^^^
  File "/home/ft_transcendence/venv/lib/python3.11/site-packages/rest_framework/views.py", line 509, in dispatch
    response = self.handle_exception(exc)
               ^^^^^^^^^^^^^^^^^^^^^^^^^^
  File "/home/ft_transcendence/venv/lib/python3.11/site-packages/rest_framework/views.py", line 469, in handle_exception
    self.raise_uncaught_exception(exc)
  File "/home/ft_transcendence/venv/lib/python3.11/site-packages/rest_framework/views.py", line 480, in raise_uncaught_exception
    raise exc
  File "/home/ft_transcendence/venv/lib/python3.11/site-packages/rest_framework/views.py", line 506, in dispatch
    response = handler(request, *args, **kwargs)
               ^^^^^^^^^^^^^^^^^^^^^^^^^^^^^^^^^
  File "/home/ft_transcendence/src/api/views/account.py", line 46, in post
    serializer.is_valid(raise_exception=True)
  File "/home/ft_transcendence/venv/lib/python3.11/site-packages/rest_framework/serializers.py", line 227, in is_valid
    self._validated_data = self.run_validation(self.initial_data)
                           ^^^^^^^^^^^^^^^^^^^^^^^^^^^^^^^^^^^^^^
  File "/home/ft_transcendence/venv/lib/python3.11/site-packages/rest_framework/serializers.py", line 429, in run_validation
    value = self.validate(value)
            ^^^^^^^^^^^^^^^^^^^^
  File "/home/ft_transcendence/src/api/serializers/account.py", line 90, in validate
    or not user.is_valid_otp()
           ^^^^^^^^^^^^^^^^^
AttributeError: 'Account' object has no attribute 'is_valid_otp'
Bad Request: /auth/login
Internal Server Error: /auth/otp
Traceback (most recent call last):
  File "/home/ft_transcendence/venv/lib/python3.11/site-packages/django/core/handlers/exception.py", line 55, in inner
    response = get_response(request)
               ^^^^^^^^^^^^^^^^^^^^^
  File "/home/ft_transcendence/venv/lib/python3.11/site-packages/django/core/handlers/base.py", line 197, in _get_response
    response = wrapped_callback(request, *callback_args, **callback_kwargs)
               ^^^^^^^^^^^^^^^^^^^^^^^^^^^^^^^^^^^^^^^^^^^^^^^^^^^^^^^^^^^^
  File "/home/ft_transcendence/venv/lib/python3.11/site-packages/django/views/decorators/csrf.py", line 56, in wrapper_view
    return view_func(*args, **kwargs)
           ^^^^^^^^^^^^^^^^^^^^^^^^^^
  File "/home/ft_transcendence/venv/lib/python3.11/site-packages/django/views/generic/base.py", line 104, in view
    return self.dispatch(request, *args, **kwargs)
           ^^^^^^^^^^^^^^^^^^^^^^^^^^^^^^^^^^^^^^^
  File "/home/ft_transcendence/venv/lib/python3.11/site-packages/rest_framework/views.py", line 509, in dispatch
    response = self.handle_exception(exc)
               ^^^^^^^^^^^^^^^^^^^^^^^^^^
  File "/home/ft_transcendence/venv/lib/python3.11/site-packages/rest_framework/views.py", line 469, in handle_exception
    self.raise_uncaught_exception(exc)
  File "/home/ft_transcendence/venv/lib/python3.11/site-packages/rest_framework/views.py", line 480, in raise_uncaught_exception
    raise exc
  File "/home/ft_transcendence/venv/lib/python3.11/site-packages/rest_framework/views.py", line 506, in dispatch
    response = handler(request, *args, **kwargs)
               ^^^^^^^^^^^^^^^^^^^^^^^^^^^^^^^^^
  File "/home/ft_transcendence/src/api/views/account.py", line 46, in post
    serializer.is_valid(raise_exception=True)
  File "/home/ft_transcendence/venv/lib/python3.11/site-packages/rest_framework/serializers.py", line 227, in is_valid
    self._validated_data = self.run_validation(self.initial_data)
                           ^^^^^^^^^^^^^^^^^^^^^^^^^^^^^^^^^^^^^^
  File "/home/ft_transcendence/venv/lib/python3.11/site-packages/rest_framework/serializers.py", line 429, in run_validation
    value = self.validate(value)
            ^^^^^^^^^^^^^^^^^^^^
  File "/home/ft_transcendence/src/api/serializers/account.py", line 90, in validate
    or not user.is_valid_otp()
           ^^^^^^^^^^^^^^^^^
AttributeError: 'Account' object has no attribute 'is_valid_otp'
Internal Server Error: /auth/otp
Traceback (most recent call last):
  File "/home/ft_transcendence/venv/lib/python3.11/site-packages/django/core/handlers/exception.py", line 55, in inner
    response = get_response(request)
               ^^^^^^^^^^^^^^^^^^^^^
  File "/home/ft_transcendence/venv/lib/python3.11/site-packages/django/core/handlers/base.py", line 197, in _get_response
    response = wrapped_callback(request, *callback_args, **callback_kwargs)
               ^^^^^^^^^^^^^^^^^^^^^^^^^^^^^^^^^^^^^^^^^^^^^^^^^^^^^^^^^^^^
  File "/home/ft_transcendence/venv/lib/python3.11/site-packages/django/views/decorators/csrf.py", line 56, in wrapper_view
    return view_func(*args, **kwargs)
           ^^^^^^^^^^^^^^^^^^^^^^^^^^
  File "/home/ft_transcendence/venv/lib/python3.11/site-packages/django/views/generic/base.py", line 104, in view
    return self.dispatch(request, *args, **kwargs)
           ^^^^^^^^^^^^^^^^^^^^^^^^^^^^^^^^^^^^^^^
  File "/home/ft_transcendence/venv/lib/python3.11/site-packages/rest_framework/views.py", line 509, in dispatch
    response = self.handle_exception(exc)
               ^^^^^^^^^^^^^^^^^^^^^^^^^^
  File "/home/ft_transcendence/venv/lib/python3.11/site-packages/rest_framework/views.py", line 469, in handle_exception
    self.raise_uncaught_exception(exc)
  File "/home/ft_transcendence/venv/lib/python3.11/site-packages/rest_framework/views.py", line 480, in raise_uncaught_exception
    raise exc
  File "/home/ft_transcendence/venv/lib/python3.11/site-packages/rest_framework/views.py", line 506, in dispatch
    response = handler(request, *args, **kwargs)
               ^^^^^^^^^^^^^^^^^^^^^^^^^^^^^^^^^
  File "/home/ft_transcendence/src/api/views/account.py", line 46, in post
    serializer.is_valid(raise_exception=True)
  File "/home/ft_transcendence/venv/lib/python3.11/site-packages/rest_framework/serializers.py", line 227, in is_valid
    self._validated_data = self.run_validation(self.initial_data)
                           ^^^^^^^^^^^^^^^^^^^^^^^^^^^^^^^^^^^^^^
  File "/home/ft_transcendence/venv/lib/python3.11/site-packages/rest_framework/serializers.py", line 429, in run_validation
    value = self.validate(value)
            ^^^^^^^^^^^^^^^^^^^^
  File "/home/ft_transcendence/src/api/serializers/account.py", line 90, in validate
    or not user.is_valid_otp()
           ^^^^^^^^^^^^^^^^^
AttributeError: 'Account' object has no attribute 'is_valid_otp'
Internal Server Error: /auth/otp
Traceback (most recent call last):
  File "/home/ft_transcendence/venv/lib/python3.11/site-packages/django/core/handlers/exception.py", line 55, in inner
    response = get_response(request)
               ^^^^^^^^^^^^^^^^^^^^^
  File "/home/ft_transcendence/venv/lib/python3.11/site-packages/django/core/handlers/base.py", line 197, in _get_response
    response = wrapped_callback(request, *callback_args, **callback_kwargs)
               ^^^^^^^^^^^^^^^^^^^^^^^^^^^^^^^^^^^^^^^^^^^^^^^^^^^^^^^^^^^^
  File "/home/ft_transcendence/venv/lib/python3.11/site-packages/django/views/decorators/csrf.py", line 56, in wrapper_view
    return view_func(*args, **kwargs)
           ^^^^^^^^^^^^^^^^^^^^^^^^^^
  File "/home/ft_transcendence/venv/lib/python3.11/site-packages/django/views/generic/base.py", line 104, in view
    return self.dispatch(request, *args, **kwargs)
           ^^^^^^^^^^^^^^^^^^^^^^^^^^^^^^^^^^^^^^^
  File "/home/ft_transcendence/venv/lib/python3.11/site-packages/rest_framework/views.py", line 509, in dispatch
    response = self.handle_exception(exc)
               ^^^^^^^^^^^^^^^^^^^^^^^^^^
  File "/home/ft_transcendence/venv/lib/python3.11/site-packages/rest_framework/views.py", line 469, in handle_exception
    self.raise_uncaught_exception(exc)
  File "/home/ft_transcendence/venv/lib/python3.11/site-packages/rest_framework/views.py", line 480, in raise_uncaught_exception
    raise exc
  File "/home/ft_transcendence/venv/lib/python3.11/site-packages/rest_framework/views.py", line 506, in dispatch
    response = handler(request, *args, **kwargs)
               ^^^^^^^^^^^^^^^^^^^^^^^^^^^^^^^^^
  File "/home/ft_transcendence/src/api/views/account.py", line 46, in post
    serializer.is_valid(raise_exception=True)
  File "/home/ft_transcendence/venv/lib/python3.11/site-packages/rest_framework/serializers.py", line 227, in is_valid
    self._validated_data = self.run_validation(self.initial_data)
                           ^^^^^^^^^^^^^^^^^^^^^^^^^^^^^^^^^^^^^^
  File "/home/ft_transcendence/venv/lib/python3.11/site-packages/rest_framework/serializers.py", line 429, in run_validation
    value = self.validate(value)
            ^^^^^^^^^^^^^^^^^^^^
  File "/home/ft_transcendence/src/api/serializers/account.py", line 90, in validate
    or not user.is_valid_otp()
           ^^^^^^^^^^^^^^^^^
AttributeError: 'Account' object has no attribute 'is_valid_otp'
Internal Server Error: /auth/otp
Traceback (most recent call last):
  File "/home/ft_transcendence/venv/lib/python3.11/site-packages/django/core/handlers/exception.py", line 55, in inner
    response = get_response(request)
               ^^^^^^^^^^^^^^^^^^^^^
  File "/home/ft_transcendence/venv/lib/python3.11/site-packages/django/core/handlers/base.py", line 197, in _get_response
    response = wrapped_callback(request, *callback_args, **callback_kwargs)
               ^^^^^^^^^^^^^^^^^^^^^^^^^^^^^^^^^^^^^^^^^^^^^^^^^^^^^^^^^^^^
  File "/home/ft_transcendence/venv/lib/python3.11/site-packages/django/views/decorators/csrf.py", line 56, in wrapper_view
    return view_func(*args, **kwargs)
           ^^^^^^^^^^^^^^^^^^^^^^^^^^
  File "/home/ft_transcendence/venv/lib/python3.11/site-packages/django/views/generic/base.py", line 104, in view
    return self.dispatch(request, *args, **kwargs)
           ^^^^^^^^^^^^^^^^^^^^^^^^^^^^^^^^^^^^^^^
  File "/home/ft_transcendence/venv/lib/python3.11/site-packages/rest_framework/views.py", line 509, in dispatch
    response = self.handle_exception(exc)
               ^^^^^^^^^^^^^^^^^^^^^^^^^^
  File "/home/ft_transcendence/venv/lib/python3.11/site-packages/rest_framework/views.py", line 469, in handle_exception
    self.raise_uncaught_exception(exc)
  File "/home/ft_transcendence/venv/lib/python3.11/site-packages/rest_framework/views.py", line 480, in raise_uncaught_exception
    raise exc
  File "/home/ft_transcendence/venv/lib/python3.11/site-packages/rest_framework/views.py", line 506, in dispatch
    response = handler(request, *args, **kwargs)
               ^^^^^^^^^^^^^^^^^^^^^^^^^^^^^^^^^
  File "/home/ft_transcendence/src/api/views/account.py", line 46, in post
    serializer.is_valid(raise_exception=True)
  File "/home/ft_transcendence/venv/lib/python3.11/site-packages/rest_framework/serializers.py", line 227, in is_valid
    self._validated_data = self.run_validation(self.initial_data)
                           ^^^^^^^^^^^^^^^^^^^^^^^^^^^^^^^^^^^^^^
  File "/home/ft_transcendence/venv/lib/python3.11/site-packages/rest_framework/serializers.py", line 429, in run_validation
    value = self.validate(value)
            ^^^^^^^^^^^^^^^^^^^^
  File "/home/ft_transcendence/src/api/serializers/account.py", line 90, in validate
    or not user.is_valid_otp()
           ^^^^^^^^^^^^^^^^^
AttributeError: 'Account' object has no attribute 'is_valid_otp'
Internal Server Error: /auth/otp
Traceback (most recent call last):
  File "/home/ft_transcendence/venv/lib/python3.11/site-packages/django/core/handlers/exception.py", line 55, in inner
    response = get_response(request)
               ^^^^^^^^^^^^^^^^^^^^^
  File "/home/ft_transcendence/venv/lib/python3.11/site-packages/django/core/handlers/base.py", line 197, in _get_response
    response = wrapped_callback(request, *callback_args, **callback_kwargs)
               ^^^^^^^^^^^^^^^^^^^^^^^^^^^^^^^^^^^^^^^^^^^^^^^^^^^^^^^^^^^^
  File "/home/ft_transcendence/venv/lib/python3.11/site-packages/django/views/decorators/csrf.py", line 56, in wrapper_view
    return view_func(*args, **kwargs)
           ^^^^^^^^^^^^^^^^^^^^^^^^^^
  File "/home/ft_transcendence/venv/lib/python3.11/site-packages/django/views/generic/base.py", line 104, in view
    return self.dispatch(request, *args, **kwargs)
           ^^^^^^^^^^^^^^^^^^^^^^^^^^^^^^^^^^^^^^^
  File "/home/ft_transcendence/venv/lib/python3.11/site-packages/rest_framework/views.py", line 509, in dispatch
    response = self.handle_exception(exc)
               ^^^^^^^^^^^^^^^^^^^^^^^^^^
  File "/home/ft_transcendence/venv/lib/python3.11/site-packages/rest_framework/views.py", line 469, in handle_exception
    self.raise_uncaught_exception(exc)
  File "/home/ft_transcendence/venv/lib/python3.11/site-packages/rest_framework/views.py", line 480, in raise_uncaught_exception
    raise exc
  File "/home/ft_transcendence/venv/lib/python3.11/site-packages/rest_framework/views.py", line 506, in dispatch
    response = handler(request, *args, **kwargs)
               ^^^^^^^^^^^^^^^^^^^^^^^^^^^^^^^^^
  File "/home/ft_transcendence/src/api/views/account.py", line 46, in post
    serializer.is_valid(raise_exception=True)
  File "/home/ft_transcendence/venv/lib/python3.11/site-packages/rest_framework/serializers.py", line 227, in is_valid
    self._validated_data = self.run_validation(self.initial_data)
                           ^^^^^^^^^^^^^^^^^^^^^^^^^^^^^^^^^^^^^^
  File "/home/ft_transcendence/venv/lib/python3.11/site-packages/rest_framework/serializers.py", line 429, in run_validation
    value = self.validate(value)
            ^^^^^^^^^^^^^^^^^^^^
  File "/home/ft_transcendence/src/api/serializers/account.py", line 90, in validate
    or not user.is_valid_otp()
           ^^^^^^^^^^^^^^^^^
AttributeError: 'Account' object has no attribute 'is_valid_otp'
Internal Server Error: /auth/otp
Traceback (most recent call last):
  File "/home/ft_transcendence/venv/lib/python3.11/site-packages/django/core/handlers/exception.py", line 55, in inner
    response = get_response(request)
               ^^^^^^^^^^^^^^^^^^^^^
  File "/home/ft_transcendence/venv/lib/python3.11/site-packages/django/core/handlers/base.py", line 197, in _get_response
    response = wrapped_callback(request, *callback_args, **callback_kwargs)
               ^^^^^^^^^^^^^^^^^^^^^^^^^^^^^^^^^^^^^^^^^^^^^^^^^^^^^^^^^^^^
  File "/home/ft_transcendence/venv/lib/python3.11/site-packages/django/views/decorators/csrf.py", line 56, in wrapper_view
    return view_func(*args, **kwargs)
           ^^^^^^^^^^^^^^^^^^^^^^^^^^
  File "/home/ft_transcendence/venv/lib/python3.11/site-packages/django/views/generic/base.py", line 104, in view
    return self.dispatch(request, *args, **kwargs)
           ^^^^^^^^^^^^^^^^^^^^^^^^^^^^^^^^^^^^^^^
  File "/home/ft_transcendence/venv/lib/python3.11/site-packages/rest_framework/views.py", line 509, in dispatch
    response = self.handle_exception(exc)
               ^^^^^^^^^^^^^^^^^^^^^^^^^^
  File "/home/ft_transcendence/venv/lib/python3.11/site-packages/rest_framework/views.py", line 469, in handle_exception
    self.raise_uncaught_exception(exc)
  File "/home/ft_transcendence/venv/lib/python3.11/site-packages/rest_framework/views.py", line 480, in raise_uncaught_exception
    raise exc
  File "/home/ft_transcendence/venv/lib/python3.11/site-packages/rest_framework/views.py", line 506, in dispatch
    response = handler(request, *args, **kwargs)
               ^^^^^^^^^^^^^^^^^^^^^^^^^^^^^^^^^
  File "/home/ft_transcendence/src/api/views/account.py", line 46, in post
    serializer.is_valid(raise_exception=True)
  File "/home/ft_transcendence/venv/lib/python3.11/site-packages/rest_framework/serializers.py", line 227, in is_valid
    self._validated_data = self.run_validation(self.initial_data)
                           ^^^^^^^^^^^^^^^^^^^^^^^^^^^^^^^^^^^^^^
  File "/home/ft_transcendence/venv/lib/python3.11/site-packages/rest_framework/serializers.py", line 429, in run_validation
    value = self.validate(value)
            ^^^^^^^^^^^^^^^^^^^^
  File "/home/ft_transcendence/src/api/serializers/account.py", line 90, in validate
    or not user.is_valid_otp()
           ^^^^^^^^^^^^^^^^^
AttributeError: 'Account' object has no attribute 'is_valid_otp'
Internal Server Error: /auth/otp
Traceback (most recent call last):
  File "/home/ft_transcendence/venv/lib/python3.11/site-packages/django/core/handlers/exception.py", line 55, in inner
    response = get_response(request)
               ^^^^^^^^^^^^^^^^^^^^^
  File "/home/ft_transcendence/venv/lib/python3.11/site-packages/django/core/handlers/base.py", line 197, in _get_response
    response = wrapped_callback(request, *callback_args, **callback_kwargs)
               ^^^^^^^^^^^^^^^^^^^^^^^^^^^^^^^^^^^^^^^^^^^^^^^^^^^^^^^^^^^^
  File "/home/ft_transcendence/venv/lib/python3.11/site-packages/django/views/decorators/csrf.py", line 56, in wrapper_view
    return view_func(*args, **kwargs)
           ^^^^^^^^^^^^^^^^^^^^^^^^^^
  File "/home/ft_transcendence/venv/lib/python3.11/site-packages/django/views/generic/base.py", line 104, in view
    return self.dispatch(request, *args, **kwargs)
           ^^^^^^^^^^^^^^^^^^^^^^^^^^^^^^^^^^^^^^^
  File "/home/ft_transcendence/venv/lib/python3.11/site-packages/rest_framework/views.py", line 509, in dispatch
    response = self.handle_exception(exc)
               ^^^^^^^^^^^^^^^^^^^^^^^^^^
  File "/home/ft_transcendence/venv/lib/python3.11/site-packages/rest_framework/views.py", line 469, in handle_exception
    self.raise_uncaught_exception(exc)
  File "/home/ft_transcendence/venv/lib/python3.11/site-packages/rest_framework/views.py", line 480, in raise_uncaught_exception
    raise exc
  File "/home/ft_transcendence/venv/lib/python3.11/site-packages/rest_framework/views.py", line 506, in dispatch
    response = handler(request, *args, **kwargs)
               ^^^^^^^^^^^^^^^^^^^^^^^^^^^^^^^^^
  File "/home/ft_transcendence/src/api/views/account.py", line 46, in post
    serializer.is_valid(raise_exception=True)
  File "/home/ft_transcendence/venv/lib/python3.11/site-packages/rest_framework/serializers.py", line 227, in is_valid
    self._validated_data = self.run_validation(self.initial_data)
                           ^^^^^^^^^^^^^^^^^^^^^^^^^^^^^^^^^^^^^^
  File "/home/ft_transcendence/venv/lib/python3.11/site-packages/rest_framework/serializers.py", line 429, in run_validation
    value = self.validate(value)
            ^^^^^^^^^^^^^^^^^^^^
  File "/home/ft_transcendence/src/api/serializers/account.py", line 90, in validate
    or not user.is_valid_otp()
           ^^^^^^^^^^^^^^^^^
AttributeError: 'Account' object has no attribute 'is_valid_otp'
Internal Server Error: /auth/otp
Traceback (most recent call last):
  File "/home/ft_transcendence/venv/lib/python3.11/site-packages/django/core/handlers/exception.py", line 55, in inner
    response = get_response(request)
               ^^^^^^^^^^^^^^^^^^^^^
  File "/home/ft_transcendence/venv/lib/python3.11/site-packages/django/core/handlers/base.py", line 197, in _get_response
    response = wrapped_callback(request, *callback_args, **callback_kwargs)
               ^^^^^^^^^^^^^^^^^^^^^^^^^^^^^^^^^^^^^^^^^^^^^^^^^^^^^^^^^^^^
  File "/home/ft_transcendence/venv/lib/python3.11/site-packages/django/views/decorators/csrf.py", line 56, in wrapper_view
    return view_func(*args, **kwargs)
           ^^^^^^^^^^^^^^^^^^^^^^^^^^
  File "/home/ft_transcendence/venv/lib/python3.11/site-packages/django/views/generic/base.py", line 104, in view
    return self.dispatch(request, *args, **kwargs)
           ^^^^^^^^^^^^^^^^^^^^^^^^^^^^^^^^^^^^^^^
  File "/home/ft_transcendence/venv/lib/python3.11/site-packages/rest_framework/views.py", line 509, in dispatch
    response = self.handle_exception(exc)
               ^^^^^^^^^^^^^^^^^^^^^^^^^^
  File "/home/ft_transcendence/venv/lib/python3.11/site-packages/rest_framework/views.py", line 469, in handle_exception
    self.raise_uncaught_exception(exc)
  File "/home/ft_transcendence/venv/lib/python3.11/site-packages/rest_framework/views.py", line 480, in raise_uncaught_exception
    raise exc
  File "/home/ft_transcendence/venv/lib/python3.11/site-packages/rest_framework/views.py", line 506, in dispatch
    response = handler(request, *args, **kwargs)
               ^^^^^^^^^^^^^^^^^^^^^^^^^^^^^^^^^
  File "/home/ft_transcendence/src/api/views/account.py", line 46, in post
    serializer.is_valid(raise_exception=True)
  File "/home/ft_transcendence/venv/lib/python3.11/site-packages/rest_framework/serializers.py", line 227, in is_valid
    self._validated_data = self.run_validation(self.initial_data)
                           ^^^^^^^^^^^^^^^^^^^^^^^^^^^^^^^^^^^^^^
  File "/home/ft_transcendence/venv/lib/python3.11/site-packages/rest_framework/serializers.py", line 429, in run_validation
    value = self.validate(value)
            ^^^^^^^^^^^^^^^^^^^^
  File "/home/ft_transcendence/src/api/serializers/account.py", line 90, in validate
    or not user.is_valid_otp()
           ^^^^^^^^^^^^^^^^^
AttributeError: 'Account' object has no attribute 'is_valid_otp'
Internal Server Error: /auth/otp
Traceback (most recent call last):
  File "/home/ft_transcendence/venv/lib/python3.11/site-packages/django/core/handlers/exception.py", line 55, in inner
    response = get_response(request)
               ^^^^^^^^^^^^^^^^^^^^^
  File "/home/ft_transcendence/venv/lib/python3.11/site-packages/django/core/handlers/base.py", line 197, in _get_response
    response = wrapped_callback(request, *callback_args, **callback_kwargs)
               ^^^^^^^^^^^^^^^^^^^^^^^^^^^^^^^^^^^^^^^^^^^^^^^^^^^^^^^^^^^^
  File "/home/ft_transcendence/venv/lib/python3.11/site-packages/django/views/decorators/csrf.py", line 56, in wrapper_view
    return view_func(*args, **kwargs)
           ^^^^^^^^^^^^^^^^^^^^^^^^^^
  File "/home/ft_transcendence/venv/lib/python3.11/site-packages/django/views/generic/base.py", line 104, in view
    return self.dispatch(request, *args, **kwargs)
           ^^^^^^^^^^^^^^^^^^^^^^^^^^^^^^^^^^^^^^^
  File "/home/ft_transcendence/venv/lib/python3.11/site-packages/rest_framework/views.py", line 509, in dispatch
    response = self.handle_exception(exc)
               ^^^^^^^^^^^^^^^^^^^^^^^^^^
  File "/home/ft_transcendence/venv/lib/python3.11/site-packages/rest_framework/views.py", line 469, in handle_exception
    self.raise_uncaught_exception(exc)
  File "/home/ft_transcendence/venv/lib/python3.11/site-packages/rest_framework/views.py", line 480, in raise_uncaught_exception
    raise exc
  File "/home/ft_transcendence/venv/lib/python3.11/site-packages/rest_framework/views.py", line 506, in dispatch
    response = handler(request, *args, **kwargs)
               ^^^^^^^^^^^^^^^^^^^^^^^^^^^^^^^^^
  File "/home/ft_transcendence/src/api/views/account.py", line 46, in post
    serializer.is_valid(raise_exception=True)
  File "/home/ft_transcendence/venv/lib/python3.11/site-packages/rest_framework/serializers.py", line 227, in is_valid
    self._validated_data = self.run_validation(self.initial_data)
                           ^^^^^^^^^^^^^^^^^^^^^^^^^^^^^^^^^^^^^^
  File "/home/ft_transcendence/venv/lib/python3.11/site-packages/rest_framework/serializers.py", line 429, in run_validation
    value = self.validate(value)
            ^^^^^^^^^^^^^^^^^^^^
  File "/home/ft_transcendence/src/api/serializers/account.py", line 90, in validate
    or not user.is_valid_otp()
           ^^^^^^^^^^^^^^^^^
AttributeError: 'Account' object has no attribute 'is_valid_otp'
Internal Server Error: /auth/otp
Traceback (most recent call last):
  File "/home/ft_transcendence/venv/lib/python3.11/site-packages/django/core/handlers/exception.py", line 55, in inner
    response = get_response(request)
               ^^^^^^^^^^^^^^^^^^^^^
  File "/home/ft_transcendence/venv/lib/python3.11/site-packages/django/core/handlers/base.py", line 197, in _get_response
    response = wrapped_callback(request, *callback_args, **callback_kwargs)
               ^^^^^^^^^^^^^^^^^^^^^^^^^^^^^^^^^^^^^^^^^^^^^^^^^^^^^^^^^^^^
  File "/home/ft_transcendence/venv/lib/python3.11/site-packages/django/views/decorators/csrf.py", line 56, in wrapper_view
    return view_func(*args, **kwargs)
           ^^^^^^^^^^^^^^^^^^^^^^^^^^
  File "/home/ft_transcendence/venv/lib/python3.11/site-packages/django/views/generic/base.py", line 104, in view
    return self.dispatch(request, *args, **kwargs)
           ^^^^^^^^^^^^^^^^^^^^^^^^^^^^^^^^^^^^^^^
  File "/home/ft_transcendence/venv/lib/python3.11/site-packages/rest_framework/views.py", line 509, in dispatch
    response = self.handle_exception(exc)
               ^^^^^^^^^^^^^^^^^^^^^^^^^^
  File "/home/ft_transcendence/venv/lib/python3.11/site-packages/rest_framework/views.py", line 469, in handle_exception
    self.raise_uncaught_exception(exc)
  File "/home/ft_transcendence/venv/lib/python3.11/site-packages/rest_framework/views.py", line 480, in raise_uncaught_exception
    raise exc
  File "/home/ft_transcendence/venv/lib/python3.11/site-packages/rest_framework/views.py", line 506, in dispatch
    response = handler(request, *args, **kwargs)
               ^^^^^^^^^^^^^^^^^^^^^^^^^^^^^^^^^
  File "/home/ft_transcendence/src/api/views/account.py", line 46, in post
    serializer.is_valid(raise_exception=True)
  File "/home/ft_transcendence/venv/lib/python3.11/site-packages/rest_framework/serializers.py", line 227, in is_valid
    self._validated_data = self.run_validation(self.initial_data)
                           ^^^^^^^^^^^^^^^^^^^^^^^^^^^^^^^^^^^^^^
  File "/home/ft_transcendence/venv/lib/python3.11/site-packages/rest_framework/serializers.py", line 429, in run_validation
    value = self.validate(value)
            ^^^^^^^^^^^^^^^^^^^^
  File "/home/ft_transcendence/src/api/serializers/account.py", line 90, in validate
    or not user.is_valid_otp()
           ^^^^^^^^^^^^^^^^^
AttributeError: 'Account' object has no attribute 'is_valid_otp'
Internal Server Error: /auth/otp
Traceback (most recent call last):
  File "/home/ft_transcendence/venv/lib/python3.11/site-packages/django/core/handlers/exception.py", line 55, in inner
    response = get_response(request)
               ^^^^^^^^^^^^^^^^^^^^^
  File "/home/ft_transcendence/venv/lib/python3.11/site-packages/django/core/handlers/base.py", line 197, in _get_response
    response = wrapped_callback(request, *callback_args, **callback_kwargs)
               ^^^^^^^^^^^^^^^^^^^^^^^^^^^^^^^^^^^^^^^^^^^^^^^^^^^^^^^^^^^^
  File "/home/ft_transcendence/venv/lib/python3.11/site-packages/django/views/decorators/csrf.py", line 56, in wrapper_view
    return view_func(*args, **kwargs)
           ^^^^^^^^^^^^^^^^^^^^^^^^^^
  File "/home/ft_transcendence/venv/lib/python3.11/site-packages/django/views/generic/base.py", line 104, in view
    return self.dispatch(request, *args, **kwargs)
           ^^^^^^^^^^^^^^^^^^^^^^^^^^^^^^^^^^^^^^^
  File "/home/ft_transcendence/venv/lib/python3.11/site-packages/rest_framework/views.py", line 509, in dispatch
    response = self.handle_exception(exc)
               ^^^^^^^^^^^^^^^^^^^^^^^^^^
  File "/home/ft_transcendence/venv/lib/python3.11/site-packages/rest_framework/views.py", line 469, in handle_exception
    self.raise_uncaught_exception(exc)
  File "/home/ft_transcendence/venv/lib/python3.11/site-packages/rest_framework/views.py", line 480, in raise_uncaught_exception
    raise exc
  File "/home/ft_transcendence/venv/lib/python3.11/site-packages/rest_framework/views.py", line 506, in dispatch
    response = handler(request, *args, **kwargs)
               ^^^^^^^^^^^^^^^^^^^^^^^^^^^^^^^^^
  File "/home/ft_transcendence/src/api/views/account.py", line 46, in post
    serializer.is_valid(raise_exception=True)
  File "/home/ft_transcendence/venv/lib/python3.11/site-packages/rest_framework/serializers.py", line 227, in is_valid
    self._validated_data = self.run_validation(self.initial_data)
                           ^^^^^^^^^^^^^^^^^^^^^^^^^^^^^^^^^^^^^^
  File "/home/ft_transcendence/venv/lib/python3.11/site-packages/rest_framework/serializers.py", line 429, in run_validation
    value = self.validate(value)
            ^^^^^^^^^^^^^^^^^^^^
  File "/home/ft_transcendence/src/api/serializers/account.py", line 90, in validate
    or not user.is_valid_otp()
           ^^^^^^^^^^^^^^^^^
AttributeError: 'Account' object has no attribute 'is_valid_otp'
Internal Server Error: /auth/otp
Traceback (most recent call last):
  File "/home/ft_transcendence/venv/lib/python3.11/site-packages/django/core/handlers/exception.py", line 55, in inner
    response = get_response(request)
               ^^^^^^^^^^^^^^^^^^^^^
  File "/home/ft_transcendence/venv/lib/python3.11/site-packages/django/core/handlers/base.py", line 197, in _get_response
    response = wrapped_callback(request, *callback_args, **callback_kwargs)
               ^^^^^^^^^^^^^^^^^^^^^^^^^^^^^^^^^^^^^^^^^^^^^^^^^^^^^^^^^^^^
  File "/home/ft_transcendence/venv/lib/python3.11/site-packages/django/views/decorators/csrf.py", line 56, in wrapper_view
    return view_func(*args, **kwargs)
           ^^^^^^^^^^^^^^^^^^^^^^^^^^
  File "/home/ft_transcendence/venv/lib/python3.11/site-packages/django/views/generic/base.py", line 104, in view
    return self.dispatch(request, *args, **kwargs)
           ^^^^^^^^^^^^^^^^^^^^^^^^^^^^^^^^^^^^^^^
  File "/home/ft_transcendence/venv/lib/python3.11/site-packages/rest_framework/views.py", line 509, in dispatch
    response = self.handle_exception(exc)
               ^^^^^^^^^^^^^^^^^^^^^^^^^^
  File "/home/ft_transcendence/venv/lib/python3.11/site-packages/rest_framework/views.py", line 469, in handle_exception
    self.raise_uncaught_exception(exc)
  File "/home/ft_transcendence/venv/lib/python3.11/site-packages/rest_framework/views.py", line 480, in raise_uncaught_exception
    raise exc
  File "/home/ft_transcendence/venv/lib/python3.11/site-packages/rest_framework/views.py", line 506, in dispatch
    response = handler(request, *args, **kwargs)
               ^^^^^^^^^^^^^^^^^^^^^^^^^^^^^^^^^
  File "/home/ft_transcendence/src/api/views/account.py", line 46, in post
    serializer.is_valid(raise_exception=True)
  File "/home/ft_transcendence/venv/lib/python3.11/site-packages/rest_framework/serializers.py", line 227, in is_valid
    self._validated_data = self.run_validation(self.initial_data)
                           ^^^^^^^^^^^^^^^^^^^^^^^^^^^^^^^^^^^^^^
  File "/home/ft_transcendence/venv/lib/python3.11/site-packages/rest_framework/serializers.py", line 429, in run_validation
    value = self.validate(value)
            ^^^^^^^^^^^^^^^^^^^^
  File "/home/ft_transcendence/src/api/serializers/account.py", line 90, in validate
    or not user.is_valid_otp()
           ^^^^^^^^^^^^^^^^^
AttributeError: 'Account' object has no attribute 'is_valid_otp'
Internal Server Error: /auth/otp
Traceback (most recent call last):
  File "/home/ft_transcendence/venv/lib/python3.11/site-packages/django/core/handlers/exception.py", line 55, in inner
    response = get_response(request)
               ^^^^^^^^^^^^^^^^^^^^^
  File "/home/ft_transcendence/venv/lib/python3.11/site-packages/django/core/handlers/base.py", line 197, in _get_response
    response = wrapped_callback(request, *callback_args, **callback_kwargs)
               ^^^^^^^^^^^^^^^^^^^^^^^^^^^^^^^^^^^^^^^^^^^^^^^^^^^^^^^^^^^^
  File "/home/ft_transcendence/venv/lib/python3.11/site-packages/django/views/decorators/csrf.py", line 56, in wrapper_view
    return view_func(*args, **kwargs)
           ^^^^^^^^^^^^^^^^^^^^^^^^^^
  File "/home/ft_transcendence/venv/lib/python3.11/site-packages/django/views/generic/base.py", line 104, in view
    return self.dispatch(request, *args, **kwargs)
           ^^^^^^^^^^^^^^^^^^^^^^^^^^^^^^^^^^^^^^^
  File "/home/ft_transcendence/venv/lib/python3.11/site-packages/rest_framework/views.py", line 509, in dispatch
    response = self.handle_exception(exc)
               ^^^^^^^^^^^^^^^^^^^^^^^^^^
  File "/home/ft_transcendence/venv/lib/python3.11/site-packages/rest_framework/views.py", line 469, in handle_exception
    self.raise_uncaught_exception(exc)
  File "/home/ft_transcendence/venv/lib/python3.11/site-packages/rest_framework/views.py", line 480, in raise_uncaught_exception
    raise exc
  File "/home/ft_transcendence/venv/lib/python3.11/site-packages/rest_framework/views.py", line 506, in dispatch
    response = handler(request, *args, **kwargs)
               ^^^^^^^^^^^^^^^^^^^^^^^^^^^^^^^^^
  File "/home/ft_transcendence/src/api/views/account.py", line 46, in post
    serializer.is_valid(raise_exception=True)
  File "/home/ft_transcendence/venv/lib/python3.11/site-packages/rest_framework/serializers.py", line 227, in is_valid
    self._validated_data = self.run_validation(self.initial_data)
                           ^^^^^^^^^^^^^^^^^^^^^^^^^^^^^^^^^^^^^^
  File "/home/ft_transcendence/venv/lib/python3.11/site-packages/rest_framework/serializers.py", line 429, in run_validation
    value = self.validate(value)
            ^^^^^^^^^^^^^^^^^^^^
  File "/home/ft_transcendence/src/api/serializers/account.py", line 90, in validate
    or not user.is_valid_otp()
           ^^^^^^^^^^^^^^^^^
AttributeError: 'Account' object has no attribute 'is_valid_otp'
Internal Server Error: /auth/otp
Traceback (most recent call last):
  File "/home/ft_transcendence/venv/lib/python3.11/site-packages/django/core/handlers/exception.py", line 55, in inner
    response = get_response(request)
               ^^^^^^^^^^^^^^^^^^^^^
  File "/home/ft_transcendence/venv/lib/python3.11/site-packages/django/core/handlers/base.py", line 197, in _get_response
    response = wrapped_callback(request, *callback_args, **callback_kwargs)
               ^^^^^^^^^^^^^^^^^^^^^^^^^^^^^^^^^^^^^^^^^^^^^^^^^^^^^^^^^^^^
  File "/home/ft_transcendence/venv/lib/python3.11/site-packages/django/views/decorators/csrf.py", line 56, in wrapper_view
    return view_func(*args, **kwargs)
           ^^^^^^^^^^^^^^^^^^^^^^^^^^
  File "/home/ft_transcendence/venv/lib/python3.11/site-packages/django/views/generic/base.py", line 104, in view
    return self.dispatch(request, *args, **kwargs)
           ^^^^^^^^^^^^^^^^^^^^^^^^^^^^^^^^^^^^^^^
  File "/home/ft_transcendence/venv/lib/python3.11/site-packages/rest_framework/views.py", line 509, in dispatch
    response = self.handle_exception(exc)
               ^^^^^^^^^^^^^^^^^^^^^^^^^^
  File "/home/ft_transcendence/venv/lib/python3.11/site-packages/rest_framework/views.py", line 469, in handle_exception
    self.raise_uncaught_exception(exc)
  File "/home/ft_transcendence/venv/lib/python3.11/site-packages/rest_framework/views.py", line 480, in raise_uncaught_exception
    raise exc
  File "/home/ft_transcendence/venv/lib/python3.11/site-packages/rest_framework/views.py", line 506, in dispatch
    response = handler(request, *args, **kwargs)
               ^^^^^^^^^^^^^^^^^^^^^^^^^^^^^^^^^
  File "/home/ft_transcendence/src/api/views/account.py", line 46, in post
    serializer.is_valid(raise_exception=True)
  File "/home/ft_transcendence/venv/lib/python3.11/site-packages/rest_framework/serializers.py", line 227, in is_valid
    self._validated_data = self.run_validation(self.initial_data)
                           ^^^^^^^^^^^^^^^^^^^^^^^^^^^^^^^^^^^^^^
  File "/home/ft_transcendence/venv/lib/python3.11/site-packages/rest_framework/serializers.py", line 429, in run_validation
    value = self.validate(value)
            ^^^^^^^^^^^^^^^^^^^^
  File "/home/ft_transcendence/src/api/serializers/account.py", line 90, in validate
    or not user.is_valid_otp()
           ^^^^^^^^^^^^^^^^^
AttributeError: 'Account' object has no attribute 'is_valid_otp'
Internal Server Error: /auth/otp
Traceback (most recent call last):
  File "/home/ft_transcendence/venv/lib/python3.11/site-packages/django/core/handlers/exception.py", line 55, in inner
    response = get_response(request)
               ^^^^^^^^^^^^^^^^^^^^^
  File "/home/ft_transcendence/venv/lib/python3.11/site-packages/django/core/handlers/base.py", line 197, in _get_response
    response = wrapped_callback(request, *callback_args, **callback_kwargs)
               ^^^^^^^^^^^^^^^^^^^^^^^^^^^^^^^^^^^^^^^^^^^^^^^^^^^^^^^^^^^^
  File "/home/ft_transcendence/venv/lib/python3.11/site-packages/django/views/decorators/csrf.py", line 56, in wrapper_view
    return view_func(*args, **kwargs)
           ^^^^^^^^^^^^^^^^^^^^^^^^^^
  File "/home/ft_transcendence/venv/lib/python3.11/site-packages/django/views/generic/base.py", line 104, in view
    return self.dispatch(request, *args, **kwargs)
           ^^^^^^^^^^^^^^^^^^^^^^^^^^^^^^^^^^^^^^^
  File "/home/ft_transcendence/venv/lib/python3.11/site-packages/rest_framework/views.py", line 509, in dispatch
    response = self.handle_exception(exc)
               ^^^^^^^^^^^^^^^^^^^^^^^^^^
  File "/home/ft_transcendence/venv/lib/python3.11/site-packages/rest_framework/views.py", line 469, in handle_exception
    self.raise_uncaught_exception(exc)
  File "/home/ft_transcendence/venv/lib/python3.11/site-packages/rest_framework/views.py", line 480, in raise_uncaught_exception
    raise exc
  File "/home/ft_transcendence/venv/lib/python3.11/site-packages/rest_framework/views.py", line 506, in dispatch
    response = handler(request, *args, **kwargs)
               ^^^^^^^^^^^^^^^^^^^^^^^^^^^^^^^^^
  File "/home/ft_transcendence/src/api/views/account.py", line 46, in post
    serializer.is_valid(raise_exception=True)
  File "/home/ft_transcendence/venv/lib/python3.11/site-packages/rest_framework/serializers.py", line 227, in is_valid
    self._validated_data = self.run_validation(self.initial_data)
                           ^^^^^^^^^^^^^^^^^^^^^^^^^^^^^^^^^^^^^^
  File "/home/ft_transcendence/venv/lib/python3.11/site-packages/rest_framework/serializers.py", line 429, in run_validation
    value = self.validate(value)
            ^^^^^^^^^^^^^^^^^^^^
  File "/home/ft_transcendence/src/api/serializers/account.py", line 90, in validate
    or not user.is_valid_otp()
           ^^^^^^^^^^^^^^^^^
AttributeError: 'Account' object has no attribute 'is_valid_otp'
Bad Request: /auth/login
Invalid HTTP_HOST header: '10.3.3.4:5000'. You may need to add '10.3.3.4' to ALLOWED_HOSTS.
Traceback (most recent call last):
  File "/home/ft_transcendence/venv/lib/python3.11/site-packages/django/core/handlers/exception.py", line 55, in inner
    response = get_response(request)
               ^^^^^^^^^^^^^^^^^^^^^
  File "/home/ft_transcendence/venv/lib/python3.11/site-packages/django/utils/deprecation.py", line 133, in __call__
    response = self.process_request(request)
               ^^^^^^^^^^^^^^^^^^^^^^^^^^^^^
  File "/home/ft_transcendence/venv/lib/python3.11/site-packages/django/middleware/common.py", line 48, in process_request
    host = request.get_host()
           ^^^^^^^^^^^^^^^^^^
  File "/home/ft_transcendence/venv/lib/python3.11/site-packages/django/http/request.py", line 150, in get_host
    raise DisallowedHost(msg)
django.core.exceptions.DisallowedHost: Invalid HTTP_HOST header: '10.3.3.4:5000'. You may need to add '10.3.3.4' to ALLOWED_HOSTS.
Bad Request: /
Invalid HTTP_HOST header: '10.3.3.4:5000'. You may need to add '10.3.3.4' to ALLOWED_HOSTS.
Traceback (most recent call last):
  File "/home/ft_transcendence/venv/lib/python3.11/site-packages/django/core/handlers/exception.py", line 55, in inner
    response = get_response(request)
               ^^^^^^^^^^^^^^^^^^^^^
  File "/home/ft_transcendence/venv/lib/python3.11/site-packages/django/utils/deprecation.py", line 133, in __call__
    response = self.process_request(request)
               ^^^^^^^^^^^^^^^^^^^^^^^^^^^^^
  File "/home/ft_transcendence/venv/lib/python3.11/site-packages/django/middleware/common.py", line 48, in process_request
    host = request.get_host()
           ^^^^^^^^^^^^^^^^^^
  File "/home/ft_transcendence/venv/lib/python3.11/site-packages/django/http/request.py", line 150, in get_host
    raise DisallowedHost(msg)
django.core.exceptions.DisallowedHost: Invalid HTTP_HOST header: '10.3.3.4:5000'. You may need to add '10.3.3.4' to ALLOWED_HOSTS.
Bad Request: /favicon.ico
[2024-02-13 12:30:16 +0000] [7] [INFO] Handling signal: term
[2024-02-13 12:30:16 +0000] [12] [INFO] Worker exiting (pid: 12)
[2024-02-13 12:30:16 +0000] [7] [INFO] Shutting down: Master
[2024-02-13 12:30:20 +0000] [7] [INFO] Starting gunicorn 21.2.0
[2024-02-13 12:30:20 +0000] [7] [INFO] Listening at: http://0.0.0.0:8000 (7)
[2024-02-13 12:30:20 +0000] [7] [INFO] Using worker: sync
[2024-02-13 12:30:20 +0000] [12] [INFO] Booting worker with pid: 12
[2024-02-13 12:31:01 +0000] [7] [INFO] Handling signal: term
[2024-02-13 12:31:01 +0000] [12] [INFO] Worker exiting (pid: 12)
[2024-02-13 12:31:02 +0000] [7] [INFO] Shutting down: Master
[2024-02-13 12:31:04 +0000] [7] [INFO] Starting gunicorn 21.2.0
[2024-02-13 12:31:04 +0000] [7] [INFO] Listening at: http://0.0.0.0:8000 (7)
[2024-02-13 12:31:04 +0000] [7] [INFO] Using worker: sync
[2024-02-13 12:31:04 +0000] [12] [INFO] Booting worker with pid: 12
[2024-02-13 12:31:42 +0000] [7] [INFO] Handling signal: term
[2024-02-13 12:31:42 +0000] [12] [INFO] Worker exiting (pid: 12)
[2024-02-13 12:31:42 +0000] [7] [INFO] Shutting down: Master
[2024-02-13 12:31:45 +0000] [7] [INFO] Starting gunicorn 21.2.0
[2024-02-13 12:31:45 +0000] [7] [INFO] Listening at: http://0.0.0.0:8000 (7)
[2024-02-13 12:31:45 +0000] [7] [INFO] Using worker: sync
[2024-02-13 12:31:45 +0000] [12] [INFO] Booting worker with pid: 12
[2024-02-13 12:34:06 +0000] [7] [INFO] Handling signal: term
[2024-02-13 12:34:06 +0000] [12] [INFO] Worker exiting (pid: 12)
[2024-02-13 12:34:06 +0000] [7] [INFO] Shutting down: Master
[2024-02-13 12:34:09 +0000] [7] [INFO] Starting gunicorn 21.2.0
[2024-02-13 12:34:09 +0000] [7] [INFO] Listening at: http://0.0.0.0:8000 (7)
[2024-02-13 12:34:09 +0000] [7] [INFO] Using worker: sync
[2024-02-13 12:34:09 +0000] [12] [INFO] Booting worker with pid: 12
[2024-02-13 12:35:30 +0000] [7] [INFO] Handling signal: term
[2024-02-13 12:35:30 +0000] [12] [INFO] Worker exiting (pid: 12)
[2024-02-13 12:35:30 +0000] [7] [INFO] Shutting down: Master
[2024-02-13 12:35:33 +0000] [7] [INFO] Starting gunicorn 21.2.0
[2024-02-13 12:35:33 +0000] [7] [INFO] Listening at: http://0.0.0.0:8000 (7)
[2024-02-13 12:35:33 +0000] [7] [INFO] Using worker: sync
[2024-02-13 12:35:33 +0000] [12] [INFO] Booting worker with pid: 12
[2024-02-13 12:36:05 +0000] [7] [INFO] Handling signal: term
[2024-02-13 12:36:05 +0000] [12] [INFO] Worker exiting (pid: 12)
[2024-02-13 12:36:05 +0000] [7] [INFO] Shutting down: Master
[2024-02-13 12:36:51 +0000] [6] [INFO] Starting gunicorn 21.2.0
[2024-02-13 12:36:51 +0000] [6] [INFO] Listening at: http://0.0.0.0:8000 (6)
[2024-02-13 12:36:51 +0000] [6] [INFO] Using worker: sync
[2024-02-13 12:36:51 +0000] [11] [INFO] Booting worker with pid: 11
[2024-02-13 12:37:37 +0000] [6] [INFO] Handling signal: term
[2024-02-13 12:37:37 +0000] [11] [INFO] Worker exiting (pid: 11)
[2024-02-13 12:37:37 +0000] [6] [INFO] Shutting down: Master
[2024-02-13 12:41:48 +0000] [7] [INFO] Starting gunicorn 21.2.0
[2024-02-13 12:41:48 +0000] [7] [INFO] Listening at: http://0.0.0.0:8000 (7)
[2024-02-13 12:41:48 +0000] [7] [INFO] Using worker: sync
[2024-02-13 12:41:48 +0000] [12] [INFO] Booting worker with pid: 12
[2024-02-13 12:43:08 +0000] [7] [INFO] Handling signal: term
[2024-02-13 12:43:08 +0000] [12] [INFO] Worker exiting (pid: 12)
[2024-02-13 12:43:08 +0000] [7] [INFO] Shutting down: Master
[2024-02-13 12:43:11 +0000] [7] [INFO] Starting gunicorn 21.2.0
[2024-02-13 12:43:11 +0000] [7] [INFO] Listening at: http://0.0.0.0:8000 (7)
[2024-02-13 12:43:11 +0000] [7] [INFO] Using worker: sync
[2024-02-13 12:43:11 +0000] [12] [INFO] Booting worker with pid: 12
Internal Server Error: /auth/otp
Traceback (most recent call last):
  File "/home/ft_transcendence/venv/lib/python3.11/site-packages/django/core/handlers/exception.py", line 55, in inner
    response = get_response(request)
               ^^^^^^^^^^^^^^^^^^^^^
  File "/home/ft_transcendence/venv/lib/python3.11/site-packages/django/core/handlers/base.py", line 197, in _get_response
    response = wrapped_callback(request, *callback_args, **callback_kwargs)
               ^^^^^^^^^^^^^^^^^^^^^^^^^^^^^^^^^^^^^^^^^^^^^^^^^^^^^^^^^^^^
  File "/home/ft_transcendence/venv/lib/python3.11/site-packages/django/views/decorators/csrf.py", line 56, in wrapper_view
    return view_func(*args, **kwargs)
           ^^^^^^^^^^^^^^^^^^^^^^^^^^
  File "/home/ft_transcendence/venv/lib/python3.11/site-packages/django/views/generic/base.py", line 104, in view
    return self.dispatch(request, *args, **kwargs)
           ^^^^^^^^^^^^^^^^^^^^^^^^^^^^^^^^^^^^^^^
  File "/home/ft_transcendence/venv/lib/python3.11/site-packages/rest_framework/views.py", line 509, in dispatch
    response = self.handle_exception(exc)
               ^^^^^^^^^^^^^^^^^^^^^^^^^^
  File "/home/ft_transcendence/venv/lib/python3.11/site-packages/rest_framework/views.py", line 469, in handle_exception
    self.raise_uncaught_exception(exc)
  File "/home/ft_transcendence/venv/lib/python3.11/site-packages/rest_framework/views.py", line 480, in raise_uncaught_exception
    raise exc
  File "/home/ft_transcendence/venv/lib/python3.11/site-packages/rest_framework/views.py", line 506, in dispatch
    response = handler(request, *args, **kwargs)
               ^^^^^^^^^^^^^^^^^^^^^^^^^^^^^^^^^
  File "/home/ft_transcendence/src/api/views/account.py", line 46, in post
    serializer.is_valid(raise_exception=True)
  File "/home/ft_transcendence/venv/lib/python3.11/site-packages/rest_framework/serializers.py", line 227, in is_valid
    self._validated_data = self.run_validation(self.initial_data)
                           ^^^^^^^^^^^^^^^^^^^^^^^^^^^^^^^^^^^^^^
  File "/home/ft_transcendence/venv/lib/python3.11/site-packages/rest_framework/serializers.py", line 429, in run_validation
    value = self.validate(value)
            ^^^^^^^^^^^^^^^^^^^^
  File "/home/ft_transcendence/src/api/serializers/account.py", line 90, in validate
    or not user.is_valid_otp()
           ^^^^^^^^^^^^^^^^^
AttributeError: 'Account' object has no attribute 'is_valid_otp'
Bad Request: /auth/login
Bad Request: /auth/login
Bad Request: /auth/login
Bad Request: /auth/login
Bad Request: /auth/login
Bad Request: /auth/login
Bad Request: /auth/login
Bad Request: /auth/login
Bad Request: /auth/login
Bad Request: /auth/login
[2024-02-13 13:00:07 +0000] [7] [INFO] Handling signal: term
[2024-02-13 13:00:07 +0000] [12] [INFO] Worker exiting (pid: 12)
[2024-02-13 13:00:07 +0000] [7] [INFO] Shutting down: Master
[2024-02-13 13:00:10 +0000] [7] [INFO] Starting gunicorn 21.2.0
[2024-02-13 13:00:10 +0000] [7] [INFO] Listening at: http://0.0.0.0:8000 (7)
[2024-02-13 13:00:10 +0000] [7] [INFO] Using worker: sync
[2024-02-13 13:00:10 +0000] [12] [INFO] Booting worker with pid: 12
Bad Request: /auth/otp
Bad Request: /auth/otp
Bad Request: /auth/otp
Bad Request: /auth/otp
Bad Request: /auth/otp
Bad Request: /auth/otp
Bad Request: /auth/otp
Bad Request: /auth/otp
Bad Request: /auth/otp
Bad Request: /auth/otp
Internal Server Error: /auth/otp
Traceback (most recent call last):
  File "/home/ft_transcendence/venv/lib/python3.11/site-packages/django/core/handlers/exception.py", line 55, in inner
    response = get_response(request)
               ^^^^^^^^^^^^^^^^^^^^^
  File "/home/ft_transcendence/venv/lib/python3.11/site-packages/django/core/handlers/base.py", line 197, in _get_response
    response = wrapped_callback(request, *callback_args, **callback_kwargs)
               ^^^^^^^^^^^^^^^^^^^^^^^^^^^^^^^^^^^^^^^^^^^^^^^^^^^^^^^^^^^^
  File "/home/ft_transcendence/venv/lib/python3.11/site-packages/django/views/decorators/csrf.py", line 56, in wrapper_view
    return view_func(*args, **kwargs)
           ^^^^^^^^^^^^^^^^^^^^^^^^^^
  File "/home/ft_transcendence/venv/lib/python3.11/site-packages/django/views/generic/base.py", line 104, in view
    return self.dispatch(request, *args, **kwargs)
           ^^^^^^^^^^^^^^^^^^^^^^^^^^^^^^^^^^^^^^^
  File "/home/ft_transcendence/venv/lib/python3.11/site-packages/rest_framework/views.py", line 509, in dispatch
    response = self.handle_exception(exc)
               ^^^^^^^^^^^^^^^^^^^^^^^^^^
  File "/home/ft_transcendence/venv/lib/python3.11/site-packages/rest_framework/views.py", line 469, in handle_exception
    self.raise_uncaught_exception(exc)
  File "/home/ft_transcendence/venv/lib/python3.11/site-packages/rest_framework/views.py", line 480, in raise_uncaught_exception
    raise exc
  File "/home/ft_transcendence/venv/lib/python3.11/site-packages/rest_framework/views.py", line 506, in dispatch
    response = handler(request, *args, **kwargs)
               ^^^^^^^^^^^^^^^^^^^^^^^^^^^^^^^^^
  File "/home/ft_transcendence/src/api/views/account.py", line 46, in post
    serializer.is_valid(raise_exception=True)
  File "/home/ft_transcendence/venv/lib/python3.11/site-packages/rest_framework/serializers.py", line 227, in is_valid
    self._validated_data = self.run_validation(self.initial_data)
                           ^^^^^^^^^^^^^^^^^^^^^^^^^^^^^^^^^^^^^^
  File "/home/ft_transcendence/venv/lib/python3.11/site-packages/rest_framework/serializers.py", line 429, in run_validation
    value = self.validate(value)
            ^^^^^^^^^^^^^^^^^^^^
  File "/home/ft_transcendence/src/api/serializers/account.py", line 90, in validate
    or not user.is_valid_otp()
           ^^^^^^^^^^^^^^^^^
AttributeError: 'Account' object has no attribute 'is_valid_otp'
Bad Request: /auth/otp
Bad Request: /auth/otp
[2024-02-13 13:08:53 +0000] [7] [INFO] Handling signal: term
[2024-02-13 13:08:53 +0000] [12] [INFO] Worker exiting (pid: 12)
[2024-02-13 13:08:54 +0000] [7] [INFO] Shutting down: Master
[2024-02-13 13:08:57 +0000] [7] [INFO] Starting gunicorn 21.2.0
[2024-02-13 13:08:57 +0000] [7] [INFO] Listening at: http://0.0.0.0:8000 (7)
[2024-02-13 13:08:57 +0000] [7] [INFO] Using worker: sync
[2024-02-13 13:08:57 +0000] [12] [INFO] Booting worker with pid: 12
Internal Server Error: /auth/otp
Traceback (most recent call last):
  File "/home/ft_transcendence/venv/lib/python3.11/site-packages/django/core/handlers/exception.py", line 55, in inner
    response = get_response(request)
               ^^^^^^^^^^^^^^^^^^^^^
  File "/home/ft_transcendence/venv/lib/python3.11/site-packages/django/core/handlers/base.py", line 197, in _get_response
    response = wrapped_callback(request, *callback_args, **callback_kwargs)
               ^^^^^^^^^^^^^^^^^^^^^^^^^^^^^^^^^^^^^^^^^^^^^^^^^^^^^^^^^^^^
  File "/home/ft_transcendence/venv/lib/python3.11/site-packages/django/views/decorators/csrf.py", line 56, in wrapper_view
    return view_func(*args, **kwargs)
           ^^^^^^^^^^^^^^^^^^^^^^^^^^
  File "/home/ft_transcendence/venv/lib/python3.11/site-packages/django/views/generic/base.py", line 104, in view
    return self.dispatch(request, *args, **kwargs)
           ^^^^^^^^^^^^^^^^^^^^^^^^^^^^^^^^^^^^^^^
  File "/home/ft_transcendence/venv/lib/python3.11/site-packages/rest_framework/views.py", line 509, in dispatch
    response = self.handle_exception(exc)
               ^^^^^^^^^^^^^^^^^^^^^^^^^^
  File "/home/ft_transcendence/venv/lib/python3.11/site-packages/rest_framework/views.py", line 469, in handle_exception
    self.raise_uncaught_exception(exc)
  File "/home/ft_transcendence/venv/lib/python3.11/site-packages/rest_framework/views.py", line 480, in raise_uncaught_exception
    raise exc
  File "/home/ft_transcendence/venv/lib/python3.11/site-packages/rest_framework/views.py", line 506, in dispatch
    response = handler(request, *args, **kwargs)
               ^^^^^^^^^^^^^^^^^^^^^^^^^^^^^^^^^
  File "/home/ft_transcendence/src/api/views/account.py", line 46, in post
    serializer.is_valid(raise_exception=True)
  File "/home/ft_transcendence/venv/lib/python3.11/site-packages/rest_framework/serializers.py", line 227, in is_valid
    self._validated_data = self.run_validation(self.initial_data)
                           ^^^^^^^^^^^^^^^^^^^^^^^^^^^^^^^^^^^^^^
  File "/home/ft_transcendence/venv/lib/python3.11/site-packages/rest_framework/serializers.py", line 429, in run_validation
    value = self.validate(value)
            ^^^^^^^^^^^^^^^^^^^^
  File "/home/ft_transcendence/src/api/serializers/account.py", line 87, in validate
    if ((attrs.get("otp") != user.login_otp) or not user.is_valid_otp()):
                                                    ^^^^^^^^^^^^^^^^^
AttributeError: 'Account' object has no attribute 'is_valid_otp'
[2024-02-13 13:10:45 +0000] [7] [INFO] Handling signal: term
[2024-02-13 13:10:45 +0000] [12] [INFO] Worker exiting (pid: 12)
[2024-02-13 13:10:45 +0000] [7] [INFO] Shutting down: Master
[2024-02-13 13:10:49 +0000] [7] [INFO] Starting gunicorn 21.2.0
[2024-02-13 13:10:49 +0000] [7] [INFO] Listening at: http://0.0.0.0:8000 (7)
[2024-02-13 13:10:49 +0000] [7] [INFO] Using worker: sync
[2024-02-13 13:10:49 +0000] [12] [INFO] Booting worker with pid: 12
[2024-02-13 13:11:32 +0000] [7] [INFO] Handling signal: term
[2024-02-13 13:11:32 +0000] [12] [INFO] Worker exiting (pid: 12)
[2024-02-13 13:11:32 +0000] [7] [INFO] Shutting down: Master
[2024-02-13 13:11:35 +0000] [7] [INFO] Starting gunicorn 21.2.0
[2024-02-13 13:11:35 +0000] [7] [INFO] Listening at: http://0.0.0.0:8000 (7)
[2024-02-13 13:11:35 +0000] [7] [INFO] Using worker: sync
[2024-02-13 13:11:35 +0000] [12] [INFO] Booting worker with pid: 12
Internal Server Error: /auth/otp
Traceback (most recent call last):
  File "/home/ft_transcendence/venv/lib/python3.11/site-packages/django/core/handlers/exception.py", line 55, in inner
    response = get_response(request)
               ^^^^^^^^^^^^^^^^^^^^^
  File "/home/ft_transcendence/venv/lib/python3.11/site-packages/django/core/handlers/base.py", line 197, in _get_response
    response = wrapped_callback(request, *callback_args, **callback_kwargs)
               ^^^^^^^^^^^^^^^^^^^^^^^^^^^^^^^^^^^^^^^^^^^^^^^^^^^^^^^^^^^^
  File "/home/ft_transcendence/venv/lib/python3.11/site-packages/django/views/decorators/csrf.py", line 56, in wrapper_view
    return view_func(*args, **kwargs)
           ^^^^^^^^^^^^^^^^^^^^^^^^^^
  File "/home/ft_transcendence/venv/lib/python3.11/site-packages/django/views/generic/base.py", line 104, in view
    return self.dispatch(request, *args, **kwargs)
           ^^^^^^^^^^^^^^^^^^^^^^^^^^^^^^^^^^^^^^^
  File "/home/ft_transcendence/venv/lib/python3.11/site-packages/rest_framework/views.py", line 509, in dispatch
    response = self.handle_exception(exc)
               ^^^^^^^^^^^^^^^^^^^^^^^^^^
  File "/home/ft_transcendence/venv/lib/python3.11/site-packages/rest_framework/views.py", line 469, in handle_exception
    self.raise_uncaught_exception(exc)
  File "/home/ft_transcendence/venv/lib/python3.11/site-packages/rest_framework/views.py", line 480, in raise_uncaught_exception
    raise exc
  File "/home/ft_transcendence/venv/lib/python3.11/site-packages/rest_framework/views.py", line 506, in dispatch
    response = handler(request, *args, **kwargs)
               ^^^^^^^^^^^^^^^^^^^^^^^^^^^^^^^^^
  File "/home/ft_transcendence/src/api/views/account.py", line 46, in post
    serializer.is_valid(raise_exception=True)
  File "/home/ft_transcendence/venv/lib/python3.11/site-packages/rest_framework/serializers.py", line 227, in is_valid
    self._validated_data = self.run_validation(self.initial_data)
                           ^^^^^^^^^^^^^^^^^^^^^^^^^^^^^^^^^^^^^^
  File "/home/ft_transcendence/venv/lib/python3.11/site-packages/rest_framework/serializers.py", line 429, in run_validation
    value = self.validate(value)
            ^^^^^^^^^^^^^^^^^^^^
  File "/home/ft_transcendence/src/api/serializers/account.py", line 87, in validate
    if ((attrs.get("otp") != user.login_otp) or not user.is_valid_otp()):
                                                    ^^^^^^^^^^^^^^^^^
AttributeError: 'Account' object has no attribute 'is_valid_otp'
[2024-02-13 13:14:47 +0000] [7] [INFO] Handling signal: term
[2024-02-13 13:14:47 +0000] [12] [INFO] Worker exiting (pid: 12)
[2024-02-13 13:14:47 +0000] [7] [INFO] Shutting down: Master
[2024-02-13 13:14:51 +0000] [6] [INFO] Starting gunicorn 21.2.0
[2024-02-13 13:14:51 +0000] [6] [INFO] Listening at: http://0.0.0.0:8000 (6)
[2024-02-13 13:14:51 +0000] [6] [INFO] Using worker: sync
[2024-02-13 13:14:51 +0000] [11] [INFO] Booting worker with pid: 11
Internal Server Error: /auth/otp
Traceback (most recent call last):
  File "/home/ft_transcendence/venv/lib/python3.11/site-packages/django/core/handlers/exception.py", line 55, in inner
    response = get_response(request)
               ^^^^^^^^^^^^^^^^^^^^^
  File "/home/ft_transcendence/venv/lib/python3.11/site-packages/django/core/handlers/base.py", line 197, in _get_response
    response = wrapped_callback(request, *callback_args, **callback_kwargs)
               ^^^^^^^^^^^^^^^^^^^^^^^^^^^^^^^^^^^^^^^^^^^^^^^^^^^^^^^^^^^^
  File "/home/ft_transcendence/venv/lib/python3.11/site-packages/django/views/decorators/csrf.py", line 56, in wrapper_view
    return view_func(*args, **kwargs)
           ^^^^^^^^^^^^^^^^^^^^^^^^^^
  File "/home/ft_transcendence/venv/lib/python3.11/site-packages/django/views/generic/base.py", line 104, in view
    return self.dispatch(request, *args, **kwargs)
           ^^^^^^^^^^^^^^^^^^^^^^^^^^^^^^^^^^^^^^^
  File "/home/ft_transcendence/venv/lib/python3.11/site-packages/rest_framework/views.py", line 509, in dispatch
    response = self.handle_exception(exc)
               ^^^^^^^^^^^^^^^^^^^^^^^^^^
  File "/home/ft_transcendence/venv/lib/python3.11/site-packages/rest_framework/views.py", line 469, in handle_exception
    self.raise_uncaught_exception(exc)
  File "/home/ft_transcendence/venv/lib/python3.11/site-packages/rest_framework/views.py", line 480, in raise_uncaught_exception
    raise exc
  File "/home/ft_transcendence/venv/lib/python3.11/site-packages/rest_framework/views.py", line 506, in dispatch
    response = handler(request, *args, **kwargs)
               ^^^^^^^^^^^^^^^^^^^^^^^^^^^^^^^^^
  File "/home/ft_transcendence/src/api/views/account.py", line 46, in post
    serializer.is_valid(raise_exception=True)
  File "/home/ft_transcendence/venv/lib/python3.11/site-packages/rest_framework/serializers.py", line 227, in is_valid
    self._validated_data = self.run_validation(self.initial_data)
                           ^^^^^^^^^^^^^^^^^^^^^^^^^^^^^^^^^^^^^^
  File "/home/ft_transcendence/venv/lib/python3.11/site-packages/rest_framework/serializers.py", line 429, in run_validation
    value = self.validate(value)
            ^^^^^^^^^^^^^^^^^^^^
  File "/home/ft_transcendence/src/api/serializers/account.py", line 87, in validate
    if ((attrs.get("otp") != user.login_otp) or not user.is_valid_otp()):
                                                    ^^^^^^^^^^^^^^^^^
  File "/home/ft_transcendence/src/api/models.py", line 24, in is_valid_otp
    now = datetime.now(timezone.utc)
          ^^^^^^^^
NameError: name 'datetime' is not defined
[2024-02-13 13:16:34 +0000] [6] [INFO] Handling signal: term
[2024-02-13 13:16:34 +0000] [11] [INFO] Worker exiting (pid: 11)
[2024-02-13 13:16:34 +0000] [6] [INFO] Shutting down: Master
[2024-02-13 13:16:37 +0000] [7] [INFO] Starting gunicorn 21.2.0
[2024-02-13 13:16:37 +0000] [7] [INFO] Listening at: http://0.0.0.0:8000 (7)
[2024-02-13 13:16:37 +0000] [7] [INFO] Using worker: sync
[2024-02-13 13:16:37 +0000] [12] [INFO] Booting worker with pid: 12
Internal Server Error: /auth/otp
Traceback (most recent call last):
  File "/home/ft_transcendence/venv/lib/python3.11/site-packages/django/core/handlers/exception.py", line 55, in inner
    response = get_response(request)
               ^^^^^^^^^^^^^^^^^^^^^
  File "/home/ft_transcendence/venv/lib/python3.11/site-packages/django/core/handlers/base.py", line 197, in _get_response
    response = wrapped_callback(request, *callback_args, **callback_kwargs)
               ^^^^^^^^^^^^^^^^^^^^^^^^^^^^^^^^^^^^^^^^^^^^^^^^^^^^^^^^^^^^
  File "/home/ft_transcendence/venv/lib/python3.11/site-packages/django/views/decorators/csrf.py", line 56, in wrapper_view
    return view_func(*args, **kwargs)
           ^^^^^^^^^^^^^^^^^^^^^^^^^^
  File "/home/ft_transcendence/venv/lib/python3.11/site-packages/django/views/generic/base.py", line 104, in view
    return self.dispatch(request, *args, **kwargs)
           ^^^^^^^^^^^^^^^^^^^^^^^^^^^^^^^^^^^^^^^
  File "/home/ft_transcendence/venv/lib/python3.11/site-packages/rest_framework/views.py", line 509, in dispatch
    response = self.handle_exception(exc)
               ^^^^^^^^^^^^^^^^^^^^^^^^^^
  File "/home/ft_transcendence/venv/lib/python3.11/site-packages/rest_framework/views.py", line 469, in handle_exception
    self.raise_uncaught_exception(exc)
  File "/home/ft_transcendence/venv/lib/python3.11/site-packages/rest_framework/views.py", line 480, in raise_uncaught_exception
    raise exc
  File "/home/ft_transcendence/venv/lib/python3.11/site-packages/rest_framework/views.py", line 506, in dispatch
    response = handler(request, *args, **kwargs)
               ^^^^^^^^^^^^^^^^^^^^^^^^^^^^^^^^^
  File "/home/ft_transcendence/src/api/views/account.py", line 46, in post
    serializer.is_valid(raise_exception=True)
  File "/home/ft_transcendence/venv/lib/python3.11/site-packages/rest_framework/serializers.py", line 227, in is_valid
    self._validated_data = self.run_validation(self.initial_data)
                           ^^^^^^^^^^^^^^^^^^^^^^^^^^^^^^^^^^^^^^
  File "/home/ft_transcendence/venv/lib/python3.11/site-packages/rest_framework/serializers.py", line 429, in run_validation
    value = self.validate(value)
            ^^^^^^^^^^^^^^^^^^^^
  File "/home/ft_transcendence/src/api/serializers/account.py", line 87, in validate
    if ((attrs.get("otp") != user.login_otp) or not user.is_valid_otp()):
                                                    ^^^^^^^^^^^^^^^^^
  File "/home/ft_transcendence/src/api/models.py", line 26, in is_valid_otp
    now = datetime.now(timezone.utc)
          ^^^^^^^^^^^^
AttributeError: module 'datetime' has no attribute 'now'
[2024-02-13 13:17:35 +0000] [7] [INFO] Handling signal: term
[2024-02-13 13:17:35 +0000] [12] [INFO] Worker exiting (pid: 12)
[2024-02-13 13:17:35 +0000] [7] [INFO] Shutting down: Master
[2024-02-13 13:17:38 +0000] [7] [INFO] Starting gunicorn 21.2.0
[2024-02-13 13:17:38 +0000] [7] [INFO] Listening at: http://0.0.0.0:8000 (7)
[2024-02-13 13:17:38 +0000] [7] [INFO] Using worker: sync
[2024-02-13 13:17:38 +0000] [12] [INFO] Booting worker with pid: 12
Internal Server Error: /auth/otp
Traceback (most recent call last):
  File "/home/ft_transcendence/venv/lib/python3.11/site-packages/django/core/handlers/exception.py", line 55, in inner
    response = get_response(request)
               ^^^^^^^^^^^^^^^^^^^^^
  File "/home/ft_transcendence/venv/lib/python3.11/site-packages/django/core/handlers/base.py", line 197, in _get_response
    response = wrapped_callback(request, *callback_args, **callback_kwargs)
               ^^^^^^^^^^^^^^^^^^^^^^^^^^^^^^^^^^^^^^^^^^^^^^^^^^^^^^^^^^^^
  File "/home/ft_transcendence/venv/lib/python3.11/site-packages/django/views/decorators/csrf.py", line 56, in wrapper_view
    return view_func(*args, **kwargs)
           ^^^^^^^^^^^^^^^^^^^^^^^^^^
  File "/home/ft_transcendence/venv/lib/python3.11/site-packages/django/views/generic/base.py", line 104, in view
    return self.dispatch(request, *args, **kwargs)
           ^^^^^^^^^^^^^^^^^^^^^^^^^^^^^^^^^^^^^^^
  File "/home/ft_transcendence/venv/lib/python3.11/site-packages/rest_framework/views.py", line 509, in dispatch
    response = self.handle_exception(exc)
               ^^^^^^^^^^^^^^^^^^^^^^^^^^
  File "/home/ft_transcendence/venv/lib/python3.11/site-packages/rest_framework/views.py", line 469, in handle_exception
    self.raise_uncaught_exception(exc)
  File "/home/ft_transcendence/venv/lib/python3.11/site-packages/rest_framework/views.py", line 480, in raise_uncaught_exception
    raise exc
  File "/home/ft_transcendence/venv/lib/python3.11/site-packages/rest_framework/views.py", line 506, in dispatch
    response = handler(request, *args, **kwargs)
               ^^^^^^^^^^^^^^^^^^^^^^^^^^^^^^^^^
  File "/home/ft_transcendence/src/api/views/account.py", line 46, in post
    serializer.is_valid(raise_exception=True)
  File "/home/ft_transcendence/venv/lib/python3.11/site-packages/rest_framework/serializers.py", line 227, in is_valid
    self._validated_data = self.run_validation(self.initial_data)
                           ^^^^^^^^^^^^^^^^^^^^^^^^^^^^^^^^^^^^^^
  File "/home/ft_transcendence/venv/lib/python3.11/site-packages/rest_framework/serializers.py", line 429, in run_validation
    value = self.validate(value)
            ^^^^^^^^^^^^^^^^^^^^
  File "/home/ft_transcendence/src/api/serializers/account.py", line 87, in validate
    if ((attrs.get("otp") != user.login_otp) or not user.is_valid_otp()):
                                                    ^^^^^^^^^^^^^^^^^^^
TypeError: 'bool' object is not callable
[2024-02-13 13:19:20 +0000] [7] [INFO] Handling signal: term
[2024-02-13 13:19:20 +0000] [12] [INFO] Worker exiting (pid: 12)
[2024-02-13 13:19:20 +0000] [7] [INFO] Shutting down: Master
[2024-02-13 13:19:23 +0000] [6] [INFO] Starting gunicorn 21.2.0
[2024-02-13 13:19:23 +0000] [6] [INFO] Listening at: http://0.0.0.0:8000 (6)
[2024-02-13 13:19:23 +0000] [6] [INFO] Using worker: sync
[2024-02-13 13:19:23 +0000] [11] [INFO] Booting worker with pid: 11
Bad Request: /auth/otp
Bad Request: /auth/otp
Bad Request: /auth/otp
Bad Request: /auth/otp
Bad Request: /auth/otp
[2024-02-13 13:21:27 +0000] [6] [INFO] Handling signal: term
[2024-02-13 13:21:27 +0000] [11] [INFO] Worker exiting (pid: 11)
[2024-02-13 13:21:28 +0000] [6] [INFO] Shutting down: Master
[2024-02-13 13:21:30 +0000] [6] [INFO] Starting gunicorn 21.2.0
[2024-02-13 13:21:30 +0000] [6] [INFO] Listening at: http://0.0.0.0:8000 (6)
[2024-02-13 13:21:30 +0000] [6] [INFO] Using worker: sync
[2024-02-13 13:21:30 +0000] [11] [INFO] Booting worker with pid: 11
Bad Request: /auth/otp
[2024-02-13 13:24:42 +0000] [6] [INFO] Handling signal: term
[2024-02-13 13:24:42 +0000] [11] [INFO] Worker exiting (pid: 11)
[2024-02-13 13:24:42 +0000] [6] [INFO] Shutting down: Master
[2024-02-13 13:24:45 +0000] [7] [INFO] Starting gunicorn 21.2.0
[2024-02-13 13:24:45 +0000] [7] [INFO] Listening at: http://0.0.0.0:8000 (7)
[2024-02-13 13:24:45 +0000] [7] [INFO] Using worker: sync
[2024-02-13 13:24:45 +0000] [12] [INFO] Booting worker with pid: 12
Bad Request: /auth/otp
Bad Request: /auth/otp
Bad Request: /auth/otp
Bad Request: /auth/otp
Internal Server Error: /auth/otp
Traceback (most recent call last):
  File "/home/ft_transcendence/venv/lib/python3.11/site-packages/django/core/handlers/exception.py", line 55, in inner
    response = get_response(request)
               ^^^^^^^^^^^^^^^^^^^^^
  File "/home/ft_transcendence/venv/lib/python3.11/site-packages/django/core/handlers/base.py", line 197, in _get_response
    response = wrapped_callback(request, *callback_args, **callback_kwargs)
               ^^^^^^^^^^^^^^^^^^^^^^^^^^^^^^^^^^^^^^^^^^^^^^^^^^^^^^^^^^^^
  File "/home/ft_transcendence/venv/lib/python3.11/site-packages/django/views/decorators/csrf.py", line 56, in wrapper_view
    return view_func(*args, **kwargs)
           ^^^^^^^^^^^^^^^^^^^^^^^^^^
  File "/home/ft_transcendence/venv/lib/python3.11/site-packages/django/views/generic/base.py", line 104, in view
    return self.dispatch(request, *args, **kwargs)
           ^^^^^^^^^^^^^^^^^^^^^^^^^^^^^^^^^^^^^^^
  File "/home/ft_transcendence/venv/lib/python3.11/site-packages/rest_framework/views.py", line 509, in dispatch
    response = self.handle_exception(exc)
               ^^^^^^^^^^^^^^^^^^^^^^^^^^
  File "/home/ft_transcendence/venv/lib/python3.11/site-packages/rest_framework/views.py", line 469, in handle_exception
    self.raise_uncaught_exception(exc)
  File "/home/ft_transcendence/venv/lib/python3.11/site-packages/rest_framework/views.py", line 480, in raise_uncaught_exception
    raise exc
  File "/home/ft_transcendence/venv/lib/python3.11/site-packages/rest_framework/views.py", line 506, in dispatch
    response = handler(request, *args, **kwargs)
               ^^^^^^^^^^^^^^^^^^^^^^^^^^^^^^^^^
  File "/home/ft_transcendence/src/api/views/account.py", line 46, in post
    serializer.is_valid(raise_exception=True)
  File "/home/ft_transcendence/venv/lib/python3.11/site-packages/rest_framework/serializers.py", line 227, in is_valid
    self._validated_data = self.run_validation(self.initial_data)
                           ^^^^^^^^^^^^^^^^^^^^^^^^^^^^^^^^^^^^^^
  File "/home/ft_transcendence/venv/lib/python3.11/site-packages/rest_framework/serializers.py", line 429, in run_validation
    value = self.validate(value)
            ^^^^^^^^^^^^^^^^^^^^
  File "/home/ft_transcendence/src/api/serializers/account.py", line 89, in validate
    if ( not user.is_valid_otp()):
             ^^^^^^^^^^^^^^^^^^^
TypeError: 'bool' object is not callable
[2024-02-13 13:28:07 +0000] [7] [INFO] Handling signal: term
[2024-02-13 13:28:07 +0000] [12] [INFO] Worker exiting (pid: 12)
[2024-02-13 13:28:08 +0000] [7] [INFO] Shutting down: Master
[2024-02-13 13:28:10 +0000] [7] [INFO] Starting gunicorn 21.2.0
[2024-02-13 13:28:10 +0000] [7] [INFO] Listening at: http://0.0.0.0:8000 (7)
[2024-02-13 13:28:10 +0000] [7] [INFO] Using worker: sync
[2024-02-13 13:28:10 +0000] [12] [INFO] Booting worker with pid: 12
[2024-02-13 13:29:30 +0000] [7] [INFO] Handling signal: term
[2024-02-13 13:29:30 +0000] [12] [INFO] Worker exiting (pid: 12)
[2024-02-13 13:29:30 +0000] [7] [INFO] Shutting down: Master
[2024-02-13 13:29:34 +0000] [8] [INFO] Starting gunicorn 21.2.0
[2024-02-13 13:29:34 +0000] [8] [INFO] Listening at: http://0.0.0.0:8000 (8)
[2024-02-13 13:29:34 +0000] [8] [INFO] Using worker: sync
[2024-02-13 13:29:34 +0000] [13] [INFO] Booting worker with pid: 13
Bad Request: /auth/otp
Bad Request: /auth/otp
[2024-02-13 13:31:24 +0000] [8] [INFO] Handling signal: term
[2024-02-13 13:31:24 +0000] [13] [INFO] Worker exiting (pid: 13)
[2024-02-13 13:31:24 +0000] [8] [INFO] Shutting down: Master
[2024-02-13 13:31:27 +0000] [7] [INFO] Starting gunicorn 21.2.0
[2024-02-13 13:31:27 +0000] [7] [INFO] Listening at: http://0.0.0.0:8000 (7)
[2024-02-13 13:31:27 +0000] [7] [INFO] Using worker: sync
[2024-02-13 13:31:27 +0000] [12] [INFO] Booting worker with pid: 12
Internal Server Error: /auth/otp
Traceback (most recent call last):
  File "/home/ft_transcendence/venv/lib/python3.11/site-packages/django/core/handlers/exception.py", line 55, in inner
    response = get_response(request)
               ^^^^^^^^^^^^^^^^^^^^^
  File "/home/ft_transcendence/venv/lib/python3.11/site-packages/django/core/handlers/base.py", line 197, in _get_response
    response = wrapped_callback(request, *callback_args, **callback_kwargs)
               ^^^^^^^^^^^^^^^^^^^^^^^^^^^^^^^^^^^^^^^^^^^^^^^^^^^^^^^^^^^^
  File "/home/ft_transcendence/venv/lib/python3.11/site-packages/django/views/decorators/csrf.py", line 56, in wrapper_view
    return view_func(*args, **kwargs)
           ^^^^^^^^^^^^^^^^^^^^^^^^^^
  File "/home/ft_transcendence/venv/lib/python3.11/site-packages/django/views/generic/base.py", line 104, in view
    return self.dispatch(request, *args, **kwargs)
           ^^^^^^^^^^^^^^^^^^^^^^^^^^^^^^^^^^^^^^^
  File "/home/ft_transcendence/venv/lib/python3.11/site-packages/rest_framework/views.py", line 509, in dispatch
    response = self.handle_exception(exc)
               ^^^^^^^^^^^^^^^^^^^^^^^^^^
  File "/home/ft_transcendence/venv/lib/python3.11/site-packages/rest_framework/views.py", line 469, in handle_exception
    self.raise_uncaught_exception(exc)
  File "/home/ft_transcendence/venv/lib/python3.11/site-packages/rest_framework/views.py", line 480, in raise_uncaught_exception
    raise exc
  File "/home/ft_transcendence/venv/lib/python3.11/site-packages/rest_framework/views.py", line 506, in dispatch
    response = handler(request, *args, **kwargs)
               ^^^^^^^^^^^^^^^^^^^^^^^^^^^^^^^^^
  File "/home/ft_transcendence/src/api/views/account.py", line 47, in post
    login_info: dict = serializer.save()
                       ^^^^^^^^^^^^^^^^^
  File "/home/ft_transcendence/venv/lib/python3.11/site-packages/rest_framework/serializers.py", line 212, in save
    self.instance = self.create(validated_data)
                    ^^^^^^^^^^^^^^^^^^^^^^^^^^^
  File "/home/ft_transcendence/src/api/serializers/account.py", line 96, in create
    refresh = RefreshToken.for_user(user)
              ^^^^^^^^^^^^^^^^^^^^^^^^^^^
  File "/home/ft_transcendence/venv/lib/python3.11/site-packages/rest_framework_simplejwt/tokens.py", line 203, in for_user
    user_id = getattr(user, api_settings.USER_ID_FIELD)
              ^^^^^^^^^^^^^^^^^^^^^^^^^^^^^^^^^^^^^^^^^
AttributeError: 'NoneType' object has no attribute 'id'
[2024-02-13 13:33:20 +0000] [7] [INFO] Handling signal: term
[2024-02-13 13:33:20 +0000] [12] [INFO] Worker exiting (pid: 12)
[2024-02-13 13:33:20 +0000] [7] [INFO] Shutting down: Master
[2024-02-13 13:33:23 +0000] [8] [INFO] Starting gunicorn 21.2.0
[2024-02-13 13:33:23 +0000] [8] [INFO] Listening at: http://0.0.0.0:8000 (8)
[2024-02-13 13:33:23 +0000] [8] [INFO] Using worker: sync
[2024-02-13 13:33:23 +0000] [13] [INFO] Booting worker with pid: 13
Internal Server Error: /auth/otp
Traceback (most recent call last):
  File "/home/ft_transcendence/venv/lib/python3.11/site-packages/django/core/handlers/exception.py", line 55, in inner
    response = get_response(request)
               ^^^^^^^^^^^^^^^^^^^^^
  File "/home/ft_transcendence/venv/lib/python3.11/site-packages/django/core/handlers/base.py", line 197, in _get_response
    response = wrapped_callback(request, *callback_args, **callback_kwargs)
               ^^^^^^^^^^^^^^^^^^^^^^^^^^^^^^^^^^^^^^^^^^^^^^^^^^^^^^^^^^^^
  File "/home/ft_transcendence/venv/lib/python3.11/site-packages/django/views/decorators/csrf.py", line 56, in wrapper_view
    return view_func(*args, **kwargs)
           ^^^^^^^^^^^^^^^^^^^^^^^^^^
  File "/home/ft_transcendence/venv/lib/python3.11/site-packages/django/views/generic/base.py", line 104, in view
    return self.dispatch(request, *args, **kwargs)
           ^^^^^^^^^^^^^^^^^^^^^^^^^^^^^^^^^^^^^^^
  File "/home/ft_transcendence/venv/lib/python3.11/site-packages/rest_framework/views.py", line 509, in dispatch
    response = self.handle_exception(exc)
               ^^^^^^^^^^^^^^^^^^^^^^^^^^
  File "/home/ft_transcendence/venv/lib/python3.11/site-packages/rest_framework/views.py", line 469, in handle_exception
    self.raise_uncaught_exception(exc)
  File "/home/ft_transcendence/venv/lib/python3.11/site-packages/rest_framework/views.py", line 480, in raise_uncaught_exception
    raise exc
  File "/home/ft_transcendence/venv/lib/python3.11/site-packages/rest_framework/views.py", line 506, in dispatch
    response = handler(request, *args, **kwargs)
               ^^^^^^^^^^^^^^^^^^^^^^^^^^^^^^^^^
  File "/home/ft_transcendence/src/api/views/account.py", line 47, in post
    login_info: dict = serializer.save()
                       ^^^^^^^^^^^^^^^^^
  File "/home/ft_transcendence/venv/lib/python3.11/site-packages/rest_framework/serializers.py", line 212, in save
    self.instance = self.create(validated_data)
                    ^^^^^^^^^^^^^^^^^^^^^^^^^^^
  File "/home/ft_transcendence/src/api/serializers/account.py", line 96, in create
    refresh = RefreshToken.for_user(user)
              ^^^^^^^^^^^^^^^^^^^^^^^^^^^
  File "/home/ft_transcendence/venv/lib/python3.11/site-packages/rest_framework_simplejwt/tokens.py", line 203, in for_user
    user_id = getattr(user, api_settings.USER_ID_FIELD)
              ^^^^^^^^^^^^^^^^^^^^^^^^^^^^^^^^^^^^^^^^^
AttributeError: 'NoneType' object has no attribute 'id'
[2024-02-13 13:34:26 +0000] [8] [INFO] Handling signal: term
[2024-02-13 13:34:26 +0000] [13] [INFO] Worker exiting (pid: 13)
[2024-02-13 13:34:26 +0000] [8] [INFO] Shutting down: Master
[2024-02-13 13:34:29 +0000] [7] [INFO] Starting gunicorn 21.2.0
[2024-02-13 13:34:29 +0000] [7] [INFO] Listening at: http://0.0.0.0:8000 (7)
[2024-02-13 13:34:29 +0000] [7] [INFO] Using worker: sync
[2024-02-13 13:34:29 +0000] [12] [INFO] Booting worker with pid: 12
Bad Request: /auth/otp
Bad Request: /auth/otp
[2024-02-13 13:36:23 +0000] [7] [INFO] Handling signal: term
[2024-02-13 13:36:23 +0000] [12] [INFO] Worker exiting (pid: 12)
[2024-02-13 13:36:24 +0000] [7] [INFO] Shutting down: Master
[2024-02-13 13:36:28 +0000] [7] [INFO] Starting gunicorn 21.2.0
[2024-02-13 13:36:28 +0000] [7] [INFO] Listening at: http://0.0.0.0:8000 (7)
[2024-02-13 13:36:28 +0000] [7] [INFO] Using worker: sync
[2024-02-13 13:36:28 +0000] [12] [INFO] Booting worker with pid: 12
Bad Request: /auth/otp
Bad Request: /auth/otp
Bad Request: /auth/otp
Bad Request: /auth/otp
Bad Request: /auth/otp
Bad Request: /auth/otp
Bad Request: /auth/otp
Bad Request: /auth/login
Bad Request: /auth/register
[2024-02-13 13:38:34 +0000] [7] [INFO] Handling signal: term
[2024-02-13 13:38:34 +0000] [12] [INFO] Worker exiting (pid: 12)
[2024-02-13 13:38:34 +0000] [7] [INFO] Shutting down: Master
[2024-02-13 13:54:27 +0000] [6] [INFO] Starting gunicorn 21.2.0
[2024-02-13 13:54:27 +0000] [6] [INFO] Listening at: http://0.0.0.0:8000 (6)
[2024-02-13 13:54:27 +0000] [6] [INFO] Using worker: sync
[2024-02-13 13:54:27 +0000] [11] [INFO] Booting worker with pid: 11
Bad Request: /auth/register
[2024-02-13 14:28:48 +0000] [6] [INFO] Handling signal: term
[2024-02-13 14:28:48 +0000] [11] [INFO] Worker exiting (pid: 11)
[2024-02-13 14:28:49 +0000] [6] [INFO] Shutting down: Master
[2024-02-13 14:28:53 +0000] [6] [INFO] Starting gunicorn 21.2.0
[2024-02-13 14:28:53 +0000] [6] [INFO] Listening at: http://0.0.0.0:8000 (6)
[2024-02-13 14:28:53 +0000] [6] [INFO] Using worker: sync
[2024-02-13 14:28:53 +0000] [11] [INFO] Booting worker with pid: 11
Invalid HTTP_HOST header: '10.3.3.4:5000'. You may need to add '10.3.3.4' to ALLOWED_HOSTS.
Traceback (most recent call last):
  File "/home/ft_transcendence/venv/lib/python3.11/site-packages/django/core/handlers/exception.py", line 55, in inner
    response = get_response(request)
               ^^^^^^^^^^^^^^^^^^^^^
  File "/home/ft_transcendence/venv/lib/python3.11/site-packages/django/utils/deprecation.py", line 133, in __call__
    response = self.process_request(request)
               ^^^^^^^^^^^^^^^^^^^^^^^^^^^^^
  File "/home/ft_transcendence/venv/lib/python3.11/site-packages/django/middleware/common.py", line 48, in process_request
    host = request.get_host()
           ^^^^^^^^^^^^^^^^^^
  File "/home/ft_transcendence/venv/lib/python3.11/site-packages/django/http/request.py", line 150, in get_host
    raise DisallowedHost(msg)
django.core.exceptions.DisallowedHost: Invalid HTTP_HOST header: '10.3.3.4:5000'. You may need to add '10.3.3.4' to ALLOWED_HOSTS.
Bad Request: /
Invalid HTTP_HOST header: '10.3.3.4:5000'. You may need to add '10.3.3.4' to ALLOWED_HOSTS.
Traceback (most recent call last):
  File "/home/ft_transcendence/venv/lib/python3.11/site-packages/django/core/handlers/exception.py", line 55, in inner
    response = get_response(request)
               ^^^^^^^^^^^^^^^^^^^^^
  File "/home/ft_transcendence/venv/lib/python3.11/site-packages/django/utils/deprecation.py", line 133, in __call__
    response = self.process_request(request)
               ^^^^^^^^^^^^^^^^^^^^^^^^^^^^^
  File "/home/ft_transcendence/venv/lib/python3.11/site-packages/django/middleware/common.py", line 48, in process_request
    host = request.get_host()
           ^^^^^^^^^^^^^^^^^^
  File "/home/ft_transcendence/venv/lib/python3.11/site-packages/django/http/request.py", line 150, in get_host
    raise DisallowedHost(msg)
django.core.exceptions.DisallowedHost: Invalid HTTP_HOST header: '10.3.3.4:5000'. You may need to add '10.3.3.4' to ALLOWED_HOSTS.
Bad Request: /favicon.ico
[2024-02-13 14:29:44 +0000] [6] [INFO] Handling signal: term
[2024-02-13 14:29:44 +0000] [11] [INFO] Worker exiting (pid: 11)
[2024-02-13 14:29:44 +0000] [6] [INFO] Shutting down: Master
[2024-02-13 14:31:46 +0000] [7] [INFO] Starting gunicorn 21.2.0
[2024-02-13 14:31:46 +0000] [7] [INFO] Listening at: http://0.0.0.0:8000 (7)
[2024-02-13 14:31:46 +0000] [7] [INFO] Using worker: sync
[2024-02-13 14:31:46 +0000] [12] [INFO] Booting worker with pid: 12
[2024-02-13 14:40:24 +0000] [7] [INFO] Handling signal: term
[2024-02-13 14:40:24 +0000] [12] [INFO] Worker exiting (pid: 12)
[2024-02-13 14:40:25 +0000] [7] [INFO] Shutting down: Master
[2024-02-17 13:39:25 +0000] [7] [INFO] Starting gunicorn 21.2.0
[2024-02-17 13:39:25 +0000] [7] [INFO] Listening at: http://0.0.0.0:8000 (7)
[2024-02-17 13:39:25 +0000] [7] [INFO] Using worker: sync
[2024-02-17 13:39:25 +0000] [12] [INFO] Booting worker with pid: 12
Bad Request: /auth/otp
[2024-02-17 13:47:42 +0000] [7] [INFO] Handling signal: term
[2024-02-17 13:47:42 +0000] [12] [INFO] Worker exiting (pid: 12)
[2024-02-17 13:47:43 +0000] [7] [INFO] Shutting down: Master
[2024-02-17 13:47:46 +0000] [7] [INFO] Starting gunicorn 21.2.0
[2024-02-17 13:47:46 +0000] [7] [INFO] Listening at: http://0.0.0.0:8000 (7)
[2024-02-17 13:47:46 +0000] [7] [INFO] Using worker: sync
[2024-02-17 13:47:46 +0000] [12] [INFO] Booting worker with pid: 12
Bad Request: /auth/otp
[2024-02-17 13:48:38 +0000] [7] [INFO] Handling signal: term
[2024-02-17 13:48:38 +0000] [12] [INFO] Worker exiting (pid: 12)
[2024-02-17 13:48:38 +0000] [7] [INFO] Shutting down: Master
[2024-02-28 12:46:41 +0000] [7] [INFO] Starting gunicorn 21.2.0
[2024-02-28 12:46:41 +0000] [7] [INFO] Listening at: http://0.0.0.0:8000 (7)
[2024-02-28 12:46:41 +0000] [7] [INFO] Using worker: sync
[2024-02-28 12:46:41 +0000] [12] [INFO] Booting worker with pid: 12
Unauthorized: /players/list
Bad Request: /auth/register
Unauthorized: /auth/login
[2024-02-28 12:50:06 +0000] [7] [INFO] Handling signal: term
[2024-02-28 12:50:06 +0000] [12] [INFO] Worker exiting (pid: 12)
[2024-02-28 12:50:06 +0000] [7] [INFO] Shutting down: Master
[2024-02-28 12:50:12 +0000] [8] [INFO] Starting gunicorn 21.2.0
[2024-02-28 12:50:12 +0000] [8] [INFO] Listening at: http://0.0.0.0:8000 (8)
[2024-02-28 12:50:12 +0000] [8] [INFO] Using worker: sync
[2024-02-28 12:50:12 +0000] [13] [INFO] Booting worker with pid: 13
[2024-02-28 12:54:41 +0000] [8] [INFO] Handling signal: term
[2024-02-28 12:54:41 +0000] [13] [INFO] Worker exiting (pid: 13)
[2024-02-28 12:54:41 +0000] [8] [INFO] Shutting down: Master
[2024-02-28 12:54:48 +0000] [7] [INFO] Starting gunicorn 21.2.0
[2024-02-28 12:54:48 +0000] [7] [INFO] Listening at: http://0.0.0.0:8000 (7)
[2024-02-28 12:54:48 +0000] [7] [INFO] Using worker: sync
[2024-02-28 12:54:48 +0000] [12] [INFO] Booting worker with pid: 12
[2024-02-28 12:58:03 +0000] [7] [INFO] Handling signal: term
[2024-02-28 12:58:03 +0000] [12] [INFO] Worker exiting (pid: 12)
[2024-02-28 12:58:03 +0000] [7] [INFO] Shutting down: Master
[2024-02-28 12:58:09 +0000] [7] [INFO] Starting gunicorn 21.2.0
[2024-02-28 12:58:09 +0000] [7] [INFO] Listening at: http://0.0.0.0:8000 (7)
[2024-02-28 12:58:09 +0000] [7] [INFO] Using worker: sync
[2024-02-28 12:58:09 +0000] [12] [INFO] Booting worker with pid: 12
[2024-02-28 13:00:43 +0000] [7] [INFO] Handling signal: term
[2024-02-28 13:00:43 +0000] [12] [INFO] Worker exiting (pid: 12)
[2024-02-28 13:00:43 +0000] [7] [INFO] Shutting down: Master
[2024-02-29 10:15:14 +0000] [7] [INFO] Starting gunicorn 21.2.0
[2024-02-29 10:15:14 +0000] [7] [INFO] Listening at: http://0.0.0.0:8000 (7)
[2024-02-29 10:15:14 +0000] [7] [INFO] Using worker: sync
[2024-02-29 10:15:14 +0000] [12] [INFO] Booting worker with pid: 12
Invalid HTTP_HOST header: '10.3.8.3:5000'. You may need to add '10.3.8.3' to ALLOWED_HOSTS.
Traceback (most recent call last):
  File "/home/ft_transcendence/venv/lib/python3.11/site-packages/django/core/handlers/exception.py", line 55, in inner
    response = get_response(request)
               ^^^^^^^^^^^^^^^^^^^^^
  File "/home/ft_transcendence/venv/lib/python3.11/site-packages/django/utils/deprecation.py", line 133, in __call__
    response = self.process_request(request)
               ^^^^^^^^^^^^^^^^^^^^^^^^^^^^^
  File "/home/ft_transcendence/venv/lib/python3.11/site-packages/django/middleware/common.py", line 48, in process_request
    host = request.get_host()
           ^^^^^^^^^^^^^^^^^^
  File "/home/ft_transcendence/venv/lib/python3.11/site-packages/django/http/request.py", line 150, in get_host
    raise DisallowedHost(msg)
django.core.exceptions.DisallowedHost: Invalid HTTP_HOST header: '10.3.8.3:5000'. You may need to add '10.3.8.3' to ALLOWED_HOSTS.
Bad Request: /
Invalid HTTP_HOST header: '10.3.8.3:5000'. You may need to add '10.3.8.3' to ALLOWED_HOSTS.
Traceback (most recent call last):
  File "/home/ft_transcendence/venv/lib/python3.11/site-packages/django/core/handlers/exception.py", line 55, in inner
    response = get_response(request)
               ^^^^^^^^^^^^^^^^^^^^^
  File "/home/ft_transcendence/venv/lib/python3.11/site-packages/django/utils/deprecation.py", line 133, in __call__
    response = self.process_request(request)
               ^^^^^^^^^^^^^^^^^^^^^^^^^^^^^
  File "/home/ft_transcendence/venv/lib/python3.11/site-packages/django/middleware/common.py", line 48, in process_request
    host = request.get_host()
           ^^^^^^^^^^^^^^^^^^
  File "/home/ft_transcendence/venv/lib/python3.11/site-packages/django/http/request.py", line 150, in get_host
    raise DisallowedHost(msg)
django.core.exceptions.DisallowedHost: Invalid HTTP_HOST header: '10.3.8.3:5000'. You may need to add '10.3.8.3' to ALLOWED_HOSTS.
Bad Request: /
Invalid HTTP_HOST header: '10.3.8.3:5000'. You may need to add '10.3.8.3' to ALLOWED_HOSTS.
Traceback (most recent call last):
  File "/home/ft_transcendence/venv/lib/python3.11/site-packages/django/core/handlers/exception.py", line 55, in inner
    response = get_response(request)
               ^^^^^^^^^^^^^^^^^^^^^
  File "/home/ft_transcendence/venv/lib/python3.11/site-packages/django/utils/deprecation.py", line 133, in __call__
    response = self.process_request(request)
               ^^^^^^^^^^^^^^^^^^^^^^^^^^^^^
  File "/home/ft_transcendence/venv/lib/python3.11/site-packages/django/middleware/common.py", line 48, in process_request
    host = request.get_host()
           ^^^^^^^^^^^^^^^^^^
  File "/home/ft_transcendence/venv/lib/python3.11/site-packages/django/http/request.py", line 150, in get_host
    raise DisallowedHost(msg)
django.core.exceptions.DisallowedHost: Invalid HTTP_HOST header: '10.3.8.3:5000'. You may need to add '10.3.8.3' to ALLOWED_HOSTS.
Bad Request: /
Invalid HTTP_HOST header: '10.3.8.3:5000'. You may need to add '10.3.8.3' to ALLOWED_HOSTS.
Traceback (most recent call last):
  File "/home/ft_transcendence/venv/lib/python3.11/site-packages/django/core/handlers/exception.py", line 55, in inner
    response = get_response(request)
               ^^^^^^^^^^^^^^^^^^^^^
  File "/home/ft_transcendence/venv/lib/python3.11/site-packages/django/utils/deprecation.py", line 133, in __call__
    response = self.process_request(request)
               ^^^^^^^^^^^^^^^^^^^^^^^^^^^^^
  File "/home/ft_transcendence/venv/lib/python3.11/site-packages/django/middleware/common.py", line 48, in process_request
    host = request.get_host()
           ^^^^^^^^^^^^^^^^^^
  File "/home/ft_transcendence/venv/lib/python3.11/site-packages/django/http/request.py", line 150, in get_host
    raise DisallowedHost(msg)
django.core.exceptions.DisallowedHost: Invalid HTTP_HOST header: '10.3.8.3:5000'. You may need to add '10.3.8.3' to ALLOWED_HOSTS.
Bad Request: /
Invalid HTTP_HOST header: '10.3.8.3:5000'. You may need to add '10.3.8.3' to ALLOWED_HOSTS.
Traceback (most recent call last):
  File "/home/ft_transcendence/venv/lib/python3.11/site-packages/django/core/handlers/exception.py", line 55, in inner
    response = get_response(request)
               ^^^^^^^^^^^^^^^^^^^^^
  File "/home/ft_transcendence/venv/lib/python3.11/site-packages/django/utils/deprecation.py", line 133, in __call__
    response = self.process_request(request)
               ^^^^^^^^^^^^^^^^^^^^^^^^^^^^^
  File "/home/ft_transcendence/venv/lib/python3.11/site-packages/django/middleware/common.py", line 48, in process_request
    host = request.get_host()
           ^^^^^^^^^^^^^^^^^^
  File "/home/ft_transcendence/venv/lib/python3.11/site-packages/django/http/request.py", line 150, in get_host
    raise DisallowedHost(msg)
django.core.exceptions.DisallowedHost: Invalid HTTP_HOST header: '10.3.8.3:5000'. You may need to add '10.3.8.3' to ALLOWED_HOSTS.
Bad Request: /
Invalid HTTP_HOST header: '10.3.8.3:5000'. You may need to add '10.3.8.3' to ALLOWED_HOSTS.
Traceback (most recent call last):
  File "/home/ft_transcendence/venv/lib/python3.11/site-packages/django/core/handlers/exception.py", line 55, in inner
    response = get_response(request)
               ^^^^^^^^^^^^^^^^^^^^^
  File "/home/ft_transcendence/venv/lib/python3.11/site-packages/django/utils/deprecation.py", line 133, in __call__
    response = self.process_request(request)
               ^^^^^^^^^^^^^^^^^^^^^^^^^^^^^
  File "/home/ft_transcendence/venv/lib/python3.11/site-packages/django/middleware/common.py", line 48, in process_request
    host = request.get_host()
           ^^^^^^^^^^^^^^^^^^
  File "/home/ft_transcendence/venv/lib/python3.11/site-packages/django/http/request.py", line 150, in get_host
    raise DisallowedHost(msg)
django.core.exceptions.DisallowedHost: Invalid HTTP_HOST header: '10.3.8.3:5000'. You may need to add '10.3.8.3' to ALLOWED_HOSTS.
Bad Request: /
Invalid HTTP_HOST header: '10.3.8.3:5000'. You may need to add '10.3.8.3' to ALLOWED_HOSTS.
Traceback (most recent call last):
  File "/home/ft_transcendence/venv/lib/python3.11/site-packages/django/core/handlers/exception.py", line 55, in inner
    response = get_response(request)
               ^^^^^^^^^^^^^^^^^^^^^
  File "/home/ft_transcendence/venv/lib/python3.11/site-packages/django/utils/deprecation.py", line 133, in __call__
    response = self.process_request(request)
               ^^^^^^^^^^^^^^^^^^^^^^^^^^^^^
  File "/home/ft_transcendence/venv/lib/python3.11/site-packages/django/middleware/common.py", line 48, in process_request
    host = request.get_host()
           ^^^^^^^^^^^^^^^^^^
  File "/home/ft_transcendence/venv/lib/python3.11/site-packages/django/http/request.py", line 150, in get_host
    raise DisallowedHost(msg)
django.core.exceptions.DisallowedHost: Invalid HTTP_HOST header: '10.3.8.3:5000'. You may need to add '10.3.8.3' to ALLOWED_HOSTS.
Bad Request: /
Invalid HTTP_HOST header: '10.3.8.3:5000'. You may need to add '10.3.8.3' to ALLOWED_HOSTS.
Traceback (most recent call last):
  File "/home/ft_transcendence/venv/lib/python3.11/site-packages/django/core/handlers/exception.py", line 55, in inner
    response = get_response(request)
               ^^^^^^^^^^^^^^^^^^^^^
  File "/home/ft_transcendence/venv/lib/python3.11/site-packages/django/utils/deprecation.py", line 133, in __call__
    response = self.process_request(request)
               ^^^^^^^^^^^^^^^^^^^^^^^^^^^^^
  File "/home/ft_transcendence/venv/lib/python3.11/site-packages/django/middleware/common.py", line 48, in process_request
    host = request.get_host()
           ^^^^^^^^^^^^^^^^^^
  File "/home/ft_transcendence/venv/lib/python3.11/site-packages/django/http/request.py", line 150, in get_host
    raise DisallowedHost(msg)
django.core.exceptions.DisallowedHost: Invalid HTTP_HOST header: '10.3.8.3:5000'. You may need to add '10.3.8.3' to ALLOWED_HOSTS.
Bad Request: /
Invalid HTTP_HOST header: '10.3.8.3:5000'. You may need to add '10.3.8.3' to ALLOWED_HOSTS.
Traceback (most recent call last):
  File "/home/ft_transcendence/venv/lib/python3.11/site-packages/django/core/handlers/exception.py", line 55, in inner
    response = get_response(request)
               ^^^^^^^^^^^^^^^^^^^^^
  File "/home/ft_transcendence/venv/lib/python3.11/site-packages/django/utils/deprecation.py", line 133, in __call__
    response = self.process_request(request)
               ^^^^^^^^^^^^^^^^^^^^^^^^^^^^^
  File "/home/ft_transcendence/venv/lib/python3.11/site-packages/django/middleware/common.py", line 48, in process_request
    host = request.get_host()
           ^^^^^^^^^^^^^^^^^^
  File "/home/ft_transcendence/venv/lib/python3.11/site-packages/django/http/request.py", line 150, in get_host
    raise DisallowedHost(msg)
django.core.exceptions.DisallowedHost: Invalid HTTP_HOST header: '10.3.8.3:5000'. You may need to add '10.3.8.3' to ALLOWED_HOSTS.
Bad Request: /
Invalid HTTP_HOST header: '10.3.8.3:5000'. You may need to add '10.3.8.3' to ALLOWED_HOSTS.
Traceback (most recent call last):
  File "/home/ft_transcendence/venv/lib/python3.11/site-packages/django/core/handlers/exception.py", line 55, in inner
    response = get_response(request)
               ^^^^^^^^^^^^^^^^^^^^^
  File "/home/ft_transcendence/venv/lib/python3.11/site-packages/django/utils/deprecation.py", line 133, in __call__
    response = self.process_request(request)
               ^^^^^^^^^^^^^^^^^^^^^^^^^^^^^
  File "/home/ft_transcendence/venv/lib/python3.11/site-packages/django/middleware/common.py", line 48, in process_request
    host = request.get_host()
           ^^^^^^^^^^^^^^^^^^
  File "/home/ft_transcendence/venv/lib/python3.11/site-packages/django/http/request.py", line 150, in get_host
    raise DisallowedHost(msg)
django.core.exceptions.DisallowedHost: Invalid HTTP_HOST header: '10.3.8.3:5000'. You may need to add '10.3.8.3' to ALLOWED_HOSTS.
Bad Request: /
Bad Request: /auth/login
[2024-02-29 11:06:17 +0000] [7] [INFO] Handling signal: term
[2024-02-29 11:06:17 +0000] [12] [INFO] Worker exiting (pid: 12)
[2024-02-29 11:06:17 +0000] [7] [INFO] Shutting down: Master
[2024-02-29 11:06:23 +0000] [7] [INFO] Starting gunicorn 21.2.0
[2024-02-29 11:06:23 +0000] [7] [INFO] Listening at: http://0.0.0.0:8000 (7)
[2024-02-29 11:06:23 +0000] [7] [INFO] Using worker: sync
[2024-02-29 11:06:23 +0000] [12] [INFO] Booting worker with pid: 12
[2024-02-29 11:08:45 +0000] [7] [INFO] Handling signal: term
[2024-02-29 11:08:45 +0000] [12] [INFO] Worker exiting (pid: 12)
[2024-02-29 11:08:45 +0000] [7] [INFO] Shutting down: Master
[2024-02-29 11:08:51 +0000] [7] [INFO] Starting gunicorn 21.2.0
[2024-02-29 11:08:51 +0000] [7] [INFO] Listening at: http://0.0.0.0:8000 (7)
[2024-02-29 11:08:51 +0000] [7] [INFO] Using worker: sync
[2024-02-29 11:08:51 +0000] [12] [INFO] Booting worker with pid: 12
[2024-02-29 11:12:23 +0000] [7] [INFO] Handling signal: term
[2024-02-29 11:12:23 +0000] [12] [INFO] Worker exiting (pid: 12)
[2024-02-29 11:12:23 +0000] [7] [INFO] Shutting down: Master
[2024-02-29 11:13:33 +0000] [7] [INFO] Starting gunicorn 21.2.0
[2024-02-29 11:13:33 +0000] [7] [INFO] Listening at: http://0.0.0.0:8000 (7)
[2024-02-29 11:13:33 +0000] [7] [INFO] Using worker: sync
[2024-02-29 11:13:33 +0000] [12] [INFO] Booting worker with pid: 12
Bad Request: /auth/login
[2024-02-29 11:32:56 +0000] [7] [INFO] Handling signal: term
[2024-02-29 11:32:56 +0000] [12] [INFO] Worker exiting (pid: 12)
